INFO 2025-07-27 06:11:58,407 autoreload 6468 6680 Watching for file changes with StatReloader
INFO 2025-07-27 06:13:36,475 runserver 6468 7868 [32mHTTP GET /swagger 301 [0.21, 127.0.0.1:53005][0m
INFO 2025-07-27 06:13:36,518 runserver 6468 7868 [mHTTP GET /swagger/ 200 [0.04, 127.0.0.1:53005][0m
INFO 2025-07-27 06:13:36,691 runserver 6468 7868 [mHTTP GET /static/drf-yasg/style.css 200 [0.15, 127.0.0.1:53005][0m
INFO 2025-07-27 06:13:36,698 runserver 6468 7868 [mHTTP GET /static/drf-yasg/swagger-ui-dist/swagger-ui.css 200 [0.15, 127.0.0.1:53006][0m
INFO 2025-07-27 06:13:36,734 runserver 6468 7868 [mHTTP GET /static/drf-yasg/swagger-ui-dist/swagger-ui-bundle.js 200 [0.18, 127.0.0.1:53008][0m
INFO 2025-07-27 06:13:36,747 runserver 6468 7868 [mHTTP GET /static/drf-yasg/insQ.min.js 200 [0.05, 127.0.0.1:53006][0m
INFO 2025-07-27 06:13:36,792 runserver 6468 7868 [mHTTP GET /static/drf-yasg/swagger-ui-init.js 200 [0.04, 127.0.0.1:53006][0m
INFO 2025-07-27 06:13:36,838 runserver 6468 7868 [mHTTP GET /static/drf-yasg/immutable.min.js 200 [0.10, 127.0.0.1:53008][0m
INFO 2025-07-27 06:13:36,877 runserver 6468 7868 [mHTTP GET /static/drf-yasg/swagger-ui-dist/swagger-ui-standalone-preset.js 200 [0.18, 127.0.0.1:53005][0m
INFO 2025-07-27 06:13:36,993 runserver 6468 7868 [mHTTP GET /swagger/?format=openapi 200 [0.02, 127.0.0.1:53005][0m
INFO 2025-07-27 06:13:37,008 runserver 6468 7868 [mHTTP GET /static/drf-yasg/swagger-ui-dist/favicon-32x32.png 200 [0.00, 127.0.0.1:53005][0m
INFO 2025-07-27 06:14:55,599 runserver 6468 7868 [32mHTTP GET /admin 301 [0.03, 127.0.0.1:53027][0m
INFO 2025-07-27 06:14:55,648 runserver 6468 7868 [32mHTTP GET /admin/ 302 [0.03, 127.0.0.1:53027][0m
INFO 2025-07-27 06:14:56,088 runserver 6468 7868 [mHTTP GET /admin/login/?next=/admin/ 200 [0.43, 127.0.0.1:53027][0m
INFO 2025-07-27 06:14:56,235 runserver 6468 7868 [mHTTP GET /static/admin/css/base.css 200 [0.03, 127.0.0.1:53027][0m
INFO 2025-07-27 06:14:56,252 runserver 6468 7868 [mHTTP GET /static/admin/css/nav_sidebar.css 200 [0.03, 127.0.0.1:53029][0m
INFO 2025-07-27 06:14:56,257 runserver 6468 7868 [mHTTP GET /static/admin/css/dark_mode.css 200 [0.04, 127.0.0.1:53028][0m
INFO 2025-07-27 06:14:56,282 runserver 6468 7868 [mHTTP GET /static/admin/css/login.css 200 [0.04, 127.0.0.1:53027][0m
INFO 2025-07-27 06:14:56,379 runserver 6468 7868 [mHTTP GET /static/admin/css/responsive.css 200 [0.12, 127.0.0.1:53029][0m
INFO 2025-07-27 06:14:56,381 runserver 6468 7868 [mHTTP GET /static/admin/js/theme.js 200 [0.11, 127.0.0.1:53028][0m
INFO 2025-07-27 06:14:56,415 runserver 6468 7868 [mHTTP GET /static/admin/js/nav_sidebar.js 200 [0.13, 127.0.0.1:53027][0m
WARNING 2025-07-27 06:14:56,468 log 6468 9080 Not Found: /favicon.ico
WARNING 2025-07-27 06:14:56,470 runserver 6468 7868 [33mHTTP GET /favicon.ico 404 [0.03, 127.0.0.1:53027][0m
INFO 2025-07-27 06:15:14,424 runserver 6468 7868 [32mHTTP POST /admin/login/?next=/admin/ 302 [4.67, 127.0.0.1:53027][0m
INFO 2025-07-27 06:15:16,680 runserver 6468 7868 [mHTTP GET /admin/ 200 [2.24, 127.0.0.1:53027][0m
INFO 2025-07-27 06:15:16,803 runserver 6468 7868 [mHTTP GET /static/admin/css/dashboard.css 200 [0.06, 127.0.0.1:53027][0m
INFO 2025-07-27 06:15:16,810 runserver 6468 7868 [mHTTP GET /static/admin/img/icon-addlink.svg 200 [0.06, 127.0.0.1:53028][0m
INFO 2025-07-27 06:15:16,811 runserver 6468 7868 [mHTTP GET /static/admin/img/icon-changelink.svg 200 [0.06, 127.0.0.1:53029][0m
INFO 2025-07-27 06:15:50,960 autoreload 6468 6680 C:\Users\user\Documents\Project\stanum_web\account\admin.py changed, reloading.
INFO 2025-07-27 06:15:53,533 autoreload 7496 15220 Watching for file changes with StatReloader
INFO 2025-07-27 06:16:06,284 runserver 7496 676 [mHTTP GET /admin/ 200 [2.21, 127.0.0.1:53055][0m
INFO 2025-07-27 06:16:58,728 runserver 7496 676 [mHTTP POST /api/v1/account/auth/signup 201 [12.86, 127.0.0.1:53055][0m
INFO 2025-07-27 06:17:29,554 autoreload 7496 15220 C:\Users\user\Documents\Project\stanum_web\stanum_web\settings.py changed, reloading.
INFO 2025-07-27 06:17:31,708 autoreload 2388 2348 Watching for file changes with StatReloader
INFO 2025-07-27 06:18:09,230 runserver 2388 16324 [mHTTP POST /api/v1/account/auth/signup 201 [5.62, 127.0.0.1:53081][0m
INFO 2025-07-27 06:18:37,649 autoreload 2388 2348 C:\Users\user\Documents\Project\stanum_web\account\models.py changed, reloading.
INFO 2025-07-27 06:18:40,425 autoreload 9936 9124 Watching for file changes with StatReloader
INFO 2025-07-27 06:19:01,143 autoreload 9936 9124 C:\Users\user\Documents\Project\stanum_web\utils\otp.py changed, reloading.
INFO 2025-07-27 06:19:04,195 autoreload 14520 5308 Watching for file changes with StatReloader
INFO 2025-07-27 06:19:50,507 runserver 14520 15260 [mHTTP POST /api/v1/account/auth/signup 201 [6.07, 127.0.0.1:53117][0m
INFO 2025-07-27 06:20:24,189 runserver 14520 15260 [mHTTP GET /api/v1/account/auth/verify/2/960064 200 [6.47, 127.0.0.1:53117][0m
INFO 2025-07-27 06:21:02,179 runserver 14520 15260 [mHTTP POST /api/v1/account/auth/password/forget 200 [2.90, 127.0.0.1:53117][0m
INFO 2025-07-27 06:21:49,590 runserver 14520 15260 [mHTTP GET /api/v1/account/auth/password/reset/validate-otp/2/803066 200 [8.82, 127.0.0.1:53117][0m
ERROR 2025-07-27 06:22:18,355 log 14520 4148 Internal Server Error: /api/v1/account/auth/password/reset/2/ctl5od-f9432bfb0a3af91bbf46322c75f58590
Traceback (most recent call last):
  File "C:\Users\user\Documents\venv\Lib\site-packages\django\db\backends\base\base.py", line 289, in ensure_connection
    self.connect()
  File "C:\Users\user\Documents\venv\Lib\site-packages\django\utils\asyncio.py", line 26, in inner
    return func(*args, **kwargs)
           ^^^^^^^^^^^^^^^^^^^^^
  File "C:\Users\user\Documents\venv\Lib\site-packages\django\db\backends\base\base.py", line 270, in connect
    self.connection = self.get_new_connection(conn_params)
                      ^^^^^^^^^^^^^^^^^^^^^^^^^^^^^^^^^^^^
  File "C:\Users\user\Documents\venv\Lib\site-packages\django\utils\asyncio.py", line 26, in inner
    return func(*args, **kwargs)
           ^^^^^^^^^^^^^^^^^^^^^
  File "C:\Users\user\Documents\venv\Lib\site-packages\django\db\backends\postgresql\base.py", line 275, in get_new_connection
    connection = self.Database.connect(**conn_params)
                 ^^^^^^^^^^^^^^^^^^^^^^^^^^^^^^^^^^^^
  File "C:\Users\user\Documents\venv\Lib\site-packages\psycopg2\__init__.py", line 122, in connect
    conn = _connect(dsn, connection_factory=connection_factory, **kwasync)
           ^^^^^^^^^^^^^^^^^^^^^^^^^^^^^^^^^^^^^^^^^^^^^^^^^^^^^^^^^^^^^^^
psycopg2.OperationalError: could not translate host name "victor-ao-ayomideolusola5002-b13e.h.aivencloud.com" to address: No such host is known. 


The above exception was the direct cause of the following exception:

Traceback (most recent call last):
  File "C:\Users\user\Documents\venv\Lib\site-packages\asgiref\sync.py", line 518, in thread_handler
    raise exc_info[1]
  File "C:\Users\user\Documents\venv\Lib\site-packages\django\core\handlers\exception.py", line 42, in inner
    response = await get_response(request)
               ^^^^^^^^^^^^^^^^^^^^^^^^^^^
  File "C:\Users\user\Documents\venv\Lib\site-packages\asgiref\sync.py", line 518, in thread_handler
    raise exc_info[1]
  File "C:\Users\user\Documents\venv\Lib\site-packages\django\core\handlers\base.py", line 253, in _get_response_async
    response = await wrapped_callback(
               ^^^^^^^^^^^^^^^^^^^^^^^
  File "C:\Users\user\Documents\venv\Lib\site-packages\asgiref\sync.py", line 468, in __call__
    ret = await asyncio.shield(exec_coro)
          ^^^^^^^^^^^^^^^^^^^^^^^^^^^^^^^
  File "C:\Users\user\Documents\venv\Lib\site-packages\asgiref\current_thread_executor.py", line 40, in run
    result = self.fn(*self.args, **self.kwargs)
             ^^^^^^^^^^^^^^^^^^^^^^^^^^^^^^^^^^
  File "C:\Users\user\Documents\venv\Lib\site-packages\asgiref\sync.py", line 522, in thread_handler
    return func(*args, **kwargs)
           ^^^^^^^^^^^^^^^^^^^^^
  File "C:\Users\user\Documents\venv\Lib\site-packages\django\views\decorators\csrf.py", line 56, in wrapper_view
    return view_func(*args, **kwargs)
           ^^^^^^^^^^^^^^^^^^^^^^^^^^
  File "C:\Users\user\Documents\venv\Lib\site-packages\django\views\generic\base.py", line 104, in view
    return self.dispatch(request, *args, **kwargs)
           ^^^^^^^^^^^^^^^^^^^^^^^^^^^^^^^^^^^^^^^
  File "C:\Users\user\Documents\venv\Lib\site-packages\rest_framework\views.py", line 509, in dispatch
    response = self.handle_exception(exc)
               ^^^^^^^^^^^^^^^^^^^^^^^^^^
  File "C:\Users\user\Documents\venv\Lib\site-packages\rest_framework\views.py", line 469, in handle_exception
    self.raise_uncaught_exception(exc)
  File "C:\Users\user\Documents\venv\Lib\site-packages\rest_framework\views.py", line 480, in raise_uncaught_exception
    raise exc
  File "C:\Users\user\Documents\venv\Lib\site-packages\rest_framework\views.py", line 506, in dispatch
    response = handler(request, *args, **kwargs)
               ^^^^^^^^^^^^^^^^^^^^^^^^^^^^^^^^^
  File "C:\Users\user\Documents\Project\stanum_web\account\views.py", line 444, in post
    user = get_object_or_404(User, id=id, email_verified=True)
           ^^^^^^^^^^^^^^^^^^^^^^^^^^^^^^^^^^^^^^^^^^^^^^^^^^^
  File "C:\Users\user\Documents\venv\Lib\site-packages\django\shortcuts.py", line 85, in get_object_or_404
    return queryset.get(*args, **kwargs)
           ^^^^^^^^^^^^^^^^^^^^^^^^^^^^^
  File "C:\Users\user\Documents\venv\Lib\site-packages\django\db\models\query.py", line 633, in get
    num = len(clone)
          ^^^^^^^^^^
  File "C:\Users\user\Documents\venv\Lib\site-packages\django\db\models\query.py", line 380, in __len__
    self._fetch_all()
  File "C:\Users\user\Documents\venv\Lib\site-packages\django\db\models\query.py", line 1881, in _fetch_all
    self._result_cache = list(self._iterable_class(self))
                         ^^^^^^^^^^^^^^^^^^^^^^^^^^^^^^^^
  File "C:\Users\user\Documents\venv\Lib\site-packages\django\db\models\query.py", line 91, in __iter__
    results = compiler.execute_sql(
              ^^^^^^^^^^^^^^^^^^^^^
  File "C:\Users\user\Documents\venv\Lib\site-packages\django\db\models\sql\compiler.py", line 1560, in execute_sql
    cursor = self.connection.cursor()
             ^^^^^^^^^^^^^^^^^^^^^^^^
  File "C:\Users\user\Documents\venv\Lib\site-packages\django\utils\asyncio.py", line 26, in inner
    return func(*args, **kwargs)
           ^^^^^^^^^^^^^^^^^^^^^
  File "C:\Users\user\Documents\venv\Lib\site-packages\django\db\backends\base\base.py", line 330, in cursor
    return self._cursor()
           ^^^^^^^^^^^^^^
  File "C:\Users\user\Documents\venv\Lib\site-packages\django\db\backends\base\base.py", line 306, in _cursor
    self.ensure_connection()
  File "C:\Users\user\Documents\venv\Lib\site-packages\django\utils\asyncio.py", line 26, in inner
    return func(*args, **kwargs)
           ^^^^^^^^^^^^^^^^^^^^^
  File "C:\Users\user\Documents\venv\Lib\site-packages\django\db\backends\base\base.py", line 288, in ensure_connection
    with self.wrap_database_errors:
  File "C:\Users\user\Documents\venv\Lib\site-packages\django\db\utils.py", line 91, in __exit__
    raise dj_exc_value.with_traceback(traceback) from exc_value
  File "C:\Users\user\Documents\venv\Lib\site-packages\django\db\backends\base\base.py", line 289, in ensure_connection
    self.connect()
  File "C:\Users\user\Documents\venv\Lib\site-packages\django\utils\asyncio.py", line 26, in inner
    return func(*args, **kwargs)
           ^^^^^^^^^^^^^^^^^^^^^
  File "C:\Users\user\Documents\venv\Lib\site-packages\django\db\backends\base\base.py", line 270, in connect
    self.connection = self.get_new_connection(conn_params)
                      ^^^^^^^^^^^^^^^^^^^^^^^^^^^^^^^^^^^^
  File "C:\Users\user\Documents\venv\Lib\site-packages\django\utils\asyncio.py", line 26, in inner
    return func(*args, **kwargs)
           ^^^^^^^^^^^^^^^^^^^^^
  File "C:\Users\user\Documents\venv\Lib\site-packages\django\db\backends\postgresql\base.py", line 275, in get_new_connection
    connection = self.Database.connect(**conn_params)
                 ^^^^^^^^^^^^^^^^^^^^^^^^^^^^^^^^^^^^
  File "C:\Users\user\Documents\venv\Lib\site-packages\psycopg2\__init__.py", line 122, in connect
    conn = _connect(dsn, connection_factory=connection_factory, **kwasync)
           ^^^^^^^^^^^^^^^^^^^^^^^^^^^^^^^^^^^^^^^^^^^^^^^^^^^^^^^^^^^^^^^
django.db.utils.OperationalError: could not translate host name "victor-ao-ayomideolusola5002-b13e.h.aivencloud.com" to address: No such host is known. 

ERROR 2025-07-27 06:22:18,463 runserver 14520 15260 [35;1mHTTP POST /api/v1/account/auth/password/reset/2/ctl5od-f9432bfb0a3af91bbf46322c75f58590 500 [0.75, 127.0.0.1:53128][0m
ERROR 2025-07-27 06:22:27,490 log 14520 4148 Internal Server Error: /api/v1/account/auth/password/reset/2/ctl5od-f9432bfb0a3af91bbf46322c75f58590
Traceback (most recent call last):
  File "C:\Users\user\Documents\venv\Lib\site-packages\django\db\backends\base\base.py", line 289, in ensure_connection
    self.connect()
  File "C:\Users\user\Documents\venv\Lib\site-packages\django\utils\asyncio.py", line 26, in inner
    return func(*args, **kwargs)
           ^^^^^^^^^^^^^^^^^^^^^
  File "C:\Users\user\Documents\venv\Lib\site-packages\django\db\backends\base\base.py", line 270, in connect
    self.connection = self.get_new_connection(conn_params)
                      ^^^^^^^^^^^^^^^^^^^^^^^^^^^^^^^^^^^^
  File "C:\Users\user\Documents\venv\Lib\site-packages\django\utils\asyncio.py", line 26, in inner
    return func(*args, **kwargs)
           ^^^^^^^^^^^^^^^^^^^^^
  File "C:\Users\user\Documents\venv\Lib\site-packages\django\db\backends\postgresql\base.py", line 275, in get_new_connection
    connection = self.Database.connect(**conn_params)
                 ^^^^^^^^^^^^^^^^^^^^^^^^^^^^^^^^^^^^
  File "C:\Users\user\Documents\venv\Lib\site-packages\psycopg2\__init__.py", line 122, in connect
    conn = _connect(dsn, connection_factory=connection_factory, **kwasync)
           ^^^^^^^^^^^^^^^^^^^^^^^^^^^^^^^^^^^^^^^^^^^^^^^^^^^^^^^^^^^^^^^
psycopg2.OperationalError: could not translate host name "victor-ao-ayomideolusola5002-b13e.h.aivencloud.com" to address: No such host is known. 


The above exception was the direct cause of the following exception:

Traceback (most recent call last):
  File "C:\Users\user\Documents\venv\Lib\site-packages\asgiref\sync.py", line 518, in thread_handler
    raise exc_info[1]
  File "C:\Users\user\Documents\venv\Lib\site-packages\django\core\handlers\exception.py", line 42, in inner
    response = await get_response(request)
               ^^^^^^^^^^^^^^^^^^^^^^^^^^^
  File "C:\Users\user\Documents\venv\Lib\site-packages\asgiref\sync.py", line 518, in thread_handler
    raise exc_info[1]
  File "C:\Users\user\Documents\venv\Lib\site-packages\django\core\handlers\base.py", line 253, in _get_response_async
    response = await wrapped_callback(
               ^^^^^^^^^^^^^^^^^^^^^^^
  File "C:\Users\user\Documents\venv\Lib\site-packages\asgiref\sync.py", line 468, in __call__
    ret = await asyncio.shield(exec_coro)
          ^^^^^^^^^^^^^^^^^^^^^^^^^^^^^^^
  File "C:\Users\user\Documents\venv\Lib\site-packages\asgiref\current_thread_executor.py", line 40, in run
    result = self.fn(*self.args, **self.kwargs)
             ^^^^^^^^^^^^^^^^^^^^^^^^^^^^^^^^^^
  File "C:\Users\user\Documents\venv\Lib\site-packages\asgiref\sync.py", line 522, in thread_handler
    return func(*args, **kwargs)
           ^^^^^^^^^^^^^^^^^^^^^
  File "C:\Users\user\Documents\venv\Lib\site-packages\django\views\decorators\csrf.py", line 56, in wrapper_view
    return view_func(*args, **kwargs)
           ^^^^^^^^^^^^^^^^^^^^^^^^^^
  File "C:\Users\user\Documents\venv\Lib\site-packages\django\views\generic\base.py", line 104, in view
    return self.dispatch(request, *args, **kwargs)
           ^^^^^^^^^^^^^^^^^^^^^^^^^^^^^^^^^^^^^^^
  File "C:\Users\user\Documents\venv\Lib\site-packages\rest_framework\views.py", line 509, in dispatch
    response = self.handle_exception(exc)
               ^^^^^^^^^^^^^^^^^^^^^^^^^^
  File "C:\Users\user\Documents\venv\Lib\site-packages\rest_framework\views.py", line 469, in handle_exception
    self.raise_uncaught_exception(exc)
  File "C:\Users\user\Documents\venv\Lib\site-packages\rest_framework\views.py", line 480, in raise_uncaught_exception
    raise exc
  File "C:\Users\user\Documents\venv\Lib\site-packages\rest_framework\views.py", line 506, in dispatch
    response = handler(request, *args, **kwargs)
               ^^^^^^^^^^^^^^^^^^^^^^^^^^^^^^^^^
  File "C:\Users\user\Documents\Project\stanum_web\account\views.py", line 444, in post
    user = get_object_or_404(User, id=id, email_verified=True)
           ^^^^^^^^^^^^^^^^^^^^^^^^^^^^^^^^^^^^^^^^^^^^^^^^^^^
  File "C:\Users\user\Documents\venv\Lib\site-packages\django\shortcuts.py", line 85, in get_object_or_404
    return queryset.get(*args, **kwargs)
           ^^^^^^^^^^^^^^^^^^^^^^^^^^^^^
  File "C:\Users\user\Documents\venv\Lib\site-packages\django\db\models\query.py", line 633, in get
    num = len(clone)
          ^^^^^^^^^^
  File "C:\Users\user\Documents\venv\Lib\site-packages\django\db\models\query.py", line 380, in __len__
    self._fetch_all()
  File "C:\Users\user\Documents\venv\Lib\site-packages\django\db\models\query.py", line 1881, in _fetch_all
    self._result_cache = list(self._iterable_class(self))
                         ^^^^^^^^^^^^^^^^^^^^^^^^^^^^^^^^
  File "C:\Users\user\Documents\venv\Lib\site-packages\django\db\models\query.py", line 91, in __iter__
    results = compiler.execute_sql(
              ^^^^^^^^^^^^^^^^^^^^^
  File "C:\Users\user\Documents\venv\Lib\site-packages\django\db\models\sql\compiler.py", line 1560, in execute_sql
    cursor = self.connection.cursor()
             ^^^^^^^^^^^^^^^^^^^^^^^^
  File "C:\Users\user\Documents\venv\Lib\site-packages\django\utils\asyncio.py", line 26, in inner
    return func(*args, **kwargs)
           ^^^^^^^^^^^^^^^^^^^^^
  File "C:\Users\user\Documents\venv\Lib\site-packages\django\db\backends\base\base.py", line 330, in cursor
    return self._cursor()
           ^^^^^^^^^^^^^^
  File "C:\Users\user\Documents\venv\Lib\site-packages\django\db\backends\base\base.py", line 306, in _cursor
    self.ensure_connection()
  File "C:\Users\user\Documents\venv\Lib\site-packages\django\utils\asyncio.py", line 26, in inner
    return func(*args, **kwargs)
           ^^^^^^^^^^^^^^^^^^^^^
  File "C:\Users\user\Documents\venv\Lib\site-packages\django\db\backends\base\base.py", line 288, in ensure_connection
    with self.wrap_database_errors:
  File "C:\Users\user\Documents\venv\Lib\site-packages\django\db\utils.py", line 91, in __exit__
    raise dj_exc_value.with_traceback(traceback) from exc_value
  File "C:\Users\user\Documents\venv\Lib\site-packages\django\db\backends\base\base.py", line 289, in ensure_connection
    self.connect()
  File "C:\Users\user\Documents\venv\Lib\site-packages\django\utils\asyncio.py", line 26, in inner
    return func(*args, **kwargs)
           ^^^^^^^^^^^^^^^^^^^^^
  File "C:\Users\user\Documents\venv\Lib\site-packages\django\db\backends\base\base.py", line 270, in connect
    self.connection = self.get_new_connection(conn_params)
                      ^^^^^^^^^^^^^^^^^^^^^^^^^^^^^^^^^^^^
  File "C:\Users\user\Documents\venv\Lib\site-packages\django\utils\asyncio.py", line 26, in inner
    return func(*args, **kwargs)
           ^^^^^^^^^^^^^^^^^^^^^
  File "C:\Users\user\Documents\venv\Lib\site-packages\django\db\backends\postgresql\base.py", line 275, in get_new_connection
    connection = self.Database.connect(**conn_params)
                 ^^^^^^^^^^^^^^^^^^^^^^^^^^^^^^^^^^^^
  File "C:\Users\user\Documents\venv\Lib\site-packages\psycopg2\__init__.py", line 122, in connect
    conn = _connect(dsn, connection_factory=connection_factory, **kwasync)
           ^^^^^^^^^^^^^^^^^^^^^^^^^^^^^^^^^^^^^^^^^^^^^^^^^^^^^^^^^^^^^^^
django.db.utils.OperationalError: could not translate host name "victor-ao-ayomideolusola5002-b13e.h.aivencloud.com" to address: No such host is known. 

ERROR 2025-07-27 06:22:27,518 runserver 14520 15260 [35;1mHTTP POST /api/v1/account/auth/password/reset/2/ctl5od-f9432bfb0a3af91bbf46322c75f58590 500 [0.08, 127.0.0.1:53128][0m
INFO 2025-07-27 06:23:01,427 runserver 14520 15260 [mHTTP POST /api/v1/account/auth/password/reset/2/ctl5od-f9432bfb0a3af91bbf46322c75f58590 200 [2.58, 127.0.0.1:53141][0m
INFO 2025-07-31 09:27:13,675 autoreload 9332 7560 Watching for file changes with StatReloader
INFO 2025-07-31 09:27:24,724 runserver 9332 11240 [mHTTP GET /swagger/ 200 [0.15, 127.0.0.1:55063][0m
INFO 2025-07-31 09:27:25,009 runserver 9332 11240 [mHTTP GET /swagger/?format=openapi 200 [0.03, 127.0.0.1:55063][0m
INFO 2025-07-31 09:27:25,082 runserver 9332 11240 [mHTTP GET /static/drf-yasg/swagger-ui-dist/favicon-32x32.png 200 [0.08, 127.0.0.1:55064][0m
INFO 2025-07-31 09:27:54,911 runserver 9332 11240 [32mHTTP GET /admin 301 [0.13, 127.0.0.1:55064][0m
INFO 2025-07-31 09:27:58,270 runserver 9332 11240 [32mHTTP GET /admin/ 302 [3.35, 127.0.0.1:55064][0m
INFO 2025-07-31 09:27:58,710 runserver 9332 11240 [mHTTP GET /admin/login/?next=/admin/ 200 [0.43, 127.0.0.1:55064][0m
INFO 2025-07-31 09:27:58,782 runserver 9332 11240 [mHTTP GET /static/admin/css/base.css 200 [0.03, 127.0.0.1:55064][0m
INFO 2025-07-31 09:27:58,795 runserver 9332 11240 [mHTTP GET /static/admin/css/nav_sidebar.css 200 [0.03, 127.0.0.1:55065][0m
INFO 2025-07-31 09:27:58,796 runserver 9332 11240 [mHTTP GET /static/admin/css/dark_mode.css 200 [0.03, 127.0.0.1:55063][0m
INFO 2025-07-31 09:27:58,812 runserver 9332 11240 [mHTTP GET /static/admin/css/login.css 200 [0.02, 127.0.0.1:55064][0m
INFO 2025-07-31 09:27:58,844 runserver 9332 11240 [mHTTP GET /static/admin/css/responsive.css 200 [0.04, 127.0.0.1:55063][0m
INFO 2025-07-31 09:27:58,862 runserver 9332 11240 [mHTTP GET /static/admin/js/theme.js 200 [0.06, 127.0.0.1:55065][0m
INFO 2025-07-31 09:27:58,876 runserver 9332 11240 [mHTTP GET /static/admin/js/nav_sidebar.js 200 [0.06, 127.0.0.1:55064][0m
WARNING 2025-07-31 09:27:58,944 log 9332 6396 Not Found: /favicon.ico
WARNING 2025-07-31 09:27:58,946 runserver 9332 11240 [33mHTTP GET /favicon.ico 404 [0.02, 127.0.0.1:55064][0m
INFO 2025-07-31 09:28:10,394 runserver 9332 11240 [32mHTTP POST /admin/login/?next=/admin/ 302 [5.06, 127.0.0.1:55064][0m
INFO 2025-07-31 09:28:12,745 runserver 9332 11240 [mHTTP GET /admin/ 200 [2.34, 127.0.0.1:55064][0m
INFO 2025-07-31 09:28:12,856 runserver 9332 11240 [mHTTP GET /static/admin/css/dashboard.css 200 [0.03, 127.0.0.1:55064][0m
INFO 2025-07-31 09:28:12,898 runserver 9332 11240 [mHTTP GET /static/admin/img/icon-addlink.svg 200 [0.03, 127.0.0.1:55064][0m
INFO 2025-07-31 09:28:12,906 runserver 9332 11240 [mHTTP GET /static/admin/img/icon-changelink.svg 200 [0.04, 127.0.0.1:55065][0m
INFO 2025-07-31 09:28:19,982 runserver 9332 11240 [mHTTP GET /admin/challenge/propfirmchallenge/ 200 [3.68, 127.0.0.1:55065][0m
INFO 2025-07-31 09:28:20,084 runserver 9332 11240 [mHTTP GET /static/admin/css/changelists.css 200 [0.04, 127.0.0.1:55065][0m
INFO 2025-07-31 09:28:20,115 runserver 9332 11240 [mHTTP GET /static/admin/js/jquery.init.js 200 [0.06, 127.0.0.1:55087][0m
INFO 2025-07-31 09:28:20,126 runserver 9332 11240 [mHTTP GET /static/admin/js/core.js 200 [0.07, 127.0.0.1:55088][0m
INFO 2025-07-31 09:28:20,136 runserver 9332 11240 [mHTTP GET /static/admin/js/admin/RelatedObjectLookups.js 200 [0.08, 127.0.0.1:55089][0m
INFO 2025-07-31 09:28:20,141 runserver 9332 11240 [mHTTP GET /static/admin/js/actions.js 200 [0.05, 127.0.0.1:55065][0m
INFO 2025-07-31 09:28:20,148 runserver 9332 11240 [mHTTP GET /static/admin/js/urlify.js 200 [0.03, 127.0.0.1:55087][0m
INFO 2025-07-31 09:28:20,162 runserver 9332 11240 [mHTTP GET /static/admin/js/prepopulate.js 200 [0.03, 127.0.0.1:55088][0m
INFO 2025-07-31 09:28:20,209 runserver 9332 11240 [mHTTP GET /static/admin/js/vendor/jquery/jquery.js 200 [0.15, 127.0.0.1:55063][0m
INFO 2025-07-31 09:28:20,261 runserver 9332 11240 [mHTTP GET /static/admin/js/vendor/xregexp/xregexp.js 200 [0.12, 127.0.0.1:55089][0m
INFO 2025-07-31 09:28:20,307 runserver 9332 11240 [mHTTP GET /static/admin/js/filters.js 200 [0.04, 127.0.0.1:55089][0m
INFO 2025-07-31 09:28:21,870 runserver 9332 11240 [mHTTP GET /admin/jsi18n/ 200 [1.82, 127.0.0.1:55064][0m
INFO 2025-07-31 09:28:21,919 runserver 9332 11240 [mHTTP GET /static/admin/img/tooltag-add.svg 200 [0.01, 127.0.0.1:55064][0m
INFO 2025-07-31 09:28:27,469 runserver 9332 11240 [mHTTP GET /admin/challenge/propfirmchallenge/add/ 200 [3.00, 127.0.0.1:55064][0m
INFO 2025-07-31 09:28:27,591 runserver 9332 11240 [mHTTP GET /static/admin/css/forms.css 200 [0.06, 127.0.0.1:55064][0m
INFO 2025-07-31 09:28:27,620 runserver 9332 11240 [mHTTP GET /static/admin/js/prepopulate_init.js 200 [0.08, 127.0.0.1:55089][0m
INFO 2025-07-31 09:28:27,636 runserver 9332 11240 [mHTTP GET /static/admin/css/widgets.css 200 [0.03, 127.0.0.1:55064][0m
INFO 2025-07-31 09:28:27,682 runserver 9332 11240 [mHTTP GET /static/admin/js/change_form.js 200 [0.04, 127.0.0.1:55064][0m
INFO 2025-07-31 09:28:29,539 runserver 9332 11240 [mHTTP GET /admin/jsi18n/ 200 [2.00, 127.0.0.1:55063][0m
INFO 2025-07-31 09:33:44,803 autoreload 15780 5016 Watching for file changes with StatReloader
INFO 2025-07-31 09:34:17,638 runserver 15780 21496 [mHTTP GET /admin/challenge/propfirmchallenge/ 200 [3.54, 127.0.0.1:55158][0m
INFO 2025-07-31 09:34:19,450 runserver 15780 21496 [mHTTP GET /admin/jsi18n/ 200 [1.79, 127.0.0.1:55158][0m
INFO 2025-07-31 09:34:28,984 runserver 15780 21496 [mHTTP GET /api/v1/challenge/ 200 [1.63, 127.0.0.1:55158][0m
INFO 2025-07-31 09:46:11,881 runserver 15780 21496 [32mHTTP GET /api/v1/challenge 301 [0.02, 127.0.0.1:55329][0m
INFO 2025-07-31 09:46:13,899 runserver 15780 21496 [mHTTP GET /api/v1/challenge/ 200 [2.00, 127.0.0.1:55329][0m
INFO 2025-07-31 09:46:15,431 runserver 15780 21496 [mHTTP GET /api/v1/challenge/ 200 [1.52, 127.0.0.1:55329][0m
ERROR 2025-07-31 10:06:10,386 log 15780 16676 Internal Server Error: /api/v1/challenge/
Traceback (most recent call last):
  File "C:\Users\user\Documents\venv\Lib\site-packages\django\db\backends\base\base.py", line 289, in ensure_connection
    self.connect()
  File "C:\Users\user\Documents\venv\Lib\site-packages\django\utils\asyncio.py", line 26, in inner
    return func(*args, **kwargs)
           ^^^^^^^^^^^^^^^^^^^^^
  File "C:\Users\user\Documents\venv\Lib\site-packages\django\db\backends\base\base.py", line 270, in connect
    self.connection = self.get_new_connection(conn_params)
                      ^^^^^^^^^^^^^^^^^^^^^^^^^^^^^^^^^^^^
  File "C:\Users\user\Documents\venv\Lib\site-packages\django\utils\asyncio.py", line 26, in inner
    return func(*args, **kwargs)
           ^^^^^^^^^^^^^^^^^^^^^
  File "C:\Users\user\Documents\venv\Lib\site-packages\django\db\backends\postgresql\base.py", line 275, in get_new_connection
    connection = self.Database.connect(**conn_params)
                 ^^^^^^^^^^^^^^^^^^^^^^^^^^^^^^^^^^^^
  File "C:\Users\user\Documents\venv\Lib\site-packages\psycopg2\__init__.py", line 122, in connect
    conn = _connect(dsn, connection_factory=connection_factory, **kwasync)
           ^^^^^^^^^^^^^^^^^^^^^^^^^^^^^^^^^^^^^^^^^^^^^^^^^^^^^^^^^^^^^^^
psycopg2.OperationalError: could not translate host name "victor-ao-ayomideolusola5002-b13e.h.aivencloud.com" to address: No such host is known. 


The above exception was the direct cause of the following exception:

Traceback (most recent call last):
  File "C:\Users\user\Documents\venv\Lib\site-packages\asgiref\sync.py", line 518, in thread_handler
    raise exc_info[1]
  File "C:\Users\user\Documents\venv\Lib\site-packages\django\core\handlers\exception.py", line 42, in inner
    response = await get_response(request)
               ^^^^^^^^^^^^^^^^^^^^^^^^^^^
  File "C:\Users\user\Documents\venv\Lib\site-packages\asgiref\sync.py", line 518, in thread_handler
    raise exc_info[1]
  File "C:\Users\user\Documents\venv\Lib\site-packages\django\core\handlers\base.py", line 253, in _get_response_async
    response = await wrapped_callback(
               ^^^^^^^^^^^^^^^^^^^^^^^
  File "C:\Users\user\Documents\venv\Lib\site-packages\asgiref\sync.py", line 468, in __call__
    ret = await asyncio.shield(exec_coro)
          ^^^^^^^^^^^^^^^^^^^^^^^^^^^^^^^
  File "C:\Users\user\Documents\venv\Lib\site-packages\asgiref\current_thread_executor.py", line 40, in run
    result = self.fn(*self.args, **self.kwargs)
             ^^^^^^^^^^^^^^^^^^^^^^^^^^^^^^^^^^
  File "C:\Users\user\Documents\venv\Lib\site-packages\asgiref\sync.py", line 522, in thread_handler
    return func(*args, **kwargs)
           ^^^^^^^^^^^^^^^^^^^^^
  File "C:\Users\user\Documents\venv\Lib\site-packages\django\views\decorators\csrf.py", line 56, in wrapper_view
    return view_func(*args, **kwargs)
           ^^^^^^^^^^^^^^^^^^^^^^^^^^
  File "C:\Users\user\Documents\venv\Lib\site-packages\django\views\generic\base.py", line 104, in view
    return self.dispatch(request, *args, **kwargs)
           ^^^^^^^^^^^^^^^^^^^^^^^^^^^^^^^^^^^^^^^
  File "C:\Users\user\Documents\venv\Lib\site-packages\rest_framework\views.py", line 509, in dispatch
    response = self.handle_exception(exc)
               ^^^^^^^^^^^^^^^^^^^^^^^^^^
  File "C:\Users\user\Documents\venv\Lib\site-packages\rest_framework\views.py", line 469, in handle_exception
    self.raise_uncaught_exception(exc)
  File "C:\Users\user\Documents\venv\Lib\site-packages\rest_framework\views.py", line 480, in raise_uncaught_exception
    raise exc
  File "C:\Users\user\Documents\venv\Lib\site-packages\rest_framework\views.py", line 506, in dispatch
    response = handler(request, *args, **kwargs)
               ^^^^^^^^^^^^^^^^^^^^^^^^^^^^^^^^^
  File "C:\Users\user\Documents\venv\Lib\site-packages\rest_framework\generics.py", line 199, in get
    return self.list(request, *args, **kwargs)
           ^^^^^^^^^^^^^^^^^^^^^^^^^^^^^^^^^^^
  File "C:\Users\user\Documents\venv\Lib\site-packages\rest_framework\mixins.py", line 46, in list
    return Response(serializer.data)
                    ^^^^^^^^^^^^^^^
  File "C:\Users\user\Documents\venv\Lib\site-packages\rest_framework\serializers.py", line 768, in data
    ret = super().data
          ^^^^^^^^^^^^
  File "C:\Users\user\Documents\venv\Lib\site-packages\rest_framework\serializers.py", line 253, in data
    self._data = self.to_representation(self.instance)
                 ^^^^^^^^^^^^^^^^^^^^^^^^^^^^^^^^^^^^^
  File "C:\Users\user\Documents\venv\Lib\site-packages\rest_framework\serializers.py", line 686, in to_representation
    return [
           ^
  File "C:\Users\user\Documents\venv\Lib\site-packages\django\db\models\query.py", line 398, in __iter__
    self._fetch_all()
  File "C:\Users\user\Documents\venv\Lib\site-packages\django\db\models\query.py", line 1881, in _fetch_all
    self._result_cache = list(self._iterable_class(self))
                         ^^^^^^^^^^^^^^^^^^^^^^^^^^^^^^^^
  File "C:\Users\user\Documents\venv\Lib\site-packages\django\db\models\query.py", line 91, in __iter__
    results = compiler.execute_sql(
              ^^^^^^^^^^^^^^^^^^^^^
  File "C:\Users\user\Documents\venv\Lib\site-packages\django\db\models\sql\compiler.py", line 1560, in execute_sql
    cursor = self.connection.cursor()
             ^^^^^^^^^^^^^^^^^^^^^^^^
  File "C:\Users\user\Documents\venv\Lib\site-packages\django\utils\asyncio.py", line 26, in inner
    return func(*args, **kwargs)
           ^^^^^^^^^^^^^^^^^^^^^
  File "C:\Users\user\Documents\venv\Lib\site-packages\django\db\backends\base\base.py", line 330, in cursor
    return self._cursor()
           ^^^^^^^^^^^^^^
  File "C:\Users\user\Documents\venv\Lib\site-packages\django\db\backends\base\base.py", line 306, in _cursor
    self.ensure_connection()
  File "C:\Users\user\Documents\venv\Lib\site-packages\django\utils\asyncio.py", line 26, in inner
    return func(*args, **kwargs)
           ^^^^^^^^^^^^^^^^^^^^^
  File "C:\Users\user\Documents\venv\Lib\site-packages\django\db\backends\base\base.py", line 288, in ensure_connection
    with self.wrap_database_errors:
  File "C:\Users\user\Documents\venv\Lib\site-packages\django\db\utils.py", line 91, in __exit__
    raise dj_exc_value.with_traceback(traceback) from exc_value
  File "C:\Users\user\Documents\venv\Lib\site-packages\django\db\backends\base\base.py", line 289, in ensure_connection
    self.connect()
  File "C:\Users\user\Documents\venv\Lib\site-packages\django\utils\asyncio.py", line 26, in inner
    return func(*args, **kwargs)
           ^^^^^^^^^^^^^^^^^^^^^
  File "C:\Users\user\Documents\venv\Lib\site-packages\django\db\backends\base\base.py", line 270, in connect
    self.connection = self.get_new_connection(conn_params)
                      ^^^^^^^^^^^^^^^^^^^^^^^^^^^^^^^^^^^^
  File "C:\Users\user\Documents\venv\Lib\site-packages\django\utils\asyncio.py", line 26, in inner
    return func(*args, **kwargs)
           ^^^^^^^^^^^^^^^^^^^^^
  File "C:\Users\user\Documents\venv\Lib\site-packages\django\db\backends\postgresql\base.py", line 275, in get_new_connection
    connection = self.Database.connect(**conn_params)
                 ^^^^^^^^^^^^^^^^^^^^^^^^^^^^^^^^^^^^
  File "C:\Users\user\Documents\venv\Lib\site-packages\psycopg2\__init__.py", line 122, in connect
    conn = _connect(dsn, connection_factory=connection_factory, **kwasync)
           ^^^^^^^^^^^^^^^^^^^^^^^^^^^^^^^^^^^^^^^^^^^^^^^^^^^^^^^^^^^^^^^
django.db.utils.OperationalError: could not translate host name "victor-ao-ayomideolusola5002-b13e.h.aivencloud.com" to address: No such host is known. 

ERROR 2025-07-31 10:06:10,427 runserver 15780 21496 [35;1mHTTP GET /api/v1/challenge/ 500 [0.39, 127.0.0.1:55384][0m
ERROR 2025-07-31 10:06:10,510 log 15780 16676 Internal Server Error: /api/v1/challenge/
Traceback (most recent call last):
  File "C:\Users\user\Documents\venv\Lib\site-packages\django\db\backends\base\base.py", line 289, in ensure_connection
    self.connect()
  File "C:\Users\user\Documents\venv\Lib\site-packages\django\utils\asyncio.py", line 26, in inner
    return func(*args, **kwargs)
           ^^^^^^^^^^^^^^^^^^^^^
  File "C:\Users\user\Documents\venv\Lib\site-packages\django\db\backends\base\base.py", line 270, in connect
    self.connection = self.get_new_connection(conn_params)
                      ^^^^^^^^^^^^^^^^^^^^^^^^^^^^^^^^^^^^
  File "C:\Users\user\Documents\venv\Lib\site-packages\django\utils\asyncio.py", line 26, in inner
    return func(*args, **kwargs)
           ^^^^^^^^^^^^^^^^^^^^^
  File "C:\Users\user\Documents\venv\Lib\site-packages\django\db\backends\postgresql\base.py", line 275, in get_new_connection
    connection = self.Database.connect(**conn_params)
                 ^^^^^^^^^^^^^^^^^^^^^^^^^^^^^^^^^^^^
  File "C:\Users\user\Documents\venv\Lib\site-packages\psycopg2\__init__.py", line 122, in connect
    conn = _connect(dsn, connection_factory=connection_factory, **kwasync)
           ^^^^^^^^^^^^^^^^^^^^^^^^^^^^^^^^^^^^^^^^^^^^^^^^^^^^^^^^^^^^^^^
psycopg2.OperationalError: could not translate host name "victor-ao-ayomideolusola5002-b13e.h.aivencloud.com" to address: No such host is known. 


The above exception was the direct cause of the following exception:

Traceback (most recent call last):
  File "C:\Users\user\Documents\venv\Lib\site-packages\asgiref\sync.py", line 518, in thread_handler
    raise exc_info[1]
  File "C:\Users\user\Documents\venv\Lib\site-packages\django\core\handlers\exception.py", line 42, in inner
    response = await get_response(request)
               ^^^^^^^^^^^^^^^^^^^^^^^^^^^
  File "C:\Users\user\Documents\venv\Lib\site-packages\asgiref\sync.py", line 518, in thread_handler
    raise exc_info[1]
  File "C:\Users\user\Documents\venv\Lib\site-packages\django\core\handlers\base.py", line 253, in _get_response_async
    response = await wrapped_callback(
               ^^^^^^^^^^^^^^^^^^^^^^^
  File "C:\Users\user\Documents\venv\Lib\site-packages\asgiref\sync.py", line 468, in __call__
    ret = await asyncio.shield(exec_coro)
          ^^^^^^^^^^^^^^^^^^^^^^^^^^^^^^^
  File "C:\Users\user\Documents\venv\Lib\site-packages\asgiref\current_thread_executor.py", line 40, in run
    result = self.fn(*self.args, **self.kwargs)
             ^^^^^^^^^^^^^^^^^^^^^^^^^^^^^^^^^^
  File "C:\Users\user\Documents\venv\Lib\site-packages\asgiref\sync.py", line 522, in thread_handler
    return func(*args, **kwargs)
           ^^^^^^^^^^^^^^^^^^^^^
  File "C:\Users\user\Documents\venv\Lib\site-packages\django\views\decorators\csrf.py", line 56, in wrapper_view
    return view_func(*args, **kwargs)
           ^^^^^^^^^^^^^^^^^^^^^^^^^^
  File "C:\Users\user\Documents\venv\Lib\site-packages\django\views\generic\base.py", line 104, in view
    return self.dispatch(request, *args, **kwargs)
           ^^^^^^^^^^^^^^^^^^^^^^^^^^^^^^^^^^^^^^^
  File "C:\Users\user\Documents\venv\Lib\site-packages\rest_framework\views.py", line 509, in dispatch
    response = self.handle_exception(exc)
               ^^^^^^^^^^^^^^^^^^^^^^^^^^
  File "C:\Users\user\Documents\venv\Lib\site-packages\rest_framework\views.py", line 469, in handle_exception
    self.raise_uncaught_exception(exc)
  File "C:\Users\user\Documents\venv\Lib\site-packages\rest_framework\views.py", line 480, in raise_uncaught_exception
    raise exc
  File "C:\Users\user\Documents\venv\Lib\site-packages\rest_framework\views.py", line 506, in dispatch
    response = handler(request, *args, **kwargs)
               ^^^^^^^^^^^^^^^^^^^^^^^^^^^^^^^^^
  File "C:\Users\user\Documents\venv\Lib\site-packages\rest_framework\generics.py", line 199, in get
    return self.list(request, *args, **kwargs)
           ^^^^^^^^^^^^^^^^^^^^^^^^^^^^^^^^^^^
  File "C:\Users\user\Documents\venv\Lib\site-packages\rest_framework\mixins.py", line 46, in list
    return Response(serializer.data)
                    ^^^^^^^^^^^^^^^
  File "C:\Users\user\Documents\venv\Lib\site-packages\rest_framework\serializers.py", line 768, in data
    ret = super().data
          ^^^^^^^^^^^^
  File "C:\Users\user\Documents\venv\Lib\site-packages\rest_framework\serializers.py", line 253, in data
    self._data = self.to_representation(self.instance)
                 ^^^^^^^^^^^^^^^^^^^^^^^^^^^^^^^^^^^^^
  File "C:\Users\user\Documents\venv\Lib\site-packages\rest_framework\serializers.py", line 686, in to_representation
    return [
           ^
  File "C:\Users\user\Documents\venv\Lib\site-packages\django\db\models\query.py", line 398, in __iter__
    self._fetch_all()
  File "C:\Users\user\Documents\venv\Lib\site-packages\django\db\models\query.py", line 1881, in _fetch_all
    self._result_cache = list(self._iterable_class(self))
                         ^^^^^^^^^^^^^^^^^^^^^^^^^^^^^^^^
  File "C:\Users\user\Documents\venv\Lib\site-packages\django\db\models\query.py", line 91, in __iter__
    results = compiler.execute_sql(
              ^^^^^^^^^^^^^^^^^^^^^
  File "C:\Users\user\Documents\venv\Lib\site-packages\django\db\models\sql\compiler.py", line 1560, in execute_sql
    cursor = self.connection.cursor()
             ^^^^^^^^^^^^^^^^^^^^^^^^
  File "C:\Users\user\Documents\venv\Lib\site-packages\django\utils\asyncio.py", line 26, in inner
    return func(*args, **kwargs)
           ^^^^^^^^^^^^^^^^^^^^^
  File "C:\Users\user\Documents\venv\Lib\site-packages\django\db\backends\base\base.py", line 330, in cursor
    return self._cursor()
           ^^^^^^^^^^^^^^
  File "C:\Users\user\Documents\venv\Lib\site-packages\django\db\backends\base\base.py", line 306, in _cursor
    self.ensure_connection()
  File "C:\Users\user\Documents\venv\Lib\site-packages\django\utils\asyncio.py", line 26, in inner
    return func(*args, **kwargs)
           ^^^^^^^^^^^^^^^^^^^^^
  File "C:\Users\user\Documents\venv\Lib\site-packages\django\db\backends\base\base.py", line 288, in ensure_connection
    with self.wrap_database_errors:
  File "C:\Users\user\Documents\venv\Lib\site-packages\django\db\utils.py", line 91, in __exit__
    raise dj_exc_value.with_traceback(traceback) from exc_value
  File "C:\Users\user\Documents\venv\Lib\site-packages\django\db\backends\base\base.py", line 289, in ensure_connection
    self.connect()
  File "C:\Users\user\Documents\venv\Lib\site-packages\django\utils\asyncio.py", line 26, in inner
    return func(*args, **kwargs)
           ^^^^^^^^^^^^^^^^^^^^^
  File "C:\Users\user\Documents\venv\Lib\site-packages\django\db\backends\base\base.py", line 270, in connect
    self.connection = self.get_new_connection(conn_params)
                      ^^^^^^^^^^^^^^^^^^^^^^^^^^^^^^^^^^^^
  File "C:\Users\user\Documents\venv\Lib\site-packages\django\utils\asyncio.py", line 26, in inner
    return func(*args, **kwargs)
           ^^^^^^^^^^^^^^^^^^^^^
  File "C:\Users\user\Documents\venv\Lib\site-packages\django\db\backends\postgresql\base.py", line 275, in get_new_connection
    connection = self.Database.connect(**conn_params)
                 ^^^^^^^^^^^^^^^^^^^^^^^^^^^^^^^^^^^^
  File "C:\Users\user\Documents\venv\Lib\site-packages\psycopg2\__init__.py", line 122, in connect
    conn = _connect(dsn, connection_factory=connection_factory, **kwasync)
           ^^^^^^^^^^^^^^^^^^^^^^^^^^^^^^^^^^^^^^^^^^^^^^^^^^^^^^^^^^^^^^^
django.db.utils.OperationalError: could not translate host name "victor-ao-ayomideolusola5002-b13e.h.aivencloud.com" to address: No such host is known. 

ERROR 2025-07-31 10:06:10,526 runserver 15780 21496 [35;1mHTTP GET /api/v1/challenge/ 500 [0.10, 127.0.0.1:55386][0m
ERROR 2025-07-31 10:06:31,261 log 15780 16676 Internal Server Error: /api/v1/challenge/
Traceback (most recent call last):
  File "C:\Users\user\Documents\venv\Lib\site-packages\django\db\backends\base\base.py", line 289, in ensure_connection
    self.connect()
  File "C:\Users\user\Documents\venv\Lib\site-packages\django\utils\asyncio.py", line 26, in inner
    return func(*args, **kwargs)
           ^^^^^^^^^^^^^^^^^^^^^
  File "C:\Users\user\Documents\venv\Lib\site-packages\django\db\backends\base\base.py", line 270, in connect
    self.connection = self.get_new_connection(conn_params)
                      ^^^^^^^^^^^^^^^^^^^^^^^^^^^^^^^^^^^^
  File "C:\Users\user\Documents\venv\Lib\site-packages\django\utils\asyncio.py", line 26, in inner
    return func(*args, **kwargs)
           ^^^^^^^^^^^^^^^^^^^^^
  File "C:\Users\user\Documents\venv\Lib\site-packages\django\db\backends\postgresql\base.py", line 275, in get_new_connection
    connection = self.Database.connect(**conn_params)
                 ^^^^^^^^^^^^^^^^^^^^^^^^^^^^^^^^^^^^
  File "C:\Users\user\Documents\venv\Lib\site-packages\psycopg2\__init__.py", line 122, in connect
    conn = _connect(dsn, connection_factory=connection_factory, **kwasync)
           ^^^^^^^^^^^^^^^^^^^^^^^^^^^^^^^^^^^^^^^^^^^^^^^^^^^^^^^^^^^^^^^
psycopg2.OperationalError: could not translate host name "victor-ao-ayomideolusola5002-b13e.h.aivencloud.com" to address: No such host is known. 


The above exception was the direct cause of the following exception:

Traceback (most recent call last):
  File "C:\Users\user\Documents\venv\Lib\site-packages\asgiref\sync.py", line 518, in thread_handler
    raise exc_info[1]
  File "C:\Users\user\Documents\venv\Lib\site-packages\django\core\handlers\exception.py", line 42, in inner
    response = await get_response(request)
               ^^^^^^^^^^^^^^^^^^^^^^^^^^^
  File "C:\Users\user\Documents\venv\Lib\site-packages\asgiref\sync.py", line 518, in thread_handler
    raise exc_info[1]
  File "C:\Users\user\Documents\venv\Lib\site-packages\django\core\handlers\base.py", line 253, in _get_response_async
    response = await wrapped_callback(
               ^^^^^^^^^^^^^^^^^^^^^^^
  File "C:\Users\user\Documents\venv\Lib\site-packages\asgiref\sync.py", line 468, in __call__
    ret = await asyncio.shield(exec_coro)
          ^^^^^^^^^^^^^^^^^^^^^^^^^^^^^^^
  File "C:\Users\user\Documents\venv\Lib\site-packages\asgiref\current_thread_executor.py", line 40, in run
    result = self.fn(*self.args, **self.kwargs)
             ^^^^^^^^^^^^^^^^^^^^^^^^^^^^^^^^^^
  File "C:\Users\user\Documents\venv\Lib\site-packages\asgiref\sync.py", line 522, in thread_handler
    return func(*args, **kwargs)
           ^^^^^^^^^^^^^^^^^^^^^
  File "C:\Users\user\Documents\venv\Lib\site-packages\django\views\decorators\csrf.py", line 56, in wrapper_view
    return view_func(*args, **kwargs)
           ^^^^^^^^^^^^^^^^^^^^^^^^^^
  File "C:\Users\user\Documents\venv\Lib\site-packages\django\views\generic\base.py", line 104, in view
    return self.dispatch(request, *args, **kwargs)
           ^^^^^^^^^^^^^^^^^^^^^^^^^^^^^^^^^^^^^^^
  File "C:\Users\user\Documents\venv\Lib\site-packages\rest_framework\views.py", line 509, in dispatch
    response = self.handle_exception(exc)
               ^^^^^^^^^^^^^^^^^^^^^^^^^^
  File "C:\Users\user\Documents\venv\Lib\site-packages\rest_framework\views.py", line 469, in handle_exception
    self.raise_uncaught_exception(exc)
  File "C:\Users\user\Documents\venv\Lib\site-packages\rest_framework\views.py", line 480, in raise_uncaught_exception
    raise exc
  File "C:\Users\user\Documents\venv\Lib\site-packages\rest_framework\views.py", line 506, in dispatch
    response = handler(request, *args, **kwargs)
               ^^^^^^^^^^^^^^^^^^^^^^^^^^^^^^^^^
  File "C:\Users\user\Documents\venv\Lib\site-packages\rest_framework\generics.py", line 199, in get
    return self.list(request, *args, **kwargs)
           ^^^^^^^^^^^^^^^^^^^^^^^^^^^^^^^^^^^
  File "C:\Users\user\Documents\venv\Lib\site-packages\rest_framework\mixins.py", line 46, in list
    return Response(serializer.data)
                    ^^^^^^^^^^^^^^^
  File "C:\Users\user\Documents\venv\Lib\site-packages\rest_framework\serializers.py", line 768, in data
    ret = super().data
          ^^^^^^^^^^^^
  File "C:\Users\user\Documents\venv\Lib\site-packages\rest_framework\serializers.py", line 253, in data
    self._data = self.to_representation(self.instance)
                 ^^^^^^^^^^^^^^^^^^^^^^^^^^^^^^^^^^^^^
  File "C:\Users\user\Documents\venv\Lib\site-packages\rest_framework\serializers.py", line 686, in to_representation
    return [
           ^
  File "C:\Users\user\Documents\venv\Lib\site-packages\django\db\models\query.py", line 398, in __iter__
    self._fetch_all()
  File "C:\Users\user\Documents\venv\Lib\site-packages\django\db\models\query.py", line 1881, in _fetch_all
    self._result_cache = list(self._iterable_class(self))
                         ^^^^^^^^^^^^^^^^^^^^^^^^^^^^^^^^
  File "C:\Users\user\Documents\venv\Lib\site-packages\django\db\models\query.py", line 91, in __iter__
    results = compiler.execute_sql(
              ^^^^^^^^^^^^^^^^^^^^^
  File "C:\Users\user\Documents\venv\Lib\site-packages\django\db\models\sql\compiler.py", line 1560, in execute_sql
    cursor = self.connection.cursor()
             ^^^^^^^^^^^^^^^^^^^^^^^^
  File "C:\Users\user\Documents\venv\Lib\site-packages\django\utils\asyncio.py", line 26, in inner
    return func(*args, **kwargs)
           ^^^^^^^^^^^^^^^^^^^^^
  File "C:\Users\user\Documents\venv\Lib\site-packages\django\db\backends\base\base.py", line 330, in cursor
    return self._cursor()
           ^^^^^^^^^^^^^^
  File "C:\Users\user\Documents\venv\Lib\site-packages\django\db\backends\base\base.py", line 306, in _cursor
    self.ensure_connection()
  File "C:\Users\user\Documents\venv\Lib\site-packages\django\utils\asyncio.py", line 26, in inner
    return func(*args, **kwargs)
           ^^^^^^^^^^^^^^^^^^^^^
  File "C:\Users\user\Documents\venv\Lib\site-packages\django\db\backends\base\base.py", line 288, in ensure_connection
    with self.wrap_database_errors:
  File "C:\Users\user\Documents\venv\Lib\site-packages\django\db\utils.py", line 91, in __exit__
    raise dj_exc_value.with_traceback(traceback) from exc_value
  File "C:\Users\user\Documents\venv\Lib\site-packages\django\db\backends\base\base.py", line 289, in ensure_connection
    self.connect()
  File "C:\Users\user\Documents\venv\Lib\site-packages\django\utils\asyncio.py", line 26, in inner
    return func(*args, **kwargs)
           ^^^^^^^^^^^^^^^^^^^^^
  File "C:\Users\user\Documents\venv\Lib\site-packages\django\db\backends\base\base.py", line 270, in connect
    self.connection = self.get_new_connection(conn_params)
                      ^^^^^^^^^^^^^^^^^^^^^^^^^^^^^^^^^^^^
  File "C:\Users\user\Documents\venv\Lib\site-packages\django\utils\asyncio.py", line 26, in inner
    return func(*args, **kwargs)
           ^^^^^^^^^^^^^^^^^^^^^
  File "C:\Users\user\Documents\venv\Lib\site-packages\django\db\backends\postgresql\base.py", line 275, in get_new_connection
    connection = self.Database.connect(**conn_params)
                 ^^^^^^^^^^^^^^^^^^^^^^^^^^^^^^^^^^^^
  File "C:\Users\user\Documents\venv\Lib\site-packages\psycopg2\__init__.py", line 122, in connect
    conn = _connect(dsn, connection_factory=connection_factory, **kwasync)
           ^^^^^^^^^^^^^^^^^^^^^^^^^^^^^^^^^^^^^^^^^^^^^^^^^^^^^^^^^^^^^^^
django.db.utils.OperationalError: could not translate host name "victor-ao-ayomideolusola5002-b13e.h.aivencloud.com" to address: No such host is known. 

ERROR 2025-07-31 10:06:31,275 runserver 15780 21496 [35;1mHTTP GET /api/v1/challenge/ 500 [0.11, 127.0.0.1:55386][0m
ERROR 2025-07-31 10:06:31,428 log 15780 16676 Internal Server Error: /api/v1/challenge/
Traceback (most recent call last):
  File "C:\Users\user\Documents\venv\Lib\site-packages\django\db\backends\base\base.py", line 289, in ensure_connection
    self.connect()
  File "C:\Users\user\Documents\venv\Lib\site-packages\django\utils\asyncio.py", line 26, in inner
    return func(*args, **kwargs)
           ^^^^^^^^^^^^^^^^^^^^^
  File "C:\Users\user\Documents\venv\Lib\site-packages\django\db\backends\base\base.py", line 270, in connect
    self.connection = self.get_new_connection(conn_params)
                      ^^^^^^^^^^^^^^^^^^^^^^^^^^^^^^^^^^^^
  File "C:\Users\user\Documents\venv\Lib\site-packages\django\utils\asyncio.py", line 26, in inner
    return func(*args, **kwargs)
           ^^^^^^^^^^^^^^^^^^^^^
  File "C:\Users\user\Documents\venv\Lib\site-packages\django\db\backends\postgresql\base.py", line 275, in get_new_connection
    connection = self.Database.connect(**conn_params)
                 ^^^^^^^^^^^^^^^^^^^^^^^^^^^^^^^^^^^^
  File "C:\Users\user\Documents\venv\Lib\site-packages\psycopg2\__init__.py", line 122, in connect
    conn = _connect(dsn, connection_factory=connection_factory, **kwasync)
           ^^^^^^^^^^^^^^^^^^^^^^^^^^^^^^^^^^^^^^^^^^^^^^^^^^^^^^^^^^^^^^^
psycopg2.OperationalError: could not translate host name "victor-ao-ayomideolusola5002-b13e.h.aivencloud.com" to address: No such host is known. 


The above exception was the direct cause of the following exception:

Traceback (most recent call last):
  File "C:\Users\user\Documents\venv\Lib\site-packages\asgiref\sync.py", line 518, in thread_handler
    raise exc_info[1]
  File "C:\Users\user\Documents\venv\Lib\site-packages\django\core\handlers\exception.py", line 42, in inner
    response = await get_response(request)
               ^^^^^^^^^^^^^^^^^^^^^^^^^^^
  File "C:\Users\user\Documents\venv\Lib\site-packages\asgiref\sync.py", line 518, in thread_handler
    raise exc_info[1]
  File "C:\Users\user\Documents\venv\Lib\site-packages\django\core\handlers\base.py", line 253, in _get_response_async
    response = await wrapped_callback(
               ^^^^^^^^^^^^^^^^^^^^^^^
  File "C:\Users\user\Documents\venv\Lib\site-packages\asgiref\sync.py", line 468, in __call__
    ret = await asyncio.shield(exec_coro)
          ^^^^^^^^^^^^^^^^^^^^^^^^^^^^^^^
  File "C:\Users\user\Documents\venv\Lib\site-packages\asgiref\current_thread_executor.py", line 40, in run
    result = self.fn(*self.args, **self.kwargs)
             ^^^^^^^^^^^^^^^^^^^^^^^^^^^^^^^^^^
  File "C:\Users\user\Documents\venv\Lib\site-packages\asgiref\sync.py", line 522, in thread_handler
    return func(*args, **kwargs)
           ^^^^^^^^^^^^^^^^^^^^^
  File "C:\Users\user\Documents\venv\Lib\site-packages\django\views\decorators\csrf.py", line 56, in wrapper_view
    return view_func(*args, **kwargs)
           ^^^^^^^^^^^^^^^^^^^^^^^^^^
  File "C:\Users\user\Documents\venv\Lib\site-packages\django\views\generic\base.py", line 104, in view
    return self.dispatch(request, *args, **kwargs)
           ^^^^^^^^^^^^^^^^^^^^^^^^^^^^^^^^^^^^^^^
  File "C:\Users\user\Documents\venv\Lib\site-packages\rest_framework\views.py", line 509, in dispatch
    response = self.handle_exception(exc)
               ^^^^^^^^^^^^^^^^^^^^^^^^^^
  File "C:\Users\user\Documents\venv\Lib\site-packages\rest_framework\views.py", line 469, in handle_exception
    self.raise_uncaught_exception(exc)
  File "C:\Users\user\Documents\venv\Lib\site-packages\rest_framework\views.py", line 480, in raise_uncaught_exception
    raise exc
  File "C:\Users\user\Documents\venv\Lib\site-packages\rest_framework\views.py", line 506, in dispatch
    response = handler(request, *args, **kwargs)
               ^^^^^^^^^^^^^^^^^^^^^^^^^^^^^^^^^
  File "C:\Users\user\Documents\venv\Lib\site-packages\rest_framework\generics.py", line 199, in get
    return self.list(request, *args, **kwargs)
           ^^^^^^^^^^^^^^^^^^^^^^^^^^^^^^^^^^^
  File "C:\Users\user\Documents\venv\Lib\site-packages\rest_framework\mixins.py", line 46, in list
    return Response(serializer.data)
                    ^^^^^^^^^^^^^^^
  File "C:\Users\user\Documents\venv\Lib\site-packages\rest_framework\serializers.py", line 768, in data
    ret = super().data
          ^^^^^^^^^^^^
  File "C:\Users\user\Documents\venv\Lib\site-packages\rest_framework\serializers.py", line 253, in data
    self._data = self.to_representation(self.instance)
                 ^^^^^^^^^^^^^^^^^^^^^^^^^^^^^^^^^^^^^
  File "C:\Users\user\Documents\venv\Lib\site-packages\rest_framework\serializers.py", line 686, in to_representation
    return [
           ^
  File "C:\Users\user\Documents\venv\Lib\site-packages\django\db\models\query.py", line 398, in __iter__
    self._fetch_all()
  File "C:\Users\user\Documents\venv\Lib\site-packages\django\db\models\query.py", line 1881, in _fetch_all
    self._result_cache = list(self._iterable_class(self))
                         ^^^^^^^^^^^^^^^^^^^^^^^^^^^^^^^^
  File "C:\Users\user\Documents\venv\Lib\site-packages\django\db\models\query.py", line 91, in __iter__
    results = compiler.execute_sql(
              ^^^^^^^^^^^^^^^^^^^^^
  File "C:\Users\user\Documents\venv\Lib\site-packages\django\db\models\sql\compiler.py", line 1560, in execute_sql
    cursor = self.connection.cursor()
             ^^^^^^^^^^^^^^^^^^^^^^^^
  File "C:\Users\user\Documents\venv\Lib\site-packages\django\utils\asyncio.py", line 26, in inner
    return func(*args, **kwargs)
           ^^^^^^^^^^^^^^^^^^^^^
  File "C:\Users\user\Documents\venv\Lib\site-packages\django\db\backends\base\base.py", line 330, in cursor
    return self._cursor()
           ^^^^^^^^^^^^^^
  File "C:\Users\user\Documents\venv\Lib\site-packages\django\db\backends\base\base.py", line 306, in _cursor
    self.ensure_connection()
  File "C:\Users\user\Documents\venv\Lib\site-packages\django\utils\asyncio.py", line 26, in inner
    return func(*args, **kwargs)
           ^^^^^^^^^^^^^^^^^^^^^
  File "C:\Users\user\Documents\venv\Lib\site-packages\django\db\backends\base\base.py", line 288, in ensure_connection
    with self.wrap_database_errors:
  File "C:\Users\user\Documents\venv\Lib\site-packages\django\db\utils.py", line 91, in __exit__
    raise dj_exc_value.with_traceback(traceback) from exc_value
  File "C:\Users\user\Documents\venv\Lib\site-packages\django\db\backends\base\base.py", line 289, in ensure_connection
    self.connect()
  File "C:\Users\user\Documents\venv\Lib\site-packages\django\utils\asyncio.py", line 26, in inner
    return func(*args, **kwargs)
           ^^^^^^^^^^^^^^^^^^^^^
  File "C:\Users\user\Documents\venv\Lib\site-packages\django\db\backends\base\base.py", line 270, in connect
    self.connection = self.get_new_connection(conn_params)
                      ^^^^^^^^^^^^^^^^^^^^^^^^^^^^^^^^^^^^
  File "C:\Users\user\Documents\venv\Lib\site-packages\django\utils\asyncio.py", line 26, in inner
    return func(*args, **kwargs)
           ^^^^^^^^^^^^^^^^^^^^^
  File "C:\Users\user\Documents\venv\Lib\site-packages\django\db\backends\postgresql\base.py", line 275, in get_new_connection
    connection = self.Database.connect(**conn_params)
                 ^^^^^^^^^^^^^^^^^^^^^^^^^^^^^^^^^^^^
  File "C:\Users\user\Documents\venv\Lib\site-packages\psycopg2\__init__.py", line 122, in connect
    conn = _connect(dsn, connection_factory=connection_factory, **kwasync)
           ^^^^^^^^^^^^^^^^^^^^^^^^^^^^^^^^^^^^^^^^^^^^^^^^^^^^^^^^^^^^^^^
django.db.utils.OperationalError: could not translate host name "victor-ao-ayomideolusola5002-b13e.h.aivencloud.com" to address: No such host is known. 

ERROR 2025-07-31 10:06:31,443 runserver 15780 21496 [35;1mHTTP GET /api/v1/challenge/ 500 [0.16, 127.0.0.1:55384][0m
INFO 2025-07-31 10:06:55,793 runserver 15780 21496 [mHTTP GET /api/v1/challenge/ 200 [5.19, 127.0.0.1:55440][0m
INFO 2025-07-31 10:06:56,989 runserver 15780 21496 [mHTTP GET /api/v1/challenge/ 200 [1.19, 127.0.0.1:55440][0m
INFO 2025-07-31 10:08:01,267 runserver 15780 21496 [mHTTP GET /admin/challenge/propfirmchallenge/10/change/ 200 [4.09, 127.0.0.1:55476][0m
INFO 2025-07-31 10:08:03,105 runserver 15780 21496 [mHTTP GET /admin/jsi18n/ 200 [1.77, 127.0.0.1:55476][0m
INFO 2025-07-31 10:29:09,377 runserver 15780 21496 [mHTTP GET /api/v1/challenge/ 200 [2.04, 127.0.0.1:55649][0m
INFO 2025-07-31 10:31:24,038 runserver 15780 21496 [mHTTP GET /api/v1/challenge/ 200 [2.40, 127.0.0.1:55680][0m
INFO 2025-07-31 10:31:25,586 runserver 15780 21496 [mHTTP GET /api/v1/challenge/ 200 [1.53, 127.0.0.1:55680][0m
INFO 2025-07-31 10:31:27,097 runserver 15780 21496 [mHTTP GET /api/v1/challenge/ 200 [1.50, 127.0.0.1:55682][0m
INFO 2025-07-31 10:31:28,739 runserver 15780 21496 [mHTTP GET /api/v1/challenge/ 200 [1.64, 127.0.0.1:55680][0m
INFO 2025-07-31 10:33:24,880 runserver 15780 21496 [mHTTP GET /api/v1/challenge/ 200 [2.40, 127.0.0.1:55709][0m
INFO 2025-07-31 10:33:26,609 runserver 15780 21496 [mHTTP GET /api/v1/challenge/ 200 [1.72, 127.0.0.1:55709][0m
INFO 2025-07-31 10:33:28,308 runserver 15780 21496 [mHTTP GET /api/v1/challenge/ 200 [1.69, 127.0.0.1:55711][0m
INFO 2025-07-31 10:33:29,979 runserver 15780 21496 [mHTTP GET /api/v1/challenge/ 200 [1.66, 127.0.0.1:55709][0m
INFO 2025-07-31 10:41:39,754 runserver 15780 21496 [mHTTP GET /api/v1/challenge/ 200 [3.97, 127.0.0.1:55773][0m
INFO 2025-07-31 10:41:41,391 runserver 15780 21496 [mHTTP GET /api/v1/challenge/ 200 [1.63, 127.0.0.1:55773][0m
INFO 2025-07-31 10:41:43,215 runserver 15780 21496 [mHTTP GET /api/v1/challenge/ 200 [1.82, 127.0.0.1:55775][0m
INFO 2025-07-31 10:41:44,671 runserver 15780 21496 [mHTTP GET /api/v1/challenge/ 200 [1.45, 127.0.0.1:55773][0m
INFO 2025-07-31 11:06:56,698 autoreload 15180 14000 Watching for file changes with StatReloader
INFO 2025-07-31 11:07:14,831 runserver 15180 6368 [mHTTP GET /api/v1/challenge/ 200 [1.67, 127.0.0.1:56072][0m
INFO 2025-07-31 11:07:16,463 runserver 15180 6368 [mHTTP GET /api/v1/challenge/ 200 [1.63, 127.0.0.1:56072][0m
INFO 2025-07-31 11:07:18,207 runserver 15180 6368 [mHTTP GET /api/v1/challenge/ 200 [1.73, 127.0.0.1:56074][0m
INFO 2025-07-31 11:07:19,753 runserver 15180 6368 [mHTTP GET /api/v1/challenge/ 200 [1.54, 127.0.0.1:56072][0m
INFO 2025-07-31 11:09:06,446 runserver 15180 6368 [mHTTP GET /api/v1/challenge/ 200 [1.30, 127.0.0.1:56109][0m
INFO 2025-07-31 11:09:07,664 runserver 15180 6368 [mHTTP GET /api/v1/challenge/ 200 [1.22, 127.0.0.1:56109][0m
INFO 2025-07-31 11:09:08,951 runserver 15180 6368 [mHTTP GET /api/v1/challenge/ 200 [1.27, 127.0.0.1:56111][0m
INFO 2025-07-31 11:09:10,157 runserver 15180 6368 [mHTTP GET /api/v1/challenge/ 200 [1.21, 127.0.0.1:56109][0m
INFO 2025-07-31 11:20:47,715 runserver 15180 6368 [mHTTP GET /api/v1/challenge/ 200 [2.10, 127.0.0.1:56195][0m
INFO 2025-07-31 11:33:52,452 runserver 15180 6368 [mHTTP GET /api/v1/challenge/ 200 [4.59, 127.0.0.1:56266][0m
INFO 2025-07-31 11:33:53,680 runserver 15180 6368 [mHTTP GET /api/v1/challenge/ 200 [1.23, 127.0.0.1:56266][0m
INFO 2025-07-31 11:33:54,913 runserver 15180 6368 [mHTTP GET /api/v1/challenge/ 200 [1.23, 127.0.0.1:56268][0m
INFO 2025-07-31 11:33:56,163 runserver 15180 6368 [mHTTP GET /api/v1/challenge/ 200 [1.25, 127.0.0.1:56266][0m
INFO 2025-07-31 11:34:00,899 runserver 15180 6368 [mHTTP GET /api/v1/challenge/ 200 [1.22, 127.0.0.1:56266][0m
INFO 2025-07-31 11:34:02,098 runserver 15180 6368 [mHTTP GET /api/v1/challenge/ 200 [1.20, 127.0.0.1:56268][0m
INFO 2025-07-31 11:34:03,339 runserver 15180 6368 [mHTTP GET /api/v1/challenge/ 200 [1.24, 127.0.0.1:56266][0m
INFO 2025-07-31 11:34:04,507 runserver 15180 6368 [mHTTP GET /api/v1/challenge/ 200 [1.17, 127.0.0.1:56268][0m
INFO 2025-07-31 11:39:11,400 autoreload 15180 14000 C:\Users\user\Documents\Project\stanum_web\challenge\views.py changed, reloading.
INFO 2025-07-31 11:39:13,586 autoreload 18664 18868 Watching for file changes with StatReloader
INFO 2025-07-31 11:39:39,933 autoreload 18664 18868 C:\Users\user\Documents\Project\stanum_web\challenge\urls.py changed, reloading.
INFO 2025-07-31 11:39:41,526 autoreload 16360 2148 Watching for file changes with StatReloader
INFO 2025-07-31 11:42:00,466 runserver 16360 6384 [mHTTP GET /swagger/ 200 [0.03, 127.0.0.1:56359][0m
INFO 2025-07-31 11:42:00,703 runserver 16360 6384 [mHTTP GET /swagger/?format=openapi 200 [0.02, 127.0.0.1:56359][0m
ERROR 2025-07-31 11:42:10,852 log 16360 2516 Internal Server Error: /api/v1/challenge/balance
Traceback (most recent call last):
  File "C:\Users\user\Documents\venv\Lib\site-packages\asgiref\sync.py", line 518, in thread_handler
    raise exc_info[1]
  File "C:\Users\user\Documents\venv\Lib\site-packages\django\core\handlers\exception.py", line 42, in inner
    response = await get_response(request)
               ^^^^^^^^^^^^^^^^^^^^^^^^^^^
  File "C:\Users\user\Documents\venv\Lib\site-packages\asgiref\sync.py", line 518, in thread_handler
    raise exc_info[1]
  File "C:\Users\user\Documents\venv\Lib\site-packages\django\core\handlers\base.py", line 253, in _get_response_async
    response = await wrapped_callback(
               ^^^^^^^^^^^^^^^^^^^^^^^
  File "C:\Users\user\Documents\venv\Lib\site-packages\asgiref\sync.py", line 468, in __call__
    ret = await asyncio.shield(exec_coro)
          ^^^^^^^^^^^^^^^^^^^^^^^^^^^^^^^
  File "C:\Users\user\Documents\venv\Lib\site-packages\asgiref\current_thread_executor.py", line 40, in run
    result = self.fn(*self.args, **self.kwargs)
             ^^^^^^^^^^^^^^^^^^^^^^^^^^^^^^^^^^
  File "C:\Users\user\Documents\venv\Lib\site-packages\asgiref\sync.py", line 522, in thread_handler
    return func(*args, **kwargs)
           ^^^^^^^^^^^^^^^^^^^^^
  File "C:\Users\user\Documents\venv\Lib\site-packages\django\views\decorators\csrf.py", line 56, in wrapper_view
    return view_func(*args, **kwargs)
           ^^^^^^^^^^^^^^^^^^^^^^^^^^
  File "C:\Users\user\Documents\venv\Lib\site-packages\django\views\generic\base.py", line 104, in view
    return self.dispatch(request, *args, **kwargs)
           ^^^^^^^^^^^^^^^^^^^^^^^^^^^^^^^^^^^^^^^
  File "C:\Users\user\Documents\venv\Lib\site-packages\rest_framework\views.py", line 511, in dispatch
    self.response = self.finalize_response(request, response, *args, **kwargs)
                    ^^^^^^^^^^^^^^^^^^^^^^^^^^^^^^^^^^^^^^^^^^^^^^^^^^^^^^^^^^
  File "C:\Users\user\Documents\venv\Lib\site-packages\rest_framework\views.py", line 423, in finalize_response
    assert isinstance(response, HttpResponseBase), (
AssertionError: Expected a `Response`, `HttpResponse` or `HttpStreamingResponse` to be returned from the view, but received a `<class 'list'>`
ERROR 2025-07-31 11:42:10,869 runserver 16360 6384 [35;1mHTTP GET /api/v1/challenge/balance 500 [1.64, 127.0.0.1:56359][0m
INFO 2025-07-31 11:42:47,447 autoreload 16360 2148 C:\Users\user\Documents\Project\stanum_web\challenge\views.py changed, reloading.
INFO 2025-07-31 11:42:49,091 autoreload 16140 7560 Watching for file changes with StatReloader
INFO 2025-07-31 11:43:27,415 runserver 16140 20548 [mHTTP GET /api/v1/challenge/balance 200 [3.18, 127.0.0.1:56384][0m
INFO 2025-07-31 11:57:18,263 runserver 16140 20548 [mHTTP GET /api/v1/challenge/ 200 [6.63, 127.0.0.1:56467][0m
INFO 2025-07-31 11:57:45,795 runserver 16140 20548 [mHTTP GET /api/v1/challenge/ 200 [2.12, 127.0.0.1:56467][0m
INFO 2025-07-31 11:57:47,113 runserver 16140 20548 [mHTTP GET /api/v1/challenge/ 200 [1.32, 127.0.0.1:56467][0m
INFO 2025-07-31 11:59:20,704 runserver 16140 20548 [mHTTP GET /api/v1/challenge/ 200 [2.44, 127.0.0.1:56488][0m
INFO 2025-07-31 11:59:21,964 runserver 16140 20548 [mHTTP GET /api/v1/challenge/ 200 [1.24, 127.0.0.1:56488][0m
INFO 2025-07-31 11:59:23,147 runserver 16140 20548 [mHTTP GET /api/v1/challenge/ 200 [1.18, 127.0.0.1:56490][0m
INFO 2025-07-31 11:59:24,298 runserver 16140 20548 [mHTTP GET /api/v1/challenge/ 200 [1.13, 127.0.0.1:56488][0m
INFO 2025-07-31 11:59:43,120 runserver 16140 20548 [mHTTP GET /api/v1/challenge/ 200 [2.18, 127.0.0.1:56488][0m
INFO 2025-07-31 11:59:44,368 runserver 16140 20548 [mHTTP GET /api/v1/challenge/ 200 [1.25, 127.0.0.1:56490][0m
INFO 2025-07-31 11:59:46,027 runserver 16140 20548 [mHTTP GET /api/v1/challenge/ 200 [1.65, 127.0.0.1:56488][0m
INFO 2025-07-31 11:59:47,176 runserver 16140 20548 [mHTTP GET /api/v1/challenge/ 200 [1.15, 127.0.0.1:56490][0m
INFO 2025-07-31 12:06:01,366 runserver 16140 20548 [mHTTP GET /api/v1/challenge/ 200 [2.35, 127.0.0.1:56713][0m
INFO 2025-07-31 12:06:02,657 runserver 16140 20548 [mHTTP GET /api/v1/challenge/ 200 [1.29, 127.0.0.1:56713][0m
INFO 2025-07-31 12:06:03,883 runserver 16140 20548 [mHTTP GET /api/v1/challenge/ 200 [1.22, 127.0.0.1:56715][0m
INFO 2025-07-31 12:06:05,167 runserver 16140 20548 [mHTTP GET /api/v1/challenge/ 200 [1.28, 127.0.0.1:56713][0m
INFO 2025-07-31 12:07:13,463 runserver 16140 20548 [mHTTP GET /api/v1/challenge/ 200 [2.57, 127.0.0.1:56757][0m
INFO 2025-07-31 12:07:14,737 runserver 16140 20548 [mHTTP GET /api/v1/challenge/ 200 [1.27, 127.0.0.1:56757][0m
INFO 2025-07-31 12:07:15,992 runserver 16140 20548 [mHTTP GET /api/v1/challenge/ 200 [1.25, 127.0.0.1:56760][0m
INFO 2025-07-31 12:07:17,237 runserver 16140 20548 [mHTTP GET /api/v1/challenge/ 200 [1.24, 127.0.0.1:56757][0m
INFO 2025-07-31 12:08:41,146 runserver 16140 20548 [mHTTP GET /api/v1/challenge/ 200 [1.44, 127.0.0.1:56822][0m
INFO 2025-07-31 12:08:42,432 runserver 16140 20548 [mHTTP GET /api/v1/challenge/ 200 [1.28, 127.0.0.1:56822][0m
INFO 2025-07-31 12:08:43,683 runserver 16140 20548 [mHTTP GET /api/v1/challenge/ 200 [1.25, 127.0.0.1:56825][0m
INFO 2025-07-31 12:08:44,896 runserver 16140 20548 [mHTTP GET /api/v1/challenge/ 200 [1.20, 127.0.0.1:56822][0m
WARNING 2025-07-31 12:09:13,449 log 16140 5316 Not Found: /api/v1/balance
WARNING 2025-07-31 12:09:13,451 runserver 16140 20548 [33mHTTP GET /api/v1/balance 404 [0.06, 127.0.0.1:56822][0m
WARNING 2025-07-31 12:09:13,471 log 16140 5316 Not Found: /api/v1/balance
WARNING 2025-07-31 12:09:13,472 runserver 16140 20548 [33mHTTP GET /api/v1/balance 404 [0.02, 127.0.0.1:56822][0m
INFO 2025-07-31 12:09:15,163 runserver 16140 20548 [mHTTP GET /api/v1/challenge/ 200 [1.74, 127.0.0.1:56825][0m
INFO 2025-07-31 12:09:16,473 runserver 16140 20548 [mHTTP GET /api/v1/challenge/ 200 [1.31, 127.0.0.1:56822][0m
INFO 2025-07-31 12:09:51,213 runserver 16140 20548 [mHTTP GET /api/v1/challenge/balance 200 [2.17, 127.0.0.1:56822][0m
INFO 2025-07-31 12:09:51,229 runserver 16140 20548 [mHTTP GET /api/v1/challenge/ 200 [2.16, 127.0.0.1:56825][0m
INFO 2025-07-31 12:09:52,438 runserver 16140 20548 [mHTTP GET /api/v1/challenge/balance 200 [1.22, 127.0.0.1:56822][0m
INFO 2025-07-31 12:09:52,554 runserver 16140 20548 [mHTTP GET /api/v1/challenge/ 200 [1.32, 127.0.0.1:56825][0m
INFO 2025-07-31 12:10:48,596 runserver 16140 20548 [mHTTP GET /api/v1/challenge/ 200 [1.39, 127.0.0.1:56822][0m
INFO 2025-07-31 12:10:48,596 runserver 16140 20548 [mHTTP GET /api/v1/challenge/balance 200 [1.44, 127.0.0.1:56825][0m
INFO 2025-07-31 12:17:18,885 autoreload 16140 7560 C:\Users\user\Documents\Project\stanum_web\challenge\views.py changed, reloading.
INFO 2025-07-31 12:17:20,498 autoreload 10784 6780 Watching for file changes with StatReloader
INFO 2025-07-31 12:17:31,760 runserver 10784 15584 [mHTTP GET /api/v1/challenge/balance 200 [1.62, 127.0.0.1:56956][0m
INFO 2025-07-31 12:17:31,791 runserver 10784 15584 [mHTTP GET /api/v1/challenge/ 200 [1.63, 127.0.0.1:56958][0m
INFO 2025-07-31 12:17:33,319 runserver 10784 15584 [mHTTP GET /api/v1/challenge/balance 200 [1.54, 127.0.0.1:56956][0m
INFO 2025-07-31 12:17:34,218 runserver 10784 15584 [mHTTP GET /api/v1/challenge/ 200 [2.43, 127.0.0.1:56958][0m
INFO 2025-07-31 12:23:15,760 runserver 10784 15584 [mHTTP GET /api/v1/challenge/balance 200 [1.52, 127.0.0.1:56988][0m
INFO 2025-07-31 12:23:15,760 runserver 10784 15584 [mHTTP GET /api/v1/challenge/ 200 [1.50, 127.0.0.1:56989][0m
INFO 2025-07-31 12:23:17,076 runserver 10784 15584 [mHTTP GET /api/v1/challenge/balance 200 [1.32, 127.0.0.1:56988][0m
INFO 2025-07-31 12:23:17,100 runserver 10784 15584 [mHTTP GET /api/v1/challenge/ 200 [1.32, 127.0.0.1:56989][0m
INFO 2025-07-31 12:23:54,294 runserver 10784 15584 [mHTTP GET /api/v1/challenge/balance 200 [2.20, 127.0.0.1:56989][0m
INFO 2025-07-31 12:23:54,400 runserver 10784 15584 [mHTTP GET /api/v1/challenge/ 200 [2.29, 127.0.0.1:56988][0m
INFO 2025-07-31 12:23:55,603 runserver 10784 15584 [mHTTP GET /api/v1/challenge/balance 200 [1.31, 127.0.0.1:56989][0m
INFO 2025-07-31 12:23:55,709 runserver 10784 15584 [mHTTP GET /api/v1/challenge/ 200 [1.31, 127.0.0.1:56992][0m
ERROR 2025-07-31 14:27:38,805 log 10784 16792 Internal Server Error: /api/v1/challenge/balance
Traceback (most recent call last):
  File "C:\Users\user\Documents\venv\Lib\site-packages\django\db\backends\base\base.py", line 289, in ensure_connection
    self.connect()
  File "C:\Users\user\Documents\venv\Lib\site-packages\django\utils\asyncio.py", line 26, in inner
    return func(*args, **kwargs)
           ^^^^^^^^^^^^^^^^^^^^^
  File "C:\Users\user\Documents\venv\Lib\site-packages\django\db\backends\base\base.py", line 270, in connect
    self.connection = self.get_new_connection(conn_params)
                      ^^^^^^^^^^^^^^^^^^^^^^^^^^^^^^^^^^^^
  File "C:\Users\user\Documents\venv\Lib\site-packages\django\utils\asyncio.py", line 26, in inner
    return func(*args, **kwargs)
           ^^^^^^^^^^^^^^^^^^^^^
  File "C:\Users\user\Documents\venv\Lib\site-packages\django\db\backends\postgresql\base.py", line 275, in get_new_connection
    connection = self.Database.connect(**conn_params)
                 ^^^^^^^^^^^^^^^^^^^^^^^^^^^^^^^^^^^^
  File "C:\Users\user\Documents\venv\Lib\site-packages\psycopg2\__init__.py", line 122, in connect
    conn = _connect(dsn, connection_factory=connection_factory, **kwasync)
           ^^^^^^^^^^^^^^^^^^^^^^^^^^^^^^^^^^^^^^^^^^^^^^^^^^^^^^^^^^^^^^^
psycopg2.OperationalError: could not translate host name "victor-ao-ayomideolusola5002-b13e.h.aivencloud.com" to address: No such host is known. 


The above exception was the direct cause of the following exception:

Traceback (most recent call last):
  File "C:\Users\user\Documents\venv\Lib\site-packages\asgiref\sync.py", line 518, in thread_handler
    raise exc_info[1]
  File "C:\Users\user\Documents\venv\Lib\site-packages\django\core\handlers\exception.py", line 42, in inner
    response = await get_response(request)
               ^^^^^^^^^^^^^^^^^^^^^^^^^^^
  File "C:\Users\user\Documents\venv\Lib\site-packages\asgiref\sync.py", line 518, in thread_handler
    raise exc_info[1]
  File "C:\Users\user\Documents\venv\Lib\site-packages\django\core\handlers\base.py", line 253, in _get_response_async
    response = await wrapped_callback(
               ^^^^^^^^^^^^^^^^^^^^^^^
  File "C:\Users\user\Documents\venv\Lib\site-packages\asgiref\sync.py", line 468, in __call__
    ret = await asyncio.shield(exec_coro)
          ^^^^^^^^^^^^^^^^^^^^^^^^^^^^^^^
  File "C:\Users\user\Documents\venv\Lib\site-packages\asgiref\current_thread_executor.py", line 40, in run
    result = self.fn(*self.args, **self.kwargs)
             ^^^^^^^^^^^^^^^^^^^^^^^^^^^^^^^^^^
  File "C:\Users\user\Documents\venv\Lib\site-packages\asgiref\sync.py", line 522, in thread_handler
    return func(*args, **kwargs)
           ^^^^^^^^^^^^^^^^^^^^^
  File "C:\Users\user\Documents\venv\Lib\site-packages\django\views\decorators\csrf.py", line 56, in wrapper_view
    return view_func(*args, **kwargs)
           ^^^^^^^^^^^^^^^^^^^^^^^^^^
  File "C:\Users\user\Documents\venv\Lib\site-packages\django\views\generic\base.py", line 104, in view
    return self.dispatch(request, *args, **kwargs)
           ^^^^^^^^^^^^^^^^^^^^^^^^^^^^^^^^^^^^^^^
  File "C:\Users\user\Documents\venv\Lib\site-packages\rest_framework\views.py", line 509, in dispatch
    response = self.handle_exception(exc)
               ^^^^^^^^^^^^^^^^^^^^^^^^^^
  File "C:\Users\user\Documents\venv\Lib\site-packages\rest_framework\views.py", line 469, in handle_exception
    self.raise_uncaught_exception(exc)
  File "C:\Users\user\Documents\venv\Lib\site-packages\rest_framework\views.py", line 480, in raise_uncaught_exception
    raise exc
  File "C:\Users\user\Documents\venv\Lib\site-packages\rest_framework\views.py", line 506, in dispatch
    response = handler(request, *args, **kwargs)
               ^^^^^^^^^^^^^^^^^^^^^^^^^^^^^^^^^
  File "C:\Users\user\Documents\Project\stanum_web\challenge\views.py", line 30, in get
    balance = list(
              ^^^^^
  File "C:\Users\user\Documents\venv\Lib\site-packages\django\db\models\query.py", line 398, in __iter__
    self._fetch_all()
  File "C:\Users\user\Documents\venv\Lib\site-packages\django\db\models\query.py", line 1881, in _fetch_all
    self._result_cache = list(self._iterable_class(self))
                         ^^^^^^^^^^^^^^^^^^^^^^^^^^^^^^^^
  File "C:\Users\user\Documents\venv\Lib\site-packages\django\db\models\query.py", line 285, in __iter__
    for row in compiler.results_iter(
               ^^^^^^^^^^^^^^^^^^^^^^
  File "C:\Users\user\Documents\venv\Lib\site-packages\django\db\models\sql\compiler.py", line 1513, in results_iter
    results = self.execute_sql(
              ^^^^^^^^^^^^^^^^^
  File "C:\Users\user\Documents\venv\Lib\site-packages\django\db\models\sql\compiler.py", line 1560, in execute_sql
    cursor = self.connection.cursor()
             ^^^^^^^^^^^^^^^^^^^^^^^^
  File "C:\Users\user\Documents\venv\Lib\site-packages\django\utils\asyncio.py", line 26, in inner
    return func(*args, **kwargs)
           ^^^^^^^^^^^^^^^^^^^^^
  File "C:\Users\user\Documents\venv\Lib\site-packages\django\db\backends\base\base.py", line 330, in cursor
    return self._cursor()
           ^^^^^^^^^^^^^^
  File "C:\Users\user\Documents\venv\Lib\site-packages\django\db\backends\base\base.py", line 306, in _cursor
    self.ensure_connection()
  File "C:\Users\user\Documents\venv\Lib\site-packages\django\utils\asyncio.py", line 26, in inner
    return func(*args, **kwargs)
           ^^^^^^^^^^^^^^^^^^^^^
  File "C:\Users\user\Documents\venv\Lib\site-packages\django\db\backends\base\base.py", line 288, in ensure_connection
    with self.wrap_database_errors:
  File "C:\Users\user\Documents\venv\Lib\site-packages\django\db\utils.py", line 91, in __exit__
    raise dj_exc_value.with_traceback(traceback) from exc_value
  File "C:\Users\user\Documents\venv\Lib\site-packages\django\db\backends\base\base.py", line 289, in ensure_connection
    self.connect()
  File "C:\Users\user\Documents\venv\Lib\site-packages\django\utils\asyncio.py", line 26, in inner
    return func(*args, **kwargs)
           ^^^^^^^^^^^^^^^^^^^^^
  File "C:\Users\user\Documents\venv\Lib\site-packages\django\db\backends\base\base.py", line 270, in connect
    self.connection = self.get_new_connection(conn_params)
                      ^^^^^^^^^^^^^^^^^^^^^^^^^^^^^^^^^^^^
  File "C:\Users\user\Documents\venv\Lib\site-packages\django\utils\asyncio.py", line 26, in inner
    return func(*args, **kwargs)
           ^^^^^^^^^^^^^^^^^^^^^
  File "C:\Users\user\Documents\venv\Lib\site-packages\django\db\backends\postgresql\base.py", line 275, in get_new_connection
    connection = self.Database.connect(**conn_params)
                 ^^^^^^^^^^^^^^^^^^^^^^^^^^^^^^^^^^^^
  File "C:\Users\user\Documents\venv\Lib\site-packages\psycopg2\__init__.py", line 122, in connect
    conn = _connect(dsn, connection_factory=connection_factory, **kwasync)
           ^^^^^^^^^^^^^^^^^^^^^^^^^^^^^^^^^^^^^^^^^^^^^^^^^^^^^^^^^^^^^^^
django.db.utils.OperationalError: could not translate host name "victor-ao-ayomideolusola5002-b13e.h.aivencloud.com" to address: No such host is known. 

ERROR 2025-07-31 14:27:38,821 log 10784 12116 Internal Server Error: /api/v1/challenge/
Traceback (most recent call last):
  File "C:\Users\user\Documents\venv\Lib\site-packages\django\db\backends\base\base.py", line 289, in ensure_connection
    self.connect()
  File "C:\Users\user\Documents\venv\Lib\site-packages\django\utils\asyncio.py", line 26, in inner
    return func(*args, **kwargs)
           ^^^^^^^^^^^^^^^^^^^^^
  File "C:\Users\user\Documents\venv\Lib\site-packages\django\db\backends\base\base.py", line 270, in connect
    self.connection = self.get_new_connection(conn_params)
                      ^^^^^^^^^^^^^^^^^^^^^^^^^^^^^^^^^^^^
  File "C:\Users\user\Documents\venv\Lib\site-packages\django\utils\asyncio.py", line 26, in inner
    return func(*args, **kwargs)
           ^^^^^^^^^^^^^^^^^^^^^
  File "C:\Users\user\Documents\venv\Lib\site-packages\django\db\backends\postgresql\base.py", line 275, in get_new_connection
    connection = self.Database.connect(**conn_params)
                 ^^^^^^^^^^^^^^^^^^^^^^^^^^^^^^^^^^^^
  File "C:\Users\user\Documents\venv\Lib\site-packages\psycopg2\__init__.py", line 122, in connect
    conn = _connect(dsn, connection_factory=connection_factory, **kwasync)
           ^^^^^^^^^^^^^^^^^^^^^^^^^^^^^^^^^^^^^^^^^^^^^^^^^^^^^^^^^^^^^^^
psycopg2.OperationalError: could not translate host name "victor-ao-ayomideolusola5002-b13e.h.aivencloud.com" to address: No such host is known. 


The above exception was the direct cause of the following exception:

Traceback (most recent call last):
  File "C:\Users\user\Documents\venv\Lib\site-packages\asgiref\sync.py", line 518, in thread_handler
    raise exc_info[1]
  File "C:\Users\user\Documents\venv\Lib\site-packages\django\core\handlers\exception.py", line 42, in inner
    response = await get_response(request)
               ^^^^^^^^^^^^^^^^^^^^^^^^^^^
  File "C:\Users\user\Documents\venv\Lib\site-packages\asgiref\sync.py", line 518, in thread_handler
    raise exc_info[1]
  File "C:\Users\user\Documents\venv\Lib\site-packages\django\core\handlers\base.py", line 253, in _get_response_async
    response = await wrapped_callback(
               ^^^^^^^^^^^^^^^^^^^^^^^
  File "C:\Users\user\Documents\venv\Lib\site-packages\asgiref\sync.py", line 468, in __call__
    ret = await asyncio.shield(exec_coro)
          ^^^^^^^^^^^^^^^^^^^^^^^^^^^^^^^
  File "C:\Users\user\Documents\venv\Lib\site-packages\asgiref\current_thread_executor.py", line 40, in run
    result = self.fn(*self.args, **self.kwargs)
             ^^^^^^^^^^^^^^^^^^^^^^^^^^^^^^^^^^
  File "C:\Users\user\Documents\venv\Lib\site-packages\asgiref\sync.py", line 522, in thread_handler
    return func(*args, **kwargs)
           ^^^^^^^^^^^^^^^^^^^^^
  File "C:\Users\user\Documents\venv\Lib\site-packages\django\views\decorators\csrf.py", line 56, in wrapper_view
    return view_func(*args, **kwargs)
           ^^^^^^^^^^^^^^^^^^^^^^^^^^
  File "C:\Users\user\Documents\venv\Lib\site-packages\django\views\generic\base.py", line 104, in view
    return self.dispatch(request, *args, **kwargs)
           ^^^^^^^^^^^^^^^^^^^^^^^^^^^^^^^^^^^^^^^
  File "C:\Users\user\Documents\venv\Lib\site-packages\rest_framework\views.py", line 509, in dispatch
    response = self.handle_exception(exc)
               ^^^^^^^^^^^^^^^^^^^^^^^^^^
  File "C:\Users\user\Documents\venv\Lib\site-packages\rest_framework\views.py", line 469, in handle_exception
    self.raise_uncaught_exception(exc)
  File "C:\Users\user\Documents\venv\Lib\site-packages\rest_framework\views.py", line 480, in raise_uncaught_exception
    raise exc
  File "C:\Users\user\Documents\venv\Lib\site-packages\rest_framework\views.py", line 506, in dispatch
    response = handler(request, *args, **kwargs)
               ^^^^^^^^^^^^^^^^^^^^^^^^^^^^^^^^^
  File "C:\Users\user\Documents\venv\Lib\site-packages\rest_framework\generics.py", line 199, in get
    return self.list(request, *args, **kwargs)
           ^^^^^^^^^^^^^^^^^^^^^^^^^^^^^^^^^^^
  File "C:\Users\user\Documents\venv\Lib\site-packages\rest_framework\mixins.py", line 46, in list
    return Response(serializer.data)
                    ^^^^^^^^^^^^^^^
  File "C:\Users\user\Documents\venv\Lib\site-packages\rest_framework\serializers.py", line 768, in data
    ret = super().data
          ^^^^^^^^^^^^
  File "C:\Users\user\Documents\venv\Lib\site-packages\rest_framework\serializers.py", line 253, in data
    self._data = self.to_representation(self.instance)
                 ^^^^^^^^^^^^^^^^^^^^^^^^^^^^^^^^^^^^^
  File "C:\Users\user\Documents\venv\Lib\site-packages\rest_framework\serializers.py", line 686, in to_representation
    return [
           ^
  File "C:\Users\user\Documents\venv\Lib\site-packages\django\db\models\query.py", line 398, in __iter__
    self._fetch_all()
  File "C:\Users\user\Documents\venv\Lib\site-packages\django\db\models\query.py", line 1881, in _fetch_all
    self._result_cache = list(self._iterable_class(self))
                         ^^^^^^^^^^^^^^^^^^^^^^^^^^^^^^^^
  File "C:\Users\user\Documents\venv\Lib\site-packages\django\db\models\query.py", line 91, in __iter__
    results = compiler.execute_sql(
              ^^^^^^^^^^^^^^^^^^^^^
  File "C:\Users\user\Documents\venv\Lib\site-packages\django\db\models\sql\compiler.py", line 1560, in execute_sql
    cursor = self.connection.cursor()
             ^^^^^^^^^^^^^^^^^^^^^^^^
  File "C:\Users\user\Documents\venv\Lib\site-packages\django\utils\asyncio.py", line 26, in inner
    return func(*args, **kwargs)
           ^^^^^^^^^^^^^^^^^^^^^
  File "C:\Users\user\Documents\venv\Lib\site-packages\django\db\backends\base\base.py", line 330, in cursor
    return self._cursor()
           ^^^^^^^^^^^^^^
  File "C:\Users\user\Documents\venv\Lib\site-packages\django\db\backends\base\base.py", line 306, in _cursor
    self.ensure_connection()
  File "C:\Users\user\Documents\venv\Lib\site-packages\django\utils\asyncio.py", line 26, in inner
    return func(*args, **kwargs)
           ^^^^^^^^^^^^^^^^^^^^^
  File "C:\Users\user\Documents\venv\Lib\site-packages\django\db\backends\base\base.py", line 288, in ensure_connection
    with self.wrap_database_errors:
  File "C:\Users\user\Documents\venv\Lib\site-packages\django\db\utils.py", line 91, in __exit__
    raise dj_exc_value.with_traceback(traceback) from exc_value
  File "C:\Users\user\Documents\venv\Lib\site-packages\django\db\backends\base\base.py", line 289, in ensure_connection
    self.connect()
  File "C:\Users\user\Documents\venv\Lib\site-packages\django\utils\asyncio.py", line 26, in inner
    return func(*args, **kwargs)
           ^^^^^^^^^^^^^^^^^^^^^
  File "C:\Users\user\Documents\venv\Lib\site-packages\django\db\backends\base\base.py", line 270, in connect
    self.connection = self.get_new_connection(conn_params)
                      ^^^^^^^^^^^^^^^^^^^^^^^^^^^^^^^^^^^^
  File "C:\Users\user\Documents\venv\Lib\site-packages\django\utils\asyncio.py", line 26, in inner
    return func(*args, **kwargs)
           ^^^^^^^^^^^^^^^^^^^^^
  File "C:\Users\user\Documents\venv\Lib\site-packages\django\db\backends\postgresql\base.py", line 275, in get_new_connection
    connection = self.Database.connect(**conn_params)
                 ^^^^^^^^^^^^^^^^^^^^^^^^^^^^^^^^^^^^
  File "C:\Users\user\Documents\venv\Lib\site-packages\psycopg2\__init__.py", line 122, in connect
    conn = _connect(dsn, connection_factory=connection_factory, **kwasync)
           ^^^^^^^^^^^^^^^^^^^^^^^^^^^^^^^^^^^^^^^^^^^^^^^^^^^^^^^^^^^^^^^
django.db.utils.OperationalError: could not translate host name "victor-ao-ayomideolusola5002-b13e.h.aivencloud.com" to address: No such host is known. 

ERROR 2025-07-31 14:27:38,836 runserver 10784 15584 [35;1mHTTP GET /api/v1/challenge/balance 500 [0.38, 127.0.0.1:57036][0m
ERROR 2025-07-31 14:27:38,852 runserver 10784 15584 [35;1mHTTP GET /api/v1/challenge/ 500 [0.35, 127.0.0.1:57037][0m
ERROR 2025-07-31 14:27:38,940 log 10784 12116 Internal Server Error: /api/v1/challenge/balance
Traceback (most recent call last):
  File "C:\Users\user\Documents\venv\Lib\site-packages\django\db\backends\base\base.py", line 289, in ensure_connection
    self.connect()
  File "C:\Users\user\Documents\venv\Lib\site-packages\django\utils\asyncio.py", line 26, in inner
    return func(*args, **kwargs)
           ^^^^^^^^^^^^^^^^^^^^^
  File "C:\Users\user\Documents\venv\Lib\site-packages\django\db\backends\base\base.py", line 270, in connect
    self.connection = self.get_new_connection(conn_params)
                      ^^^^^^^^^^^^^^^^^^^^^^^^^^^^^^^^^^^^
  File "C:\Users\user\Documents\venv\Lib\site-packages\django\utils\asyncio.py", line 26, in inner
    return func(*args, **kwargs)
           ^^^^^^^^^^^^^^^^^^^^^
  File "C:\Users\user\Documents\venv\Lib\site-packages\django\db\backends\postgresql\base.py", line 275, in get_new_connection
    connection = self.Database.connect(**conn_params)
                 ^^^^^^^^^^^^^^^^^^^^^^^^^^^^^^^^^^^^
  File "C:\Users\user\Documents\venv\Lib\site-packages\psycopg2\__init__.py", line 122, in connect
    conn = _connect(dsn, connection_factory=connection_factory, **kwasync)
           ^^^^^^^^^^^^^^^^^^^^^^^^^^^^^^^^^^^^^^^^^^^^^^^^^^^^^^^^^^^^^^^
psycopg2.OperationalError: could not translate host name "victor-ao-ayomideolusola5002-b13e.h.aivencloud.com" to address: No such host is known. 


The above exception was the direct cause of the following exception:

Traceback (most recent call last):
  File "C:\Users\user\Documents\venv\Lib\site-packages\asgiref\sync.py", line 518, in thread_handler
    raise exc_info[1]
  File "C:\Users\user\Documents\venv\Lib\site-packages\django\core\handlers\exception.py", line 42, in inner
    response = await get_response(request)
               ^^^^^^^^^^^^^^^^^^^^^^^^^^^
  File "C:\Users\user\Documents\venv\Lib\site-packages\asgiref\sync.py", line 518, in thread_handler
    raise exc_info[1]
  File "C:\Users\user\Documents\venv\Lib\site-packages\django\core\handlers\base.py", line 253, in _get_response_async
    response = await wrapped_callback(
               ^^^^^^^^^^^^^^^^^^^^^^^
  File "C:\Users\user\Documents\venv\Lib\site-packages\asgiref\sync.py", line 468, in __call__
    ret = await asyncio.shield(exec_coro)
          ^^^^^^^^^^^^^^^^^^^^^^^^^^^^^^^
  File "C:\Users\user\Documents\venv\Lib\site-packages\asgiref\current_thread_executor.py", line 40, in run
    result = self.fn(*self.args, **self.kwargs)
             ^^^^^^^^^^^^^^^^^^^^^^^^^^^^^^^^^^
  File "C:\Users\user\Documents\venv\Lib\site-packages\asgiref\sync.py", line 522, in thread_handler
    return func(*args, **kwargs)
           ^^^^^^^^^^^^^^^^^^^^^
  File "C:\Users\user\Documents\venv\Lib\site-packages\django\views\decorators\csrf.py", line 56, in wrapper_view
    return view_func(*args, **kwargs)
           ^^^^^^^^^^^^^^^^^^^^^^^^^^
  File "C:\Users\user\Documents\venv\Lib\site-packages\django\views\generic\base.py", line 104, in view
    return self.dispatch(request, *args, **kwargs)
           ^^^^^^^^^^^^^^^^^^^^^^^^^^^^^^^^^^^^^^^
  File "C:\Users\user\Documents\venv\Lib\site-packages\rest_framework\views.py", line 509, in dispatch
    response = self.handle_exception(exc)
               ^^^^^^^^^^^^^^^^^^^^^^^^^^
  File "C:\Users\user\Documents\venv\Lib\site-packages\rest_framework\views.py", line 469, in handle_exception
    self.raise_uncaught_exception(exc)
  File "C:\Users\user\Documents\venv\Lib\site-packages\rest_framework\views.py", line 480, in raise_uncaught_exception
    raise exc
  File "C:\Users\user\Documents\venv\Lib\site-packages\rest_framework\views.py", line 506, in dispatch
    response = handler(request, *args, **kwargs)
               ^^^^^^^^^^^^^^^^^^^^^^^^^^^^^^^^^
  File "C:\Users\user\Documents\Project\stanum_web\challenge\views.py", line 30, in get
    balance = list(
              ^^^^^
  File "C:\Users\user\Documents\venv\Lib\site-packages\django\db\models\query.py", line 398, in __iter__
    self._fetch_all()
  File "C:\Users\user\Documents\venv\Lib\site-packages\django\db\models\query.py", line 1881, in _fetch_all
    self._result_cache = list(self._iterable_class(self))
                         ^^^^^^^^^^^^^^^^^^^^^^^^^^^^^^^^
  File "C:\Users\user\Documents\venv\Lib\site-packages\django\db\models\query.py", line 285, in __iter__
    for row in compiler.results_iter(
               ^^^^^^^^^^^^^^^^^^^^^^
  File "C:\Users\user\Documents\venv\Lib\site-packages\django\db\models\sql\compiler.py", line 1513, in results_iter
    results = self.execute_sql(
              ^^^^^^^^^^^^^^^^^
  File "C:\Users\user\Documents\venv\Lib\site-packages\django\db\models\sql\compiler.py", line 1560, in execute_sql
    cursor = self.connection.cursor()
             ^^^^^^^^^^^^^^^^^^^^^^^^
  File "C:\Users\user\Documents\venv\Lib\site-packages\django\utils\asyncio.py", line 26, in inner
    return func(*args, **kwargs)
           ^^^^^^^^^^^^^^^^^^^^^
  File "C:\Users\user\Documents\venv\Lib\site-packages\django\db\backends\base\base.py", line 330, in cursor
    return self._cursor()
           ^^^^^^^^^^^^^^
  File "C:\Users\user\Documents\venv\Lib\site-packages\django\db\backends\base\base.py", line 306, in _cursor
    self.ensure_connection()
  File "C:\Users\user\Documents\venv\Lib\site-packages\django\utils\asyncio.py", line 26, in inner
    return func(*args, **kwargs)
           ^^^^^^^^^^^^^^^^^^^^^
  File "C:\Users\user\Documents\venv\Lib\site-packages\django\db\backends\base\base.py", line 288, in ensure_connection
    with self.wrap_database_errors:
  File "C:\Users\user\Documents\venv\Lib\site-packages\django\db\utils.py", line 91, in __exit__
    raise dj_exc_value.with_traceback(traceback) from exc_value
  File "C:\Users\user\Documents\venv\Lib\site-packages\django\db\backends\base\base.py", line 289, in ensure_connection
    self.connect()
  File "C:\Users\user\Documents\venv\Lib\site-packages\django\utils\asyncio.py", line 26, in inner
    return func(*args, **kwargs)
           ^^^^^^^^^^^^^^^^^^^^^
  File "C:\Users\user\Documents\venv\Lib\site-packages\django\db\backends\base\base.py", line 270, in connect
    self.connection = self.get_new_connection(conn_params)
                      ^^^^^^^^^^^^^^^^^^^^^^^^^^^^^^^^^^^^
  File "C:\Users\user\Documents\venv\Lib\site-packages\django\utils\asyncio.py", line 26, in inner
    return func(*args, **kwargs)
           ^^^^^^^^^^^^^^^^^^^^^
  File "C:\Users\user\Documents\venv\Lib\site-packages\django\db\backends\postgresql\base.py", line 275, in get_new_connection
    connection = self.Database.connect(**conn_params)
                 ^^^^^^^^^^^^^^^^^^^^^^^^^^^^^^^^^^^^
  File "C:\Users\user\Documents\venv\Lib\site-packages\psycopg2\__init__.py", line 122, in connect
    conn = _connect(dsn, connection_factory=connection_factory, **kwasync)
           ^^^^^^^^^^^^^^^^^^^^^^^^^^^^^^^^^^^^^^^^^^^^^^^^^^^^^^^^^^^^^^^
django.db.utils.OperationalError: could not translate host name "victor-ao-ayomideolusola5002-b13e.h.aivencloud.com" to address: No such host is known. 

ERROR 2025-07-31 14:27:38,987 log 10784 16792 Internal Server Error: /api/v1/challenge/
Traceback (most recent call last):
  File "C:\Users\user\Documents\venv\Lib\site-packages\django\db\backends\base\base.py", line 289, in ensure_connection
    self.connect()
  File "C:\Users\user\Documents\venv\Lib\site-packages\django\utils\asyncio.py", line 26, in inner
    return func(*args, **kwargs)
           ^^^^^^^^^^^^^^^^^^^^^
  File "C:\Users\user\Documents\venv\Lib\site-packages\django\db\backends\base\base.py", line 270, in connect
    self.connection = self.get_new_connection(conn_params)
                      ^^^^^^^^^^^^^^^^^^^^^^^^^^^^^^^^^^^^
  File "C:\Users\user\Documents\venv\Lib\site-packages\django\utils\asyncio.py", line 26, in inner
    return func(*args, **kwargs)
           ^^^^^^^^^^^^^^^^^^^^^
  File "C:\Users\user\Documents\venv\Lib\site-packages\django\db\backends\postgresql\base.py", line 275, in get_new_connection
    connection = self.Database.connect(**conn_params)
                 ^^^^^^^^^^^^^^^^^^^^^^^^^^^^^^^^^^^^
  File "C:\Users\user\Documents\venv\Lib\site-packages\psycopg2\__init__.py", line 122, in connect
    conn = _connect(dsn, connection_factory=connection_factory, **kwasync)
           ^^^^^^^^^^^^^^^^^^^^^^^^^^^^^^^^^^^^^^^^^^^^^^^^^^^^^^^^^^^^^^^
psycopg2.OperationalError: could not translate host name "victor-ao-ayomideolusola5002-b13e.h.aivencloud.com" to address: No such host is known. 


The above exception was the direct cause of the following exception:

Traceback (most recent call last):
  File "C:\Users\user\Documents\venv\Lib\site-packages\asgiref\sync.py", line 518, in thread_handler
    raise exc_info[1]
  File "C:\Users\user\Documents\venv\Lib\site-packages\django\core\handlers\exception.py", line 42, in inner
    response = await get_response(request)
               ^^^^^^^^^^^^^^^^^^^^^^^^^^^
  File "C:\Users\user\Documents\venv\Lib\site-packages\asgiref\sync.py", line 518, in thread_handler
    raise exc_info[1]
  File "C:\Users\user\Documents\venv\Lib\site-packages\django\core\handlers\base.py", line 253, in _get_response_async
    response = await wrapped_callback(
               ^^^^^^^^^^^^^^^^^^^^^^^
  File "C:\Users\user\Documents\venv\Lib\site-packages\asgiref\sync.py", line 468, in __call__
    ret = await asyncio.shield(exec_coro)
          ^^^^^^^^^^^^^^^^^^^^^^^^^^^^^^^
  File "C:\Users\user\Documents\venv\Lib\site-packages\asgiref\current_thread_executor.py", line 40, in run
    result = self.fn(*self.args, **self.kwargs)
             ^^^^^^^^^^^^^^^^^^^^^^^^^^^^^^^^^^
  File "C:\Users\user\Documents\venv\Lib\site-packages\asgiref\sync.py", line 522, in thread_handler
    return func(*args, **kwargs)
           ^^^^^^^^^^^^^^^^^^^^^
  File "C:\Users\user\Documents\venv\Lib\site-packages\django\views\decorators\csrf.py", line 56, in wrapper_view
    return view_func(*args, **kwargs)
           ^^^^^^^^^^^^^^^^^^^^^^^^^^
  File "C:\Users\user\Documents\venv\Lib\site-packages\django\views\generic\base.py", line 104, in view
    return self.dispatch(request, *args, **kwargs)
           ^^^^^^^^^^^^^^^^^^^^^^^^^^^^^^^^^^^^^^^
  File "C:\Users\user\Documents\venv\Lib\site-packages\rest_framework\views.py", line 509, in dispatch
    response = self.handle_exception(exc)
               ^^^^^^^^^^^^^^^^^^^^^^^^^^
  File "C:\Users\user\Documents\venv\Lib\site-packages\rest_framework\views.py", line 469, in handle_exception
    self.raise_uncaught_exception(exc)
  File "C:\Users\user\Documents\venv\Lib\site-packages\rest_framework\views.py", line 480, in raise_uncaught_exception
    raise exc
  File "C:\Users\user\Documents\venv\Lib\site-packages\rest_framework\views.py", line 506, in dispatch
    response = handler(request, *args, **kwargs)
               ^^^^^^^^^^^^^^^^^^^^^^^^^^^^^^^^^
  File "C:\Users\user\Documents\venv\Lib\site-packages\rest_framework\generics.py", line 199, in get
    return self.list(request, *args, **kwargs)
           ^^^^^^^^^^^^^^^^^^^^^^^^^^^^^^^^^^^
  File "C:\Users\user\Documents\venv\Lib\site-packages\rest_framework\mixins.py", line 46, in list
    return Response(serializer.data)
                    ^^^^^^^^^^^^^^^
  File "C:\Users\user\Documents\venv\Lib\site-packages\rest_framework\serializers.py", line 768, in data
    ret = super().data
          ^^^^^^^^^^^^
  File "C:\Users\user\Documents\venv\Lib\site-packages\rest_framework\serializers.py", line 253, in data
    self._data = self.to_representation(self.instance)
                 ^^^^^^^^^^^^^^^^^^^^^^^^^^^^^^^^^^^^^
  File "C:\Users\user\Documents\venv\Lib\site-packages\rest_framework\serializers.py", line 686, in to_representation
    return [
           ^
  File "C:\Users\user\Documents\venv\Lib\site-packages\django\db\models\query.py", line 398, in __iter__
    self._fetch_all()
  File "C:\Users\user\Documents\venv\Lib\site-packages\django\db\models\query.py", line 1881, in _fetch_all
    self._result_cache = list(self._iterable_class(self))
                         ^^^^^^^^^^^^^^^^^^^^^^^^^^^^^^^^
  File "C:\Users\user\Documents\venv\Lib\site-packages\django\db\models\query.py", line 91, in __iter__
    results = compiler.execute_sql(
              ^^^^^^^^^^^^^^^^^^^^^
  File "C:\Users\user\Documents\venv\Lib\site-packages\django\db\models\sql\compiler.py", line 1560, in execute_sql
    cursor = self.connection.cursor()
             ^^^^^^^^^^^^^^^^^^^^^^^^
  File "C:\Users\user\Documents\venv\Lib\site-packages\django\utils\asyncio.py", line 26, in inner
    return func(*args, **kwargs)
           ^^^^^^^^^^^^^^^^^^^^^
  File "C:\Users\user\Documents\venv\Lib\site-packages\django\db\backends\base\base.py", line 330, in cursor
    return self._cursor()
           ^^^^^^^^^^^^^^
  File "C:\Users\user\Documents\venv\Lib\site-packages\django\db\backends\base\base.py", line 306, in _cursor
    self.ensure_connection()
  File "C:\Users\user\Documents\venv\Lib\site-packages\django\utils\asyncio.py", line 26, in inner
    return func(*args, **kwargs)
           ^^^^^^^^^^^^^^^^^^^^^
  File "C:\Users\user\Documents\venv\Lib\site-packages\django\db\backends\base\base.py", line 288, in ensure_connection
    with self.wrap_database_errors:
  File "C:\Users\user\Documents\venv\Lib\site-packages\django\db\utils.py", line 91, in __exit__
    raise dj_exc_value.with_traceback(traceback) from exc_value
  File "C:\Users\user\Documents\venv\Lib\site-packages\django\db\backends\base\base.py", line 289, in ensure_connection
    self.connect()
  File "C:\Users\user\Documents\venv\Lib\site-packages\django\utils\asyncio.py", line 26, in inner
    return func(*args, **kwargs)
           ^^^^^^^^^^^^^^^^^^^^^
  File "C:\Users\user\Documents\venv\Lib\site-packages\django\db\backends\base\base.py", line 270, in connect
    self.connection = self.get_new_connection(conn_params)
                      ^^^^^^^^^^^^^^^^^^^^^^^^^^^^^^^^^^^^
  File "C:\Users\user\Documents\venv\Lib\site-packages\django\utils\asyncio.py", line 26, in inner
    return func(*args, **kwargs)
           ^^^^^^^^^^^^^^^^^^^^^
  File "C:\Users\user\Documents\venv\Lib\site-packages\django\db\backends\postgresql\base.py", line 275, in get_new_connection
    connection = self.Database.connect(**conn_params)
                 ^^^^^^^^^^^^^^^^^^^^^^^^^^^^^^^^^^^^
  File "C:\Users\user\Documents\venv\Lib\site-packages\psycopg2\__init__.py", line 122, in connect
    conn = _connect(dsn, connection_factory=connection_factory, **kwasync)
           ^^^^^^^^^^^^^^^^^^^^^^^^^^^^^^^^^^^^^^^^^^^^^^^^^^^^^^^^^^^^^^^
django.db.utils.OperationalError: could not translate host name "victor-ao-ayomideolusola5002-b13e.h.aivencloud.com" to address: No such host is known. 

ERROR 2025-07-31 14:27:38,987 runserver 10784 15584 [35;1mHTTP GET /api/v1/challenge/balance 500 [0.15, 127.0.0.1:57038][0m
ERROR 2025-07-31 14:27:39,002 runserver 10784 15584 [35;1mHTTP GET /api/v1/challenge/ 500 [0.15, 127.0.0.1:57036][0m
INFO 2025-07-31 14:28:46,247 runserver 10784 15584 [mHTTP GET /api/v1/challenge/balance 200 [2.06, 127.0.0.1:57085][0m
INFO 2025-07-31 14:28:46,252 runserver 10784 15584 [mHTTP GET /api/v1/challenge/ 200 [2.02, 127.0.0.1:57089][0m
INFO 2025-07-31 14:28:47,804 runserver 10784 15584 [mHTTP GET /api/v1/challenge/balance 200 [1.54, 127.0.0.1:57085][0m
INFO 2025-07-31 14:28:47,815 runserver 10784 15584 [mHTTP GET /api/v1/challenge/ 200 [1.55, 127.0.0.1:57089][0m
INFO 2025-07-31 14:33:00,891 runserver 10784 15584 [mHTTP OPTIONS /api/v1/account/auth/login 200 [0.00, 127.0.0.1:57122][0m
INFO 2025-07-31 14:33:06,629 runserver 10784 15584 [mHTTP POST /api/v1/account/auth/login 200 [5.73, 127.0.0.1:57122][0m
INFO 2025-07-31 14:33:29,574 runserver 10784 15584 [mHTTP GET /api/v1/challenge/balance 200 [2.45, 127.0.0.1:57122][0m
INFO 2025-07-31 14:33:29,577 runserver 10784 15584 [mHTTP GET /api/v1/challenge/ 200 [2.43, 127.0.0.1:57126][0m
INFO 2025-07-31 14:33:31,468 runserver 10784 15584 [mHTTP GET /api/v1/challenge/balance 200 [1.89, 127.0.0.1:57122][0m
INFO 2025-07-31 14:33:31,468 runserver 10784 15584 [mHTTP GET /api/v1/challenge/ 200 [1.89, 127.0.0.1:57126][0m
INFO 2025-07-31 18:45:23,489 autoreload 21416 8504 Watching for file changes with StatReloader
INFO 2025-07-31 18:46:36,898 runserver 21416 6640 [mHTTP OPTIONS /api/v1/account/auth/login 200 [0.01, 127.0.0.1:59330][0m
INFO 2025-07-31 18:46:48,420 runserver 21416 6640 [mHTTP POST /api/v1/account/auth/login 200 [11.52, 127.0.0.1:59330][0m
INFO 2025-07-31 18:49:35,538 runserver 21416 6640 [mHTTP GET /api/v1/challenge/ 200 [4.14, 127.0.0.1:59426][0m
INFO 2025-07-31 18:49:36,690 runserver 21416 6640 [mHTTP GET /api/v1/challenge/ 200 [1.15, 127.0.0.1:59426][0m
INFO 2025-07-31 18:50:52,450 runserver 21416 6640 [mHTTP GET /api/v1/challenge/ 200 [2.53, 127.0.0.1:59449][0m
INFO 2025-07-31 18:50:53,968 runserver 21416 6640 [mHTTP GET /api/v1/challenge/ 200 [1.52, 127.0.0.1:59449][0m
INFO 2025-07-31 18:51:06,302 runserver 21416 6640 [mHTTP GET /api/v1/challenge/ 200 [1.44, 127.0.0.1:59449][0m
INFO 2025-07-31 18:51:07,675 runserver 21416 6640 [mHTTP GET /api/v1/challenge/ 200 [1.37, 127.0.0.1:59451][0m
INFO 2025-07-31 19:14:22,980 runserver 21416 6640 [mHTTP GET /swagger/ 200 [0.06, 127.0.0.1:59694][0m
INFO 2025-07-31 19:14:23,280 runserver 21416 6640 [mHTTP GET /swagger/?format=openapi 200 [0.08, 127.0.0.1:59694][0m
INFO 2025-07-31 19:14:51,712 autoreload 21416 8504 C:\Users\user\Documents\Project\stanum_web\stanum_web\urls.py changed, reloading.
INFO 2025-07-31 19:14:53,923 autoreload 1392 9396 Watching for file changes with StatReloader
INFO 2025-07-31 19:15:10,798 runserver 1392 18664 [mHTTP GET /swagger/ 200 [0.06, 127.0.0.1:59726][0m
ERROR 2025-07-31 19:15:11,319 log 1392 8048 Internal Server Error: /swagger/
Traceback (most recent call last):
  File "C:\Users\user\Documents\venv\Lib\site-packages\asgiref\sync.py", line 518, in thread_handler
    raise exc_info[1]
  File "C:\Users\user\Documents\venv\Lib\site-packages\django\core\handlers\exception.py", line 42, in inner
    response = await get_response(request)
               ^^^^^^^^^^^^^^^^^^^^^^^^^^^
  File "C:\Users\user\Documents\venv\Lib\site-packages\asgiref\sync.py", line 518, in thread_handler
    raise exc_info[1]
  File "C:\Users\user\Documents\venv\Lib\site-packages\django\core\handlers\base.py", line 253, in _get_response_async
    response = await wrapped_callback(
               ^^^^^^^^^^^^^^^^^^^^^^^
  File "C:\Users\user\Documents\venv\Lib\site-packages\asgiref\sync.py", line 468, in __call__
    ret = await asyncio.shield(exec_coro)
          ^^^^^^^^^^^^^^^^^^^^^^^^^^^^^^^
  File "C:\Users\user\Documents\venv\Lib\site-packages\asgiref\current_thread_executor.py", line 40, in run
    result = self.fn(*self.args, **self.kwargs)
             ^^^^^^^^^^^^^^^^^^^^^^^^^^^^^^^^^^
  File "C:\Users\user\Documents\venv\Lib\site-packages\asgiref\sync.py", line 522, in thread_handler
    return func(*args, **kwargs)
           ^^^^^^^^^^^^^^^^^^^^^
  File "C:\Users\user\Documents\venv\Lib\site-packages\django\views\decorators\csrf.py", line 56, in wrapper_view
    return view_func(*args, **kwargs)
           ^^^^^^^^^^^^^^^^^^^^^^^^^^
  File "C:\Users\user\Documents\venv\Lib\site-packages\django\views\generic\base.py", line 104, in view
    return self.dispatch(request, *args, **kwargs)
           ^^^^^^^^^^^^^^^^^^^^^^^^^^^^^^^^^^^^^^^
  File "C:\Users\user\Documents\venv\Lib\site-packages\rest_framework\views.py", line 509, in dispatch
    response = self.handle_exception(exc)
               ^^^^^^^^^^^^^^^^^^^^^^^^^^
  File "C:\Users\user\Documents\venv\Lib\site-packages\rest_framework\views.py", line 469, in handle_exception
    self.raise_uncaught_exception(exc)
  File "C:\Users\user\Documents\venv\Lib\site-packages\rest_framework\views.py", line 480, in raise_uncaught_exception
    raise exc
  File "C:\Users\user\Documents\venv\Lib\site-packages\rest_framework\views.py", line 506, in dispatch
    response = handler(request, *args, **kwargs)
               ^^^^^^^^^^^^^^^^^^^^^^^^^^^^^^^^^
  File "C:\Users\user\Documents\venv\Lib\site-packages\drf_yasg\views.py", line 96, in get
    schema = generator.get_schema(request, self.public)
             ^^^^^^^^^^^^^^^^^^^^^^^^^^^^^^^^^^^^^^^^^^
  File "C:\Users\user\Documents\venv\Lib\site-packages\drf_yasg\generators.py", line 276, in get_schema
    paths, prefix = self.get_paths(endpoints, components, request, public)
                    ^^^^^^^^^^^^^^^^^^^^^^^^^^^^^^^^^^^^^^^^^^^^^^^^^^^^^^
  File "C:\Users\user\Documents\venv\Lib\site-packages\drf_yasg\generators.py", line 482, in get_paths
    operation = self.get_operation(view, path, prefix, method, components, request)
                ^^^^^^^^^^^^^^^^^^^^^^^^^^^^^^^^^^^^^^^^^^^^^^^^^^^^^^^^^^^^^^^^^^^
  File "C:\Users\user\Documents\venv\Lib\site-packages\drf_yasg\generators.py", line 524, in get_operation
    operation = view_inspector.get_operation(operation_keys)
                ^^^^^^^^^^^^^^^^^^^^^^^^^^^^^^^^^^^^^^^^^^^^
  File "C:\Users\user\Documents\venv\Lib\site-packages\drf_yasg\inspectors\view.py", line 45, in get_operation
    responses = self.get_responses()
                ^^^^^^^^^^^^^^^^^^^^
  File "C:\Users\user\Documents\venv\Lib\site-packages\drf_yasg\inspectors\view.py", line 180, in get_responses
    response_serializers = self.get_response_serializers()
                           ^^^^^^^^^^^^^^^^^^^^^^^^^^^^^^^
  File "C:\Users\user\Documents\venv\Lib\site-packages\drf_yasg\inspectors\view.py", line 235, in get_response_serializers
    responses = self.get_default_responses()
                ^^^^^^^^^^^^^^^^^^^^^^^^^^^^
  File "C:\Users\user\Documents\venv\Lib\site-packages\drf_yasg\inspectors\view.py", line 211, in get_default_responses
    default_schema = self.serializer_to_schema(default_schema) or ''
                     ^^^^^^^^^^^^^^^^^^^^^^^^^^^^^^^^^^^^^^^^^
  File "C:\Users\user\Documents\venv\Lib\site-packages\drf_yasg\inspectors\base.py", line 438, in serializer_to_schema
    return self.probe_inspectors(
           ^^^^^^^^^^^^^^^^^^^^^^
  File "C:\Users\user\Documents\venv\Lib\site-packages\drf_yasg\inspectors\base.py", line 110, in probe_inspectors
    result = method(obj, **kwargs)
             ^^^^^^^^^^^^^^^^^^^^^
  File "C:\Users\user\Documents\venv\Lib\site-packages\drf_yasg\inspectors\field.py", line 38, in get_schema
    return self.probe_field_inspectors(serializer, openapi.Schema, self.use_definitions)
           ^^^^^^^^^^^^^^^^^^^^^^^^^^^^^^^^^^^^^^^^^^^^^^^^^^^^^^^^^^^^^^^^^^^^^^^^^^^^^
  File "C:\Users\user\Documents\venv\Lib\site-packages\drf_yasg\inspectors\base.py", line 228, in probe_field_inspectors
    return self.probe_inspectors(
           ^^^^^^^^^^^^^^^^^^^^^^
  File "C:\Users\user\Documents\venv\Lib\site-packages\drf_yasg\inspectors\base.py", line 110, in probe_inspectors
    result = method(obj, **kwargs)
             ^^^^^^^^^^^^^^^^^^^^^
  File "C:\Users\user\Documents\venv\Lib\site-packages\drf_yasg\inspectors\field.py", line 129, in field_to_swagger_object
    actual_schema = definitions.setdefault(ref_name, make_schema_definition)
                    ^^^^^^^^^^^^^^^^^^^^^^^^^^^^^^^^^^^^^^^^^^^^^^^^^^^^^^^^
  File "C:\Users\user\Documents\venv\Lib\site-packages\drf_yasg\openapi.py", line 685, in setdefault
    ret = maker()
          ^^^^^^^
  File "C:\Users\user\Documents\venv\Lib\site-packages\drf_yasg\inspectors\field.py", line 105, in make_schema_definition
    child_schema = self.probe_field_inspectors(
                   ^^^^^^^^^^^^^^^^^^^^^^^^^^^^
  File "C:\Users\user\Documents\venv\Lib\site-packages\drf_yasg\inspectors\base.py", line 228, in probe_field_inspectors
    return self.probe_inspectors(
           ^^^^^^^^^^^^^^^^^^^^^^
  File "C:\Users\user\Documents\venv\Lib\site-packages\drf_yasg\inspectors\base.py", line 110, in probe_inspectors
    result = method(obj, **kwargs)
             ^^^^^^^^^^^^^^^^^^^^^
  File "C:\Users\user\Documents\venv\Lib\site-packages\drf_yasg\inspectors\field.py", line 129, in field_to_swagger_object
    actual_schema = definitions.setdefault(ref_name, make_schema_definition)
                    ^^^^^^^^^^^^^^^^^^^^^^^^^^^^^^^^^^^^^^^^^^^^^^^^^^^^^^^^
  File "C:\Users\user\Documents\venv\Lib\site-packages\drf_yasg\openapi.py", line 685, in setdefault
    ret = maker()
          ^^^^^^^
  File "C:\Users\user\Documents\venv\Lib\site-packages\drf_yasg\inspectors\field.py", line 98, in make_schema_definition
    for property_name, child in serializer.fields.items():
                                ^^^^^^^^^^^^^^^^^
  File "C:\Users\user\Documents\venv\Lib\site-packages\django\utils\functional.py", line 57, in __get__
    res = instance.__dict__[self.name] = self.func(instance)
                                         ^^^^^^^^^^^^^^^^^^^
  File "C:\Users\user\Documents\venv\Lib\site-packages\rest_framework\serializers.py", line 356, in fields
    for key, value in self.get_fields().items():
                      ^^^^^^^^^^^^^^^^^
  File "C:\Users\user\Documents\venv\Lib\site-packages\rest_framework\serializers.py", line 1051, in get_fields
    info = model_meta.get_field_info(model)
           ^^^^^^^^^^^^^^^^^^^^^^^^^^^^^^^^
  File "C:\Users\user\Documents\venv\Lib\site-packages\rest_framework\utils\model_meta.py", line 39, in get_field_info
    forward_relations = _get_forward_relationships(opts)
                        ^^^^^^^^^^^^^^^^^^^^^^^^^^^^^^^^
  File "C:\Users\user\Documents\venv\Lib\site-packages\rest_framework\utils\model_meta.py", line 96, in _get_forward_relationships
    not field.remote_field.through._meta.auto_created
        ^^^^^^^^^^^^^^^^^^^^^^^^^^^^^^^^
AttributeError: 'NoneType' object has no attribute '_meta'
ERROR 2025-07-31 19:15:11,346 runserver 1392 18664 [35;1mHTTP GET /swagger/?format=openapi 500 [0.47, 127.0.0.1:59726][0m
INFO 2025-07-31 19:15:38,894 autoreload 1392 9396 C:\Users\user\Documents\Project\stanum_web\trading\urls.py changed, reloading.
INFO 2025-07-31 19:15:40,512 autoreload 13336 2004 Watching for file changes with StatReloader
INFO 2025-08-01 10:06:48,185 autoreload 13336 2004 C:\Users\user\Documents\Project\stanum_web\trading\views.py changed, reloading.
INFO 2025-08-01 10:06:52,156 autoreload 18452 8040 Watching for file changes with StatReloader
INFO 2025-08-01 10:07:44,114 autoreload 18452 8040 C:\Users\user\Documents\Project\stanum_web\trading\urls.py changed, reloading.
INFO 2025-08-01 10:07:48,156 autoreload 2592 15696 Watching for file changes with StatReloader
INFO 2025-08-01 10:10:29,744 runserver 2592 20968 [mHTTP GET /swagger/ 200 [0.09, 127.0.0.1:60181][0m
ERROR 2025-08-01 10:10:30,338 log 2592 13396 Internal Server Error: /swagger/
Traceback (most recent call last):
  File "C:\Users\user\Documents\venv\Lib\site-packages\asgiref\sync.py", line 518, in thread_handler
    raise exc_info[1]
  File "C:\Users\user\Documents\venv\Lib\site-packages\django\core\handlers\exception.py", line 42, in inner
    response = await get_response(request)
               ^^^^^^^^^^^^^^^^^^^^^^^^^^^
  File "C:\Users\user\Documents\venv\Lib\site-packages\asgiref\sync.py", line 518, in thread_handler
    raise exc_info[1]
  File "C:\Users\user\Documents\venv\Lib\site-packages\django\core\handlers\base.py", line 253, in _get_response_async
    response = await wrapped_callback(
               ^^^^^^^^^^^^^^^^^^^^^^^
  File "C:\Users\user\Documents\venv\Lib\site-packages\asgiref\sync.py", line 468, in __call__
    ret = await asyncio.shield(exec_coro)
          ^^^^^^^^^^^^^^^^^^^^^^^^^^^^^^^
  File "C:\Users\user\Documents\venv\Lib\site-packages\asgiref\current_thread_executor.py", line 40, in run
    result = self.fn(*self.args, **self.kwargs)
             ^^^^^^^^^^^^^^^^^^^^^^^^^^^^^^^^^^
  File "C:\Users\user\Documents\venv\Lib\site-packages\asgiref\sync.py", line 522, in thread_handler
    return func(*args, **kwargs)
           ^^^^^^^^^^^^^^^^^^^^^
  File "C:\Users\user\Documents\venv\Lib\site-packages\django\views\decorators\csrf.py", line 56, in wrapper_view
    return view_func(*args, **kwargs)
           ^^^^^^^^^^^^^^^^^^^^^^^^^^
  File "C:\Users\user\Documents\venv\Lib\site-packages\django\views\generic\base.py", line 104, in view
    return self.dispatch(request, *args, **kwargs)
           ^^^^^^^^^^^^^^^^^^^^^^^^^^^^^^^^^^^^^^^
  File "C:\Users\user\Documents\venv\Lib\site-packages\rest_framework\views.py", line 509, in dispatch
    response = self.handle_exception(exc)
               ^^^^^^^^^^^^^^^^^^^^^^^^^^
  File "C:\Users\user\Documents\venv\Lib\site-packages\rest_framework\views.py", line 469, in handle_exception
    self.raise_uncaught_exception(exc)
  File "C:\Users\user\Documents\venv\Lib\site-packages\rest_framework\views.py", line 480, in raise_uncaught_exception
    raise exc
  File "C:\Users\user\Documents\venv\Lib\site-packages\rest_framework\views.py", line 506, in dispatch
    response = handler(request, *args, **kwargs)
               ^^^^^^^^^^^^^^^^^^^^^^^^^^^^^^^^^
  File "C:\Users\user\Documents\venv\Lib\site-packages\drf_yasg\views.py", line 96, in get
    schema = generator.get_schema(request, self.public)
             ^^^^^^^^^^^^^^^^^^^^^^^^^^^^^^^^^^^^^^^^^^
  File "C:\Users\user\Documents\venv\Lib\site-packages\drf_yasg\generators.py", line 276, in get_schema
    paths, prefix = self.get_paths(endpoints, components, request, public)
                    ^^^^^^^^^^^^^^^^^^^^^^^^^^^^^^^^^^^^^^^^^^^^^^^^^^^^^^
  File "C:\Users\user\Documents\venv\Lib\site-packages\drf_yasg\generators.py", line 482, in get_paths
    operation = self.get_operation(view, path, prefix, method, components, request)
                ^^^^^^^^^^^^^^^^^^^^^^^^^^^^^^^^^^^^^^^^^^^^^^^^^^^^^^^^^^^^^^^^^^^
  File "C:\Users\user\Documents\venv\Lib\site-packages\drf_yasg\generators.py", line 524, in get_operation
    operation = view_inspector.get_operation(operation_keys)
                ^^^^^^^^^^^^^^^^^^^^^^^^^^^^^^^^^^^^^^^^^^^^
  File "C:\Users\user\Documents\venv\Lib\site-packages\drf_yasg\inspectors\view.py", line 45, in get_operation
    responses = self.get_responses()
                ^^^^^^^^^^^^^^^^^^^^
  File "C:\Users\user\Documents\venv\Lib\site-packages\drf_yasg\inspectors\view.py", line 180, in get_responses
    response_serializers = self.get_response_serializers()
                           ^^^^^^^^^^^^^^^^^^^^^^^^^^^^^^^
  File "C:\Users\user\Documents\venv\Lib\site-packages\drf_yasg\inspectors\view.py", line 235, in get_response_serializers
    responses = self.get_default_responses()
                ^^^^^^^^^^^^^^^^^^^^^^^^^^^^
  File "C:\Users\user\Documents\venv\Lib\site-packages\drf_yasg\inspectors\view.py", line 211, in get_default_responses
    default_schema = self.serializer_to_schema(default_schema) or ''
                     ^^^^^^^^^^^^^^^^^^^^^^^^^^^^^^^^^^^^^^^^^
  File "C:\Users\user\Documents\venv\Lib\site-packages\drf_yasg\inspectors\base.py", line 438, in serializer_to_schema
    return self.probe_inspectors(
           ^^^^^^^^^^^^^^^^^^^^^^
  File "C:\Users\user\Documents\venv\Lib\site-packages\drf_yasg\inspectors\base.py", line 110, in probe_inspectors
    result = method(obj, **kwargs)
             ^^^^^^^^^^^^^^^^^^^^^
  File "C:\Users\user\Documents\venv\Lib\site-packages\drf_yasg\inspectors\field.py", line 38, in get_schema
    return self.probe_field_inspectors(serializer, openapi.Schema, self.use_definitions)
           ^^^^^^^^^^^^^^^^^^^^^^^^^^^^^^^^^^^^^^^^^^^^^^^^^^^^^^^^^^^^^^^^^^^^^^^^^^^^^
  File "C:\Users\user\Documents\venv\Lib\site-packages\drf_yasg\inspectors\base.py", line 228, in probe_field_inspectors
    return self.probe_inspectors(
           ^^^^^^^^^^^^^^^^^^^^^^
  File "C:\Users\user\Documents\venv\Lib\site-packages\drf_yasg\inspectors\base.py", line 110, in probe_inspectors
    result = method(obj, **kwargs)
             ^^^^^^^^^^^^^^^^^^^^^
  File "C:\Users\user\Documents\venv\Lib\site-packages\drf_yasg\inspectors\field.py", line 129, in field_to_swagger_object
    actual_schema = definitions.setdefault(ref_name, make_schema_definition)
                    ^^^^^^^^^^^^^^^^^^^^^^^^^^^^^^^^^^^^^^^^^^^^^^^^^^^^^^^^
  File "C:\Users\user\Documents\venv\Lib\site-packages\drf_yasg\openapi.py", line 685, in setdefault
    ret = maker()
          ^^^^^^^
  File "C:\Users\user\Documents\venv\Lib\site-packages\drf_yasg\inspectors\field.py", line 105, in make_schema_definition
    child_schema = self.probe_field_inspectors(
                   ^^^^^^^^^^^^^^^^^^^^^^^^^^^^
  File "C:\Users\user\Documents\venv\Lib\site-packages\drf_yasg\inspectors\base.py", line 228, in probe_field_inspectors
    return self.probe_inspectors(
           ^^^^^^^^^^^^^^^^^^^^^^
  File "C:\Users\user\Documents\venv\Lib\site-packages\drf_yasg\inspectors\base.py", line 110, in probe_inspectors
    result = method(obj, **kwargs)
             ^^^^^^^^^^^^^^^^^^^^^
  File "C:\Users\user\Documents\venv\Lib\site-packages\drf_yasg\inspectors\field.py", line 129, in field_to_swagger_object
    actual_schema = definitions.setdefault(ref_name, make_schema_definition)
                    ^^^^^^^^^^^^^^^^^^^^^^^^^^^^^^^^^^^^^^^^^^^^^^^^^^^^^^^^
  File "C:\Users\user\Documents\venv\Lib\site-packages\drf_yasg\openapi.py", line 685, in setdefault
    ret = maker()
          ^^^^^^^
  File "C:\Users\user\Documents\venv\Lib\site-packages\drf_yasg\inspectors\field.py", line 98, in make_schema_definition
    for property_name, child in serializer.fields.items():
                                ^^^^^^^^^^^^^^^^^
  File "C:\Users\user\Documents\venv\Lib\site-packages\django\utils\functional.py", line 57, in __get__
    res = instance.__dict__[self.name] = self.func(instance)
                                         ^^^^^^^^^^^^^^^^^^^
  File "C:\Users\user\Documents\venv\Lib\site-packages\rest_framework\serializers.py", line 356, in fields
    for key, value in self.get_fields().items():
                      ^^^^^^^^^^^^^^^^^
  File "C:\Users\user\Documents\venv\Lib\site-packages\rest_framework\serializers.py", line 1051, in get_fields
    info = model_meta.get_field_info(model)
           ^^^^^^^^^^^^^^^^^^^^^^^^^^^^^^^^
  File "C:\Users\user\Documents\venv\Lib\site-packages\rest_framework\utils\model_meta.py", line 39, in get_field_info
    forward_relations = _get_forward_relationships(opts)
                        ^^^^^^^^^^^^^^^^^^^^^^^^^^^^^^^^
  File "C:\Users\user\Documents\venv\Lib\site-packages\rest_framework\utils\model_meta.py", line 96, in _get_forward_relationships
    not field.remote_field.through._meta.auto_created
        ^^^^^^^^^^^^^^^^^^^^^^^^^^^^^^^^
AttributeError: 'NoneType' object has no attribute '_meta'
ERROR 2025-08-01 10:10:30,357 runserver 2592 20968 [35;1mHTTP GET /swagger/?format=openapi 500 [0.14, 127.0.0.1:60181][0m
INFO 2025-08-01 10:10:57,044 autoreload 2592 15696 C:\Users\user\Documents\Project\stanum_web\trading\views.py changed, reloading.
INFO 2025-08-01 10:10:59,767 autoreload 20540 14832 Watching for file changes with StatReloader
INFO 2025-08-01 10:11:07,908 runserver 20540 15680 [mHTTP GET /swagger/ 200 [0.04, 127.0.0.1:60194][0m
ERROR 2025-08-01 10:11:08,232 log 20540 11364 Internal Server Error: /swagger/
Traceback (most recent call last):
  File "C:\Users\user\Documents\venv\Lib\site-packages\asgiref\sync.py", line 518, in thread_handler
    raise exc_info[1]
  File "C:\Users\user\Documents\venv\Lib\site-packages\django\core\handlers\exception.py", line 42, in inner
    response = await get_response(request)
               ^^^^^^^^^^^^^^^^^^^^^^^^^^^
  File "C:\Users\user\Documents\venv\Lib\site-packages\asgiref\sync.py", line 518, in thread_handler
    raise exc_info[1]
  File "C:\Users\user\Documents\venv\Lib\site-packages\django\core\handlers\base.py", line 253, in _get_response_async
    response = await wrapped_callback(
               ^^^^^^^^^^^^^^^^^^^^^^^
  File "C:\Users\user\Documents\venv\Lib\site-packages\asgiref\sync.py", line 468, in __call__
    ret = await asyncio.shield(exec_coro)
          ^^^^^^^^^^^^^^^^^^^^^^^^^^^^^^^
  File "C:\Users\user\Documents\venv\Lib\site-packages\asgiref\current_thread_executor.py", line 40, in run
    result = self.fn(*self.args, **self.kwargs)
             ^^^^^^^^^^^^^^^^^^^^^^^^^^^^^^^^^^
  File "C:\Users\user\Documents\venv\Lib\site-packages\asgiref\sync.py", line 522, in thread_handler
    return func(*args, **kwargs)
           ^^^^^^^^^^^^^^^^^^^^^
  File "C:\Users\user\Documents\venv\Lib\site-packages\django\views\decorators\csrf.py", line 56, in wrapper_view
    return view_func(*args, **kwargs)
           ^^^^^^^^^^^^^^^^^^^^^^^^^^
  File "C:\Users\user\Documents\venv\Lib\site-packages\django\views\generic\base.py", line 104, in view
    return self.dispatch(request, *args, **kwargs)
           ^^^^^^^^^^^^^^^^^^^^^^^^^^^^^^^^^^^^^^^
  File "C:\Users\user\Documents\venv\Lib\site-packages\rest_framework\views.py", line 509, in dispatch
    response = self.handle_exception(exc)
               ^^^^^^^^^^^^^^^^^^^^^^^^^^
  File "C:\Users\user\Documents\venv\Lib\site-packages\rest_framework\views.py", line 469, in handle_exception
    self.raise_uncaught_exception(exc)
  File "C:\Users\user\Documents\venv\Lib\site-packages\rest_framework\views.py", line 480, in raise_uncaught_exception
    raise exc
  File "C:\Users\user\Documents\venv\Lib\site-packages\rest_framework\views.py", line 506, in dispatch
    response = handler(request, *args, **kwargs)
               ^^^^^^^^^^^^^^^^^^^^^^^^^^^^^^^^^
  File "C:\Users\user\Documents\venv\Lib\site-packages\drf_yasg\views.py", line 96, in get
    schema = generator.get_schema(request, self.public)
             ^^^^^^^^^^^^^^^^^^^^^^^^^^^^^^^^^^^^^^^^^^
  File "C:\Users\user\Documents\venv\Lib\site-packages\drf_yasg\generators.py", line 276, in get_schema
    paths, prefix = self.get_paths(endpoints, components, request, public)
                    ^^^^^^^^^^^^^^^^^^^^^^^^^^^^^^^^^^^^^^^^^^^^^^^^^^^^^^
  File "C:\Users\user\Documents\venv\Lib\site-packages\drf_yasg\generators.py", line 482, in get_paths
    operation = self.get_operation(view, path, prefix, method, components, request)
                ^^^^^^^^^^^^^^^^^^^^^^^^^^^^^^^^^^^^^^^^^^^^^^^^^^^^^^^^^^^^^^^^^^^
  File "C:\Users\user\Documents\venv\Lib\site-packages\drf_yasg\generators.py", line 524, in get_operation
    operation = view_inspector.get_operation(operation_keys)
                ^^^^^^^^^^^^^^^^^^^^^^^^^^^^^^^^^^^^^^^^^^^^
  File "C:\Users\user\Documents\venv\Lib\site-packages\drf_yasg\inspectors\view.py", line 45, in get_operation
    responses = self.get_responses()
                ^^^^^^^^^^^^^^^^^^^^
  File "C:\Users\user\Documents\venv\Lib\site-packages\drf_yasg\inspectors\view.py", line 180, in get_responses
    response_serializers = self.get_response_serializers()
                           ^^^^^^^^^^^^^^^^^^^^^^^^^^^^^^^
  File "C:\Users\user\Documents\venv\Lib\site-packages\drf_yasg\inspectors\view.py", line 235, in get_response_serializers
    responses = self.get_default_responses()
                ^^^^^^^^^^^^^^^^^^^^^^^^^^^^
  File "C:\Users\user\Documents\venv\Lib\site-packages\drf_yasg\inspectors\view.py", line 211, in get_default_responses
    default_schema = self.serializer_to_schema(default_schema) or ''
                     ^^^^^^^^^^^^^^^^^^^^^^^^^^^^^^^^^^^^^^^^^
  File "C:\Users\user\Documents\venv\Lib\site-packages\drf_yasg\inspectors\base.py", line 438, in serializer_to_schema
    return self.probe_inspectors(
           ^^^^^^^^^^^^^^^^^^^^^^
  File "C:\Users\user\Documents\venv\Lib\site-packages\drf_yasg\inspectors\base.py", line 110, in probe_inspectors
    result = method(obj, **kwargs)
             ^^^^^^^^^^^^^^^^^^^^^
  File "C:\Users\user\Documents\venv\Lib\site-packages\drf_yasg\inspectors\field.py", line 38, in get_schema
    return self.probe_field_inspectors(serializer, openapi.Schema, self.use_definitions)
           ^^^^^^^^^^^^^^^^^^^^^^^^^^^^^^^^^^^^^^^^^^^^^^^^^^^^^^^^^^^^^^^^^^^^^^^^^^^^^
  File "C:\Users\user\Documents\venv\Lib\site-packages\drf_yasg\inspectors\base.py", line 228, in probe_field_inspectors
    return self.probe_inspectors(
           ^^^^^^^^^^^^^^^^^^^^^^
  File "C:\Users\user\Documents\venv\Lib\site-packages\drf_yasg\inspectors\base.py", line 110, in probe_inspectors
    result = method(obj, **kwargs)
             ^^^^^^^^^^^^^^^^^^^^^
  File "C:\Users\user\Documents\venv\Lib\site-packages\drf_yasg\inspectors\field.py", line 129, in field_to_swagger_object
    actual_schema = definitions.setdefault(ref_name, make_schema_definition)
                    ^^^^^^^^^^^^^^^^^^^^^^^^^^^^^^^^^^^^^^^^^^^^^^^^^^^^^^^^
  File "C:\Users\user\Documents\venv\Lib\site-packages\drf_yasg\openapi.py", line 685, in setdefault
    ret = maker()
          ^^^^^^^
  File "C:\Users\user\Documents\venv\Lib\site-packages\drf_yasg\inspectors\field.py", line 105, in make_schema_definition
    child_schema = self.probe_field_inspectors(
                   ^^^^^^^^^^^^^^^^^^^^^^^^^^^^
  File "C:\Users\user\Documents\venv\Lib\site-packages\drf_yasg\inspectors\base.py", line 228, in probe_field_inspectors
    return self.probe_inspectors(
           ^^^^^^^^^^^^^^^^^^^^^^
  File "C:\Users\user\Documents\venv\Lib\site-packages\drf_yasg\inspectors\base.py", line 110, in probe_inspectors
    result = method(obj, **kwargs)
             ^^^^^^^^^^^^^^^^^^^^^
  File "C:\Users\user\Documents\venv\Lib\site-packages\drf_yasg\inspectors\field.py", line 129, in field_to_swagger_object
    actual_schema = definitions.setdefault(ref_name, make_schema_definition)
                    ^^^^^^^^^^^^^^^^^^^^^^^^^^^^^^^^^^^^^^^^^^^^^^^^^^^^^^^^
  File "C:\Users\user\Documents\venv\Lib\site-packages\drf_yasg\openapi.py", line 685, in setdefault
    ret = maker()
          ^^^^^^^
  File "C:\Users\user\Documents\venv\Lib\site-packages\drf_yasg\inspectors\field.py", line 98, in make_schema_definition
    for property_name, child in serializer.fields.items():
                                ^^^^^^^^^^^^^^^^^
  File "C:\Users\user\Documents\venv\Lib\site-packages\django\utils\functional.py", line 57, in __get__
    res = instance.__dict__[self.name] = self.func(instance)
                                         ^^^^^^^^^^^^^^^^^^^
  File "C:\Users\user\Documents\venv\Lib\site-packages\rest_framework\serializers.py", line 356, in fields
    for key, value in self.get_fields().items():
                      ^^^^^^^^^^^^^^^^^
  File "C:\Users\user\Documents\venv\Lib\site-packages\rest_framework\serializers.py", line 1051, in get_fields
    info = model_meta.get_field_info(model)
           ^^^^^^^^^^^^^^^^^^^^^^^^^^^^^^^^
  File "C:\Users\user\Documents\venv\Lib\site-packages\rest_framework\utils\model_meta.py", line 39, in get_field_info
    forward_relations = _get_forward_relationships(opts)
                        ^^^^^^^^^^^^^^^^^^^^^^^^^^^^^^^^
  File "C:\Users\user\Documents\venv\Lib\site-packages\rest_framework\utils\model_meta.py", line 96, in _get_forward_relationships
    not field.remote_field.through._meta.auto_created
        ^^^^^^^^^^^^^^^^^^^^^^^^^^^^^^^^
AttributeError: 'NoneType' object has no attribute '_meta'
ERROR 2025-08-01 10:11:08,277 runserver 20540 15680 [35;1mHTTP GET /swagger/?format=openapi 500 [0.21, 127.0.0.1:60194][0m
INFO 2025-08-01 10:11:36,702 autoreload 20540 14832 C:\Users\user\Documents\Project\stanum_web\stanum_web\urls.py changed, reloading.
INFO 2025-08-01 10:11:40,364 autoreload 21476 13868 Watching for file changes with StatReloader
INFO 2025-08-01 10:11:48,167 runserver 21476 6028 [mHTTP GET /swagger/ 200 [0.09, 127.0.0.1:60208][0m
INFO 2025-08-01 10:11:48,318 runserver 21476 6028 [mHTTP GET /swagger/?format=openapi 200 [0.03, 127.0.0.1:60208][0m
INFO 2025-08-01 10:11:59,317 autoreload 21476 13868 C:\Users\user\Documents\Project\stanum_web\stanum_web\urls.py changed, reloading.
INFO 2025-08-01 10:12:01,966 autoreload 5064 1168 Watching for file changes with StatReloader
INFO 2025-08-01 10:12:10,475 autoreload 5064 1168 C:\Users\user\Documents\Project\stanum_web\trading\urls.py changed, reloading.
INFO 2025-08-01 10:12:13,433 autoreload 3716 3668 Watching for file changes with StatReloader
INFO 2025-08-01 10:12:21,580 runserver 3716 18708 [mHTTP GET /swagger/ 200 [0.09, 127.0.0.1:60228][0m
INFO 2025-08-01 10:12:21,710 runserver 3716 18708 [mHTTP GET /swagger/?format=openapi 200 [0.03, 127.0.0.1:60228][0m
INFO 2025-08-01 10:15:25,577 autoreload 3716 3668 C:\Users\user\Documents\Project\stanum_web\trading\serializers.py changed, reloading.
INFO 2025-08-01 10:15:28,130 autoreload 15460 8988 Watching for file changes with StatReloader
INFO 2025-08-01 10:15:33,769 autoreload 15460 8988 C:\Users\user\Documents\Project\stanum_web\trading\serializers.py changed, reloading.
INFO 2025-08-01 10:15:36,486 autoreload 12624 8928 Watching for file changes with StatReloader
INFO 2025-08-01 10:15:45,315 runserver 12624 12012 [mHTTP GET /swagger/ 200 [0.08, 127.0.0.1:60257][0m
INFO 2025-08-01 10:15:45,611 runserver 12624 12012 [mHTTP GET /swagger/?format=openapi 200 [0.03, 127.0.0.1:60257][0m
INFO 2025-08-01 10:15:53,557 autoreload 12624 8928 C:\Users\user\Documents\Project\stanum_web\trading\urls.py changed, reloading.
INFO 2025-08-01 10:15:55,889 autoreload 9360 5196 Watching for file changes with StatReloader
INFO 2025-08-01 10:16:03,556 runserver 9360 5336 [mHTTP GET /swagger/ 200 [0.09, 127.0.0.1:60271][0m
INFO 2025-08-01 10:16:03,763 runserver 9360 5336 [mHTTP GET /swagger/?format=openapi 200 [0.04, 127.0.0.1:60271][0m
INFO 2025-08-01 10:24:40,233 runserver 9360 5336 [mHTTP OPTIONS /api/v1/trading/accounts 200 [0.01, 127.0.0.1:60319][0m
WARNING 2025-08-01 10:24:42,500 log 9360 19116 Unauthorized: /api/v1/trading/accounts
WARNING 2025-08-01 10:24:42,502 runserver 9360 5336 [31;1mHTTP GET /api/v1/trading/accounts 401 [2.26, 127.0.0.1:60319][0m
INFO 2025-08-01 10:24:42,521 runserver 9360 5336 [mHTTP OPTIONS /api/v1/auth/token/refresh 200 [0.01, 127.0.0.1:60319][0m
WARNING 2025-08-01 10:24:42,616 log 9360 19116 Not Found: /api/v1/auth/token/refresh
WARNING 2025-08-01 10:24:42,617 runserver 9360 5336 [33mHTTP POST /api/v1/auth/token/refresh 404 [0.09, 127.0.0.1:60319][0m
WARNING 2025-08-01 10:24:52,491 log 9360 19116 Unauthorized: /api/v1/trading/accounts
WARNING 2025-08-01 10:24:52,492 runserver 9360 5336 [31;1mHTTP GET /api/v1/trading/accounts 401 [0.01, 127.0.0.1:60319][0m
WARNING 2025-08-01 10:24:52,503 log 9360 19116 Unauthorized: /api/v1/trading/accounts
WARNING 2025-08-01 10:24:52,503 runserver 9360 5336 [31;1mHTTP GET /api/v1/trading/accounts 401 [0.01, 127.0.0.1:60319][0m
WARNING 2025-08-01 10:24:54,107 log 9360 19116 Unauthorized: /api/v1/trading/accounts
WARNING 2025-08-01 10:24:54,107 runserver 9360 5336 [31;1mHTTP GET /api/v1/trading/accounts 401 [0.01, 127.0.0.1:60319][0m
WARNING 2025-08-01 10:24:54,118 log 9360 19116 Unauthorized: /api/v1/trading/accounts
WARNING 2025-08-01 10:24:54,121 runserver 9360 5336 [31;1mHTTP GET /api/v1/trading/accounts 401 [0.01, 127.0.0.1:60319][0m
INFO 2025-08-01 10:25:09,596 runserver 9360 5336 [mHTTP OPTIONS /api/v1/account/auth/login 200 [0.01, 127.0.0.1:60319][0m
INFO 2025-08-01 10:25:14,498 runserver 9360 5336 [mHTTP POST /api/v1/account/auth/login 200 [4.89, 127.0.0.1:60319][0m
INFO 2025-08-01 10:25:16,257 runserver 9360 5336 [mHTTP GET /api/v1/trading/accounts 200 [1.65, 127.0.0.1:60319][0m
INFO 2025-08-01 10:25:19,163 runserver 9360 5336 [mHTTP GET /api/v1/trading/accounts 200 [2.90, 127.0.0.1:60319][0m
INFO 2025-08-01 10:25:33,048 runserver 9360 5336 [mHTTP GET /api/v1/trading/accounts 200 [3.13, 127.0.0.1:60319][0m
INFO 2025-08-01 10:25:35,132 runserver 9360 5336 [mHTTP GET /api/v1/trading/accounts 200 [2.08, 127.0.0.1:60319][0m
INFO 2025-08-01 10:33:10,756 runserver 9360 5336 [mHTTP GET /api/v1/trading/accounts 200 [4.29, 127.0.0.1:60461][0m
INFO 2025-08-01 10:33:12,574 runserver 9360 5336 [mHTTP GET /api/v1/trading/accounts 200 [1.81, 127.0.0.1:60461][0m
INFO 2025-08-01 10:39:12,892 runserver 9360 5336 [mHTTP GET /api/v1/trading/accounts 200 [4.03, 127.0.0.1:60495][0m
INFO 2025-08-01 10:39:15,963 runserver 9360 5336 [mHTTP GET /api/v1/trading/accounts 200 [3.07, 127.0.0.1:60495][0m
WARNING 2025-08-01 10:41:34,717 log 9360 19116 Unauthorized: /api/v1/trading/accounts
WARNING 2025-08-01 10:41:34,719 runserver 9360 5336 [31;1mHTTP GET /api/v1/trading/accounts 401 [4.89, 127.0.0.1:60517][0m
WARNING 2025-08-01 10:41:34,800 log 9360 19116 Not Found: /api/v1/auth/token/refresh
WARNING 2025-08-01 10:41:34,802 runserver 9360 5336 [33mHTTP POST /api/v1/auth/token/refresh 404 [0.06, 127.0.0.1:60519][0m
WARNING 2025-08-01 10:41:36,660 log 9360 19116 Unauthorized: /api/v1/trading/accounts
WARNING 2025-08-01 10:41:36,663 runserver 9360 5336 [31;1mHTTP GET /api/v1/trading/accounts 401 [1.93, 127.0.0.1:60517][0m
WARNING 2025-08-01 10:42:47,520 log 9360 19116 Unauthorized: /api/v1/trading/accounts
WARNING 2025-08-01 10:42:47,521 runserver 9360 5336 [31;1mHTTP GET /api/v1/trading/accounts 401 [0.01, 127.0.0.1:60538][0m
WARNING 2025-08-01 10:42:47,530 log 9360 19116 Unauthorized: /api/v1/trading/accounts
WARNING 2025-08-01 10:42:47,533 runserver 9360 5336 [31;1mHTTP GET /api/v1/trading/accounts 401 [0.01, 127.0.0.1:60538][0m
WARNING 2025-08-01 10:44:37,836 log 9360 19116 Unauthorized: /api/v1/trading/accounts
WARNING 2025-08-01 10:44:37,838 runserver 9360 5336 [31;1mHTTP GET /api/v1/trading/accounts 401 [0.01, 127.0.0.1:60598][0m
WARNING 2025-08-01 10:44:37,900 log 9360 19116 Unauthorized: /api/v1/trading/accounts
WARNING 2025-08-01 10:44:37,903 runserver 9360 5336 [31;1mHTTP GET /api/v1/trading/accounts 401 [0.06, 127.0.0.1:60598][0m
WARNING 2025-08-01 10:44:38,982 log 9360 19116 Unauthorized: /api/v1/trading/accounts
WARNING 2025-08-01 10:44:38,983 runserver 9360 5336 [31;1mHTTP GET /api/v1/trading/accounts 401 [0.03, 127.0.0.1:60598][0m
WARNING 2025-08-01 10:44:38,996 log 9360 19116 Unauthorized: /api/v1/trading/accounts
WARNING 2025-08-01 10:44:38,999 runserver 9360 5336 [31;1mHTTP GET /api/v1/trading/accounts 401 [0.01, 127.0.0.1:60598][0m
WARNING 2025-08-01 10:45:07,359 log 9360 19116 Unauthorized: /api/v1/trading/accounts
WARNING 2025-08-01 10:45:07,360 runserver 9360 5336 [31;1mHTTP GET /api/v1/trading/accounts 401 [0.03, 127.0.0.1:60598][0m
WARNING 2025-08-01 10:45:07,374 log 9360 19116 Unauthorized: /api/v1/trading/accounts
WARNING 2025-08-01 10:45:07,376 runserver 9360 5336 [31;1mHTTP GET /api/v1/trading/accounts 401 [0.01, 127.0.0.1:60598][0m
WARNING 2025-08-01 10:45:25,834 log 9360 19116 Unauthorized: /api/v1/trading/accounts
WARNING 2025-08-01 10:45:25,836 runserver 9360 5336 [31;1mHTTP GET /api/v1/trading/accounts 401 [0.01, 127.0.0.1:60598][0m
WARNING 2025-08-01 10:45:25,850 log 9360 19116 Unauthorized: /api/v1/trading/accounts
WARNING 2025-08-01 10:45:25,852 runserver 9360 5336 [31;1mHTTP GET /api/v1/trading/accounts 401 [0.01, 127.0.0.1:60598][0m
INFO 2025-08-01 10:46:12,217 runserver 9360 5336 [mHTTP POST /api/v1/account/auth/login 200 [7.52, 127.0.0.1:60598][0m
INFO 2025-08-01 10:47:28,812 autoreload 9360 5196 C:\Users\user\Documents\Project\stanum_web\stanum_web\settings.py changed, reloading.
INFO 2025-08-01 10:47:31,409 autoreload 6508 8100 Watching for file changes with StatReloader
INFO 2025-08-01 10:54:14,164 runserver 6508 10976 [mHTTP GET /api/v1/challenge/balance 200 [4.60, 127.0.0.1:60731][0m
INFO 2025-08-01 10:54:14,231 runserver 6508 10976 [mHTTP GET /api/v1/challenge/ 200 [4.64, 127.0.0.1:60733][0m
INFO 2025-08-01 10:54:15,435 runserver 6508 10976 [mHTTP GET /api/v1/trading/accounts 200 [5.86, 127.0.0.1:60732][0m
INFO 2025-08-01 10:54:16,368 runserver 6508 10976 [mHTTP GET /api/v1/challenge/balance 200 [2.18, 127.0.0.1:60731][0m
INFO 2025-08-01 10:54:16,369 runserver 6508 10976 [mHTTP GET /api/v1/challenge/ 200 [2.13, 127.0.0.1:60733][0m
INFO 2025-08-01 10:54:19,421 runserver 6508 10976 [mHTTP GET /api/v1/trading/accounts 200 [3.98, 127.0.0.1:60732][0m
INFO 2025-08-01 10:55:42,573 runserver 6508 10976 [mHTTP GET /api/v1/trading/accounts 200 [6.51, 127.0.0.1:60774][0m
INFO 2025-08-01 10:55:45,752 runserver 6508 10976 [mHTTP GET /api/v1/trading/accounts 200 [3.18, 127.0.0.1:60774][0m
INFO 2025-08-01 10:57:37,421 runserver 6508 10976 [mHTTP GET /api/v1/challenge/ 200 [6.27, 127.0.0.1:60784][0m
INFO 2025-08-01 10:57:39,425 runserver 6508 10976 [mHTTP GET /api/v1/challenge/ 200 [2.00, 127.0.0.1:60784][0m
INFO 2025-08-01 10:59:34,012 runserver 6508 10976 [mHTTP GET /api/v1/challenge/ 200 [3.11, 127.0.0.1:60809][0m
INFO 2025-08-01 10:59:36,056 runserver 6508 10976 [mHTTP GET /api/v1/challenge/ 200 [2.04, 127.0.0.1:60809][0m
INFO 2025-08-01 10:59:48,890 runserver 6508 10976 [mHTTP GET /api/v1/challenge/ 200 [2.01, 127.0.0.1:60811][0m
INFO 2025-08-01 10:59:49,355 runserver 6508 10976 [mHTTP GET /api/v1/trading/accounts 200 [2.48, 127.0.0.1:60809][0m
INFO 2025-08-01 10:59:50,651 runserver 6508 10976 [mHTTP GET /api/v1/challenge/ 200 [1.75, 127.0.0.1:60811][0m
INFO 2025-08-01 10:59:51,533 runserver 6508 10976 [mHTTP GET /api/v1/trading/accounts 200 [2.17, 127.0.0.1:60809][0m
INFO 2025-08-01 11:05:14,392 runserver 6508 10976 [mHTTP GET /api/v1/challenge/balance 200 [6.91, 127.0.0.1:60859][0m
INFO 2025-08-01 11:05:14,398 runserver 6508 10976 [mHTTP GET /api/v1/challenge/ 200 [6.91, 127.0.0.1:60860][0m
INFO 2025-08-01 11:26:19,522 runserver 6508 10976 [mHTTP GET /api/v1/challenge/balance 200 [2.62, 127.0.0.1:61047][0m
INFO 2025-08-01 11:26:19,526 runserver 6508 10976 [mHTTP GET /api/v1/challenge/ 200 [2.60, 127.0.0.1:61049][0m
WARNING 2025-08-01 11:26:19,528 log 6508 4004 Unauthorized: /api/v1/trading/accounts
WARNING 2025-08-01 11:26:19,531 runserver 6508 10976 [31;1mHTTP GET /api/v1/trading/accounts 401 [2.62, 127.0.0.1:61048][0m
WARNING 2025-08-01 11:26:19,618 log 6508 4004 Not Found: /api/v1/auth/token/refresh
WARNING 2025-08-01 11:26:19,619 runserver 6508 10976 [33mHTTP POST /api/v1/auth/token/refresh 404 [0.02, 127.0.0.1:61053][0m
INFO 2025-08-01 11:26:21,888 runserver 6508 10976 [mHTTP GET /api/v1/challenge/balance 200 [2.36, 127.0.0.1:61047][0m
WARNING 2025-08-01 11:26:21,894 log 6508 4004 Unauthorized: /api/v1/trading/accounts
INFO 2025-08-01 11:26:21,898 runserver 6508 10976 [mHTTP GET /api/v1/challenge/ 200 [2.36, 127.0.0.1:61049][0m
WARNING 2025-08-01 11:26:21,903 runserver 6508 10976 [31;1mHTTP GET /api/v1/trading/accounts 401 [2.37, 127.0.0.1:61048][0m
INFO 2025-08-01 11:26:34,562 runserver 6508 10976 [mHTTP POST /api/v1/account/auth/login 200 [6.19, 127.0.0.1:61049][0m
INFO 2025-08-01 11:26:49,326 runserver 6508 10976 [mHTTP GET /api/v1/challenge/balance 200 [4.51, 127.0.0.1:61049][0m
INFO 2025-08-01 11:26:49,330 runserver 6508 10976 [mHTTP GET /api/v1/challenge/ 200 [4.50, 127.0.0.1:61047][0m
INFO 2025-08-01 11:26:49,619 runserver 6508 10976 [mHTTP GET /api/v1/trading/accounts 200 [4.80, 127.0.0.1:61048][0m
INFO 2025-08-01 11:26:50,898 runserver 6508 10976 [mHTTP GET /api/v1/challenge/balance 200 [1.57, 127.0.0.1:61049][0m
INFO 2025-08-01 11:26:51,313 runserver 6508 10976 [mHTTP GET /api/v1/challenge/ 200 [1.98, 127.0.0.1:61053][0m
INFO 2025-08-01 11:26:52,032 runserver 6508 10976 [mHTTP GET /api/v1/trading/accounts 200 [2.41, 127.0.0.1:61048][0m
INFO 2025-08-01 11:28:26,521 runserver 6508 10976 [mHTTP GET /api/v1/challenge/balance 200 [3.37, 127.0.0.1:61107][0m
INFO 2025-08-01 11:28:26,524 runserver 6508 10976 [mHTTP GET /api/v1/challenge/ 200 [3.35, 127.0.0.1:61109][0m
INFO 2025-08-01 11:28:26,824 runserver 6508 10976 [mHTTP GET /api/v1/trading/accounts 200 [3.66, 127.0.0.1:61108][0m
INFO 2025-08-01 11:28:28,624 runserver 6508 10976 [mHTTP GET /api/v1/challenge/balance 200 [2.08, 127.0.0.1:61107][0m
INFO 2025-08-01 11:28:29,871 runserver 6508 10976 [mHTTP GET /api/v1/trading/accounts 200 [3.04, 127.0.0.1:61108][0m
INFO 2025-08-01 11:28:30,182 runserver 6508 10976 [mHTTP GET /api/v1/challenge/ 200 [3.65, 127.0.0.1:61109][0m
INFO 2025-08-01 11:42:51,663 runserver 6508 10976 [mHTTP POST /api/v1/account/auth/login 200 [6.75, 127.0.0.1:61318][0m
INFO 2025-08-01 11:47:19,336 runserver 6508 10976 [mHTTP GET /api/v1/challenge/ 200 [3.05, 127.0.0.1:61361][0m
INFO 2025-08-01 11:47:19,342 runserver 6508 10976 [mHTTP GET /api/v1/challenge/balance 200 [3.06, 127.0.0.1:61360][0m
INFO 2025-08-01 11:47:21,795 runserver 6508 10976 [mHTTP GET /api/v1/challenge/ 200 [2.45, 127.0.0.1:61361][0m
INFO 2025-08-01 11:47:22,400 runserver 6508 10976 [mHTTP GET /api/v1/challenge/balance 200 [3.05, 127.0.0.1:61360][0m
INFO 2025-08-01 11:48:47,911 runserver 6508 10976 [mHTTP GET /api/v1/challenge/balance 200 [3.69, 127.0.0.1:61378][0m
INFO 2025-08-01 11:48:48,003 runserver 6508 10976 [mHTTP GET /api/v1/challenge/ 200 [3.76, 127.0.0.1:61379][0m
INFO 2025-08-01 11:53:18,669 runserver 6508 10976 [mHTTP GET /api/v1/challenge/balance 200 [3.57, 127.0.0.1:61410][0m
INFO 2025-08-01 11:53:18,673 runserver 6508 10976 [mHTTP GET /api/v1/challenge/ 200 [3.57, 127.0.0.1:61411][0m
INFO 2025-08-01 11:53:20,166 runserver 6508 10976 [mHTTP GET /api/v1/challenge/ 200 [1.48, 127.0.0.1:61411][0m
INFO 2025-08-01 11:53:20,763 runserver 6508 10976 [mHTTP GET /api/v1/challenge/balance 200 [2.09, 127.0.0.1:61410][0m
INFO 2025-08-01 12:06:35,738 runserver 6508 10976 [mHTTP GET /admin/challenge/propfirmchallenge/10/change/ 200 [4.76, 127.0.0.1:61560][0m
INFO 2025-08-01 12:06:35,920 runserver 6508 10976 [mHTTP GET /static/admin/js/jquery.init.js 200 [0.14, 127.0.0.1:61561][0m
INFO 2025-08-01 12:06:35,930 runserver 6508 10976 [mHTTP GET /static/admin/js/core.js 200 [0.15, 127.0.0.1:61562][0m
INFO 2025-08-01 12:06:35,961 runserver 6508 10976 [mHTTP GET /static/admin/js/admin/RelatedObjectLookups.js 200 [0.04, 127.0.0.1:61561][0m
INFO 2025-08-01 12:06:35,976 runserver 6508 10976 [mHTTP GET /static/admin/js/actions.js 200 [0.04, 127.0.0.1:61562][0m
INFO 2025-08-01 12:06:35,994 runserver 6508 10976 [mHTTP GET /static/admin/js/urlify.js 200 [0.03, 127.0.0.1:61561][0m
INFO 2025-08-01 12:06:36,001 runserver 6508 10976 [mHTTP GET /static/admin/js/vendor/jquery/jquery.js 200 [0.23, 127.0.0.1:61560][0m
INFO 2025-08-01 12:06:36,014 runserver 6508 10976 [mHTTP GET /static/admin/js/prepopulate.js 200 [0.04, 127.0.0.1:61562][0m
INFO 2025-08-01 12:06:36,100 runserver 6508 10976 [mHTTP GET /static/admin/js/vendor/xregexp/xregexp.js 200 [0.10, 127.0.0.1:61561][0m
INFO 2025-08-01 12:06:38,601 runserver 6508 10976 [mHTTP GET /admin/jsi18n/ 200 [2.59, 127.0.0.1:61560][0m
WARNING 2025-08-01 12:06:38,776 log 6508 3476 Not Found: /favicon.ico
WARNING 2025-08-01 12:06:38,778 runserver 6508 10976 [33mHTTP GET /favicon.ico 404 [0.01, 127.0.0.1:61560][0m
INFO 2025-08-01 12:09:23,955 autoreload 6508 8100 C:\Users\user\Documents\Project\stanum_web\trading\admin.py changed, reloading.
INFO 2025-08-01 12:09:26,935 autoreload 9960 14464 Watching for file changes with StatReloader
INFO 2025-08-01 12:11:12,229 runserver 9960 10028 [mHTTP GET /admin/challenge/propfirmchallenge/10/change/ 200 [5.02, 127.0.0.1:61603][0m
INFO 2025-08-01 12:11:15,178 runserver 9960 10028 [mHTTP GET /admin/jsi18n/ 200 [2.89, 127.0.0.1:61603][0m
INFO 2025-08-01 12:11:26,726 runserver 9960 10028 [mHTTP GET /admin/trading/tradingaccount/ 200 [3.85, 127.0.0.1:61603][0m
INFO 2025-08-01 12:11:28,793 runserver 9960 10028 [mHTTP GET /admin/jsi18n/ 200 [1.99, 127.0.0.1:61603][0m
INFO 2025-08-01 12:11:29,060 runserver 9960 10028 [mHTTP GET /static/admin/img/tooltag-add.svg 200 [0.20, 127.0.0.1:61603][0m
INFO 2025-08-01 12:13:05,866 runserver 9960 10028 [mHTTP GET /admin/trading/tradingaccount/add/ 200 [8.65, 127.0.0.1:61615][0m
INFO 2025-08-01 12:13:05,940 runserver 9960 10028 [mHTTP GET /static/admin/img/icon-viewlink.svg 200 [0.03, 127.0.0.1:61617][0m
INFO 2025-08-01 12:13:06,004 runserver 9960 10028 [mHTTP GET /static/admin/js/admin/DateTimeShortcuts.js 200 [0.10, 127.0.0.1:61616][0m
INFO 2025-08-01 12:13:06,019 runserver 9960 10028 [mHTTP GET /static/admin/js/calendar.js 200 [0.11, 127.0.0.1:61615][0m
INFO 2025-08-01 12:13:08,531 runserver 9960 10028 [mHTTP GET /admin/jsi18n/ 200 [2.59, 127.0.0.1:61617][0m
INFO 2025-08-01 12:13:08,691 runserver 9960 10028 [mHTTP GET /static/admin/img/icon-clock.svg 200 [0.04, 127.0.0.1:61615][0m
INFO 2025-08-01 12:13:08,694 runserver 9960 10028 [mHTTP GET /static/admin/img/icon-calendar.svg 200 [0.04, 127.0.0.1:61617][0m
INFO 2025-08-01 12:14:44,218 runserver 9960 10028 [mHTTP POST /admin/trading/tradingaccount/add/ 200 [6.80, 127.0.0.1:61627][0m
INFO 2025-08-01 12:14:46,834 runserver 9960 10028 [mHTTP GET /admin/jsi18n/ 200 [2.59, 127.0.0.1:61627][0m
INFO 2025-08-01 16:50:11,670 runserver 9960 10028 [mHTTP OPTIONS /api/v1/trading/accounts 200 [0.01, 127.0.0.1:61812][0m
INFO 2025-08-01 16:50:11,670 runserver 9960 10028 [mHTTP OPTIONS /api/v1/trading/accounts 200 [0.01, 127.0.0.1:61813][0m
WARNING 2025-08-01 16:50:14,045 log 9960 13240 Unauthorized: /api/v1/trading/accounts
WARNING 2025-08-01 16:50:14,045 runserver 9960 10028 [31;1mHTTP GET /api/v1/trading/accounts 401 [2.38, 127.0.0.1:61813][0m
INFO 2025-08-01 16:50:14,050 runserver 9960 10028 [mHTTP OPTIONS /api/v1/auth/token/refresh 200 [0.00, 127.0.0.1:61813][0m
WARNING 2025-08-01 16:50:14,080 log 9960 13240 Not Found: /api/v1/auth/token/refresh
WARNING 2025-08-01 16:50:14,080 runserver 9960 10028 [33mHTTP POST /api/v1/auth/token/refresh 404 [0.02, 127.0.0.1:61813][0m
WARNING 2025-08-01 16:50:15,809 log 9960 7052 Unauthorized: /api/v1/trading/accounts
WARNING 2025-08-01 16:50:15,809 runserver 9960 10028 [31;1mHTTP GET /api/v1/trading/accounts 401 [1.76, 127.0.0.1:61812][0m
INFO 2025-08-01 16:50:33,420 runserver 9960 10028 [mHTTP OPTIONS /api/v1/account/auth/login 200 [0.01, 127.0.0.1:61812][0m
INFO 2025-08-01 16:50:38,140 runserver 9960 10028 [mHTTP POST /api/v1/account/auth/login 200 [4.72, 127.0.0.1:61812][0m
INFO 2025-08-01 17:27:51,180 runserver 9960 10028 [mHTTP GET /api/v1/challenge/balance 200 [2.15, 127.0.0.1:62090][0m
INFO 2025-08-01 17:27:51,183 runserver 9960 10028 [mHTTP GET /api/v1/challenge/ 200 [2.15, 127.0.0.1:62091][0m
INFO 2025-08-01 17:27:52,811 runserver 9960 10028 [mHTTP GET /api/v1/challenge/balance 200 [1.63, 127.0.0.1:62090][0m
INFO 2025-08-01 17:27:52,815 runserver 9960 10028 [mHTTP GET /api/v1/challenge/ 200 [1.63, 127.0.0.1:62091][0m
INFO 2025-08-01 17:38:34,291 autoreload 9960 14464 C:\Users\user\Documents\Project\stanum_web\challenge\views.py changed, reloading.
INFO 2025-08-01 17:38:37,903 autoreload 1184 16328 Watching for file changes with StatReloader
INFO 2025-08-01 17:39:04,170 autoreload 1184 16328 C:\Users\user\Documents\Project\stanum_web\challenge\urls.py changed, reloading.
INFO 2025-08-01 17:39:06,577 autoreload 20788 2172 Watching for file changes with StatReloader
INFO 2025-08-01 17:39:21,085 runserver 20788 17708 [mHTTP GET /swagger/ 200 [0.11, 127.0.0.1:62170][0m
INFO 2025-08-01 17:39:21,696 runserver 20788 17708 [mHTTP GET /swagger/?format=openapi 200 [0.05, 127.0.0.1:62170][0m
INFO 2025-08-01 17:39:33,031 runserver 20788 17708 [mHTTP GET /api/v1/challenge/6 200 [1.90, 127.0.0.1:62170][0m
WARNING 2025-08-01 17:40:02,732 log 20788 15892 Method Not Allowed: /api/v1/account/auth/password/forget
WARNING 2025-08-01 17:40:02,733 runserver 20788 17708 [31;1mHTTP GET /api/v1/account/auth/password/forget 405 [0.01, 127.0.0.1:62177][0m
INFO 2025-08-01 17:40:04,869 runserver 20788 17708 [mHTTP GET /api/v1/challenge/balance 200 [2.08, 127.0.0.1:62177][0m
INFO 2025-08-01 17:40:05,076 runserver 20788 17708 [mHTTP GET /api/v1/challenge/ 200 [2.26, 127.0.0.1:62178][0m
INFO 2025-08-01 17:40:06,070 runserver 20788 17708 [mHTTP GET /api/v1/challenge/balance 200 [1.20, 127.0.0.1:62177][0m
INFO 2025-08-01 17:40:06,305 runserver 20788 17708 [mHTTP GET /api/v1/challenge/ 200 [1.22, 127.0.0.1:62178][0m
WARNING 2025-08-01 17:40:12,526 log 20788 15892 Method Not Allowed: /api/v1/account/auth/password/forget
WARNING 2025-08-01 17:40:12,527 runserver 20788 17708 [31;1mHTTP GET /api/v1/account/auth/password/forget 405 [0.01, 127.0.0.1:62178][0m
WARNING 2025-08-01 17:40:12,538 log 20788 15892 Method Not Allowed: /api/v1/account/auth/password/forget
WARNING 2025-08-01 17:40:12,540 runserver 20788 17708 [31;1mHTTP GET /api/v1/account/auth/password/forget 405 [0.01, 127.0.0.1:62178][0m
INFO 2025-08-01 17:40:14,081 runserver 20788 17708 [mHTTP GET /api/v1/challenge/ 200 [1.46, 127.0.0.1:62177][0m
INFO 2025-08-01 17:40:14,585 runserver 20788 17708 [mHTTP GET /api/v1/challenge/balance 200 [2.01, 127.0.0.1:62178][0m
INFO 2025-08-01 17:40:15,617 runserver 20788 17708 [mHTTP GET /api/v1/challenge/ 200 [1.53, 127.0.0.1:62182][0m
INFO 2025-08-01 17:40:16,212 runserver 20788 17708 [mHTTP GET /api/v1/challenge/balance 200 [1.62, 127.0.0.1:62178][0m
WARNING 2025-08-01 17:40:19,769 log 20788 15892 Method Not Allowed: /api/v1/account/auth/password/forget
WARNING 2025-08-01 17:40:19,771 runserver 20788 17708 [31;1mHTTP GET /api/v1/account/auth/password/forget 405 [0.02, 127.0.0.1:62178][0m
WARNING 2025-08-01 17:40:19,792 log 20788 15892 Method Not Allowed: /api/v1/account/auth/password/forget
WARNING 2025-08-01 17:40:19,794 runserver 20788 17708 [31;1mHTTP GET /api/v1/account/auth/password/forget 405 [0.02, 127.0.0.1:62178][0m
INFO 2025-08-01 17:40:41,613 runserver 20788 17708 [mHTTP POST /api/v1/account/auth/login 200 [5.40, 127.0.0.1:62178][0m
WARNING 2025-08-01 17:41:19,093 log 20788 15892 Not Found: /api/v1/challenge/0
WARNING 2025-08-01 17:41:19,094 runserver 20788 17708 [33mHTTP GET /api/v1/challenge/0 404 [1.69, 127.0.0.1:62178][0m
INFO 2025-08-01 17:41:36,113 runserver 20788 17708 [mHTTP GET /api/v1/challenge/balance 200 [1.70, 127.0.0.1:62178][0m
INFO 2025-08-01 17:41:36,119 runserver 20788 17708 [mHTTP GET /api/v1/challenge/ 200 [1.70, 127.0.0.1:62224][0m
INFO 2025-08-01 17:41:37,746 runserver 20788 17708 [mHTTP GET /api/v1/challenge/balance 200 [1.62, 127.0.0.1:62178][0m
INFO 2025-08-01 17:41:37,746 runserver 20788 17708 [mHTTP GET /api/v1/challenge/ 200 [1.61, 127.0.0.1:62224][0m
WARNING 2025-08-01 17:41:44,903 log 20788 15892 Not Found: /api/v1/challenge/0
WARNING 2025-08-01 17:41:44,904 runserver 20788 17708 [33mHTTP GET /api/v1/challenge/0 404 [2.84, 127.0.0.1:62224][0m
WARNING 2025-08-01 17:41:46,638 log 20788 15892 Not Found: /api/v1/challenge/0
WARNING 2025-08-01 17:41:46,639 runserver 20788 17708 [33mHTTP GET /api/v1/challenge/0 404 [1.73, 127.0.0.1:62224][0m
WARNING 2025-08-01 17:42:18,548 log 20788 15892 Not Found: /api/v1/challenge/null
WARNING 2025-08-01 17:42:18,549 runserver 20788 17708 [33mHTTP GET /api/v1/challenge/null 404 [0.03, 127.0.0.1:62224][0m
WARNING 2025-08-01 17:42:18,578 log 20788 15892 Not Found: /api/v1/challenge/null
WARNING 2025-08-01 17:42:18,579 runserver 20788 17708 [33mHTTP GET /api/v1/challenge/null 404 [0.03, 127.0.0.1:62224][0m
INFO 2025-08-01 17:42:20,534 runserver 20788 17708 [mHTTP GET /api/v1/challenge/balance 200 [1.76, 127.0.0.1:62224][0m
INFO 2025-08-01 17:42:20,943 runserver 20788 17708 [mHTTP GET /api/v1/challenge/ 200 [2.15, 127.0.0.1:62178][0m
INFO 2025-08-01 17:42:22,592 runserver 20788 17708 [mHTTP GET /api/v1/challenge/ 200 [1.65, 127.0.0.1:62228][0m
INFO 2025-08-01 17:42:23,605 runserver 20788 17708 [mHTTP GET /api/v1/challenge/balance 200 [3.06, 127.0.0.1:62224][0m
WARNING 2025-08-01 17:43:32,516 log 20788 15892 Not Found: /api/v1/challenge/0
WARNING 2025-08-01 17:43:32,516 runserver 20788 17708 [33mHTTP GET /api/v1/challenge/0 404 [3.90, 127.0.0.1:62310][0m
WARNING 2025-08-01 17:43:33,957 log 20788 15892 Not Found: /api/v1/challenge/0
WARNING 2025-08-01 17:43:33,959 runserver 20788 17708 [33mHTTP GET /api/v1/challenge/0 404 [1.43, 127.0.0.1:62310][0m
INFO 2025-08-01 17:43:35,598 runserver 20788 17708 [mHTTP GET /api/v1/challenge/balance 200 [1.49, 127.0.0.1:62310][0m
INFO 2025-08-01 17:43:35,602 runserver 20788 17708 [mHTTP GET /api/v1/challenge/ 200 [1.46, 127.0.0.1:62322][0m
INFO 2025-08-01 17:43:37,240 runserver 20788 17708 [mHTTP GET /api/v1/challenge/balance 200 [1.63, 127.0.0.1:62310][0m
INFO 2025-08-01 17:43:37,248 runserver 20788 17708 [mHTTP GET /api/v1/challenge/ 200 [1.64, 127.0.0.1:62322][0m
INFO 2025-08-01 17:44:20,654 runserver 20788 17708 [mHTTP GET /api/v1/challenge/balance 200 [1.35, 127.0.0.1:62322][0m
INFO 2025-08-01 17:44:20,656 runserver 20788 17708 [mHTTP GET /api/v1/challenge/ 200 [1.35, 127.0.0.1:62310][0m
INFO 2025-08-01 17:44:22,192 runserver 20788 17708 [mHTTP GET /api/v1/challenge/balance 200 [1.53, 127.0.0.1:62322][0m
INFO 2025-08-01 17:44:22,216 runserver 20788 17708 [mHTTP GET /api/v1/challenge/ 200 [1.55, 127.0.0.1:62324][0m
INFO 2025-08-01 17:44:27,514 runserver 20788 17708 [mHTTP GET /api/v1/challenge/6 200 [1.66, 127.0.0.1:62324][0m
INFO 2025-08-01 17:44:29,157 runserver 20788 17708 [mHTTP GET /api/v1/challenge/6 200 [1.64, 127.0.0.1:62324][0m
INFO 2025-08-01 17:44:40,103 runserver 20788 17708 [mHTTP GET /api/v1/challenge/6 200 [1.65, 127.0.0.1:62324][0m
INFO 2025-08-01 17:44:40,515 runserver 20788 17708 [mHTTP GET /api/v1/trading/accounts 200 [2.05, 127.0.0.1:62322][0m
INFO 2025-08-01 17:44:45,335 runserver 20788 17708 [mHTTP GET /api/v1/challenge/6 200 [5.23, 127.0.0.1:62324][0m
INFO 2025-08-01 17:44:45,627 runserver 20788 17708 [mHTTP GET /api/v1/trading/accounts 200 [5.11, 127.0.0.1:62322][0m
INFO 2025-08-01 17:46:34,430 runserver 20788 17708 [mHTTP GET /api/v1/challenge/6 200 [2.69, 127.0.0.1:62449][0m
INFO 2025-08-01 17:53:20,300 runserver 20788 17708 [mHTTP GET /api/v1/challenge/6 200 [3.26, 127.0.0.1:62669][0m
INFO 2025-08-01 17:53:20,572 runserver 20788 17708 [mHTTP GET /api/v1/trading/accounts 200 [3.52, 127.0.0.1:62670][0m
INFO 2025-08-01 17:53:21,828 runserver 20788 17708 [mHTTP GET /api/v1/challenge/6 200 [1.52, 127.0.0.1:62669][0m
INFO 2025-08-01 17:53:22,641 runserver 20788 17708 [mHTTP GET /api/v1/trading/accounts 200 [2.05, 127.0.0.1:62670][0m
INFO 2025-08-01 17:54:21,124 runserver 20788 17708 [mHTTP GET /api/v1/challenge/6 200 [2.63, 127.0.0.1:62670][0m
INFO 2025-08-01 17:54:21,525 runserver 20788 17708 [mHTTP GET /api/v1/trading/accounts 200 [3.02, 127.0.0.1:62669][0m
INFO 2025-08-01 17:54:22,659 runserver 20788 17708 [mHTTP GET /api/v1/challenge/6 200 [1.53, 127.0.0.1:62670][0m
INFO 2025-08-01 17:54:23,370 runserver 20788 17708 [mHTTP GET /api/v1/trading/accounts 200 [1.83, 127.0.0.1:62669][0m
INFO 2025-08-01 17:58:09,372 runserver 20788 17708 [mHTTP GET /api/v1/challenge/ 200 [5.30, 127.0.0.1:62722][0m
INFO 2025-08-01 17:58:09,375 runserver 20788 17708 [mHTTP GET /api/v1/challenge/balance 200 [5.35, 127.0.0.1:62715][0m
INFO 2025-08-01 17:58:11,220 runserver 20788 17708 [mHTTP GET /api/v1/challenge/balance 200 [1.84, 127.0.0.1:62722][0m
INFO 2025-08-01 17:58:11,226 runserver 20788 17708 [mHTTP GET /api/v1/challenge/ 200 [1.84, 127.0.0.1:62715][0m
INFO 2025-08-01 17:58:23,910 runserver 20788 17708 [mHTTP GET /api/v1/challenge/3 200 [1.73, 127.0.0.1:62715][0m
INFO 2025-08-01 17:58:25,739 runserver 20788 17708 [mHTTP GET /api/v1/challenge/3 200 [1.82, 127.0.0.1:62715][0m
