INFO 2025-07-27 06:11:58,407 autoreload 6468 6680 Watching for file changes with StatReloader
INFO 2025-07-27 06:13:36,475 runserver 6468 7868 [32mHTTP GET /swagger 301 [0.21, 127.0.0.1:53005][0m
INFO 2025-07-27 06:13:36,518 runserver 6468 7868 [mHTTP GET /swagger/ 200 [0.04, 127.0.0.1:53005][0m
INFO 2025-07-27 06:13:36,691 runserver 6468 7868 [mHTTP GET /static/drf-yasg/style.css 200 [0.15, 127.0.0.1:53005][0m
INFO 2025-07-27 06:13:36,698 runserver 6468 7868 [mHTTP GET /static/drf-yasg/swagger-ui-dist/swagger-ui.css 200 [0.15, 127.0.0.1:53006][0m
INFO 2025-07-27 06:13:36,734 runserver 6468 7868 [mHTTP GET /static/drf-yasg/swagger-ui-dist/swagger-ui-bundle.js 200 [0.18, 127.0.0.1:53008][0m
INFO 2025-07-27 06:13:36,747 runserver 6468 7868 [mHTTP GET /static/drf-yasg/insQ.min.js 200 [0.05, 127.0.0.1:53006][0m
INFO 2025-07-27 06:13:36,792 runserver 6468 7868 [mHTTP GET /static/drf-yasg/swagger-ui-init.js 200 [0.04, 127.0.0.1:53006][0m
INFO 2025-07-27 06:13:36,838 runserver 6468 7868 [mHTTP GET /static/drf-yasg/immutable.min.js 200 [0.10, 127.0.0.1:53008][0m
INFO 2025-07-27 06:13:36,877 runserver 6468 7868 [mHTTP GET /static/drf-yasg/swagger-ui-dist/swagger-ui-standalone-preset.js 200 [0.18, 127.0.0.1:53005][0m
INFO 2025-07-27 06:13:36,993 runserver 6468 7868 [mHTTP GET /swagger/?format=openapi 200 [0.02, 127.0.0.1:53005][0m
INFO 2025-07-27 06:13:37,008 runserver 6468 7868 [mHTTP GET /static/drf-yasg/swagger-ui-dist/favicon-32x32.png 200 [0.00, 127.0.0.1:53005][0m
INFO 2025-07-27 06:14:55,599 runserver 6468 7868 [32mHTTP GET /admin 301 [0.03, 127.0.0.1:53027][0m
INFO 2025-07-27 06:14:55,648 runserver 6468 7868 [32mHTTP GET /admin/ 302 [0.03, 127.0.0.1:53027][0m
INFO 2025-07-27 06:14:56,088 runserver 6468 7868 [mHTTP GET /admin/login/?next=/admin/ 200 [0.43, 127.0.0.1:53027][0m
INFO 2025-07-27 06:14:56,235 runserver 6468 7868 [mHTTP GET /static/admin/css/base.css 200 [0.03, 127.0.0.1:53027][0m
INFO 2025-07-27 06:14:56,252 runserver 6468 7868 [mHTTP GET /static/admin/css/nav_sidebar.css 200 [0.03, 127.0.0.1:53029][0m
INFO 2025-07-27 06:14:56,257 runserver 6468 7868 [mHTTP GET /static/admin/css/dark_mode.css 200 [0.04, 127.0.0.1:53028][0m
INFO 2025-07-27 06:14:56,282 runserver 6468 7868 [mHTTP GET /static/admin/css/login.css 200 [0.04, 127.0.0.1:53027][0m
INFO 2025-07-27 06:14:56,379 runserver 6468 7868 [mHTTP GET /static/admin/css/responsive.css 200 [0.12, 127.0.0.1:53029][0m
INFO 2025-07-27 06:14:56,381 runserver 6468 7868 [mHTTP GET /static/admin/js/theme.js 200 [0.11, 127.0.0.1:53028][0m
INFO 2025-07-27 06:14:56,415 runserver 6468 7868 [mHTTP GET /static/admin/js/nav_sidebar.js 200 [0.13, 127.0.0.1:53027][0m
WARNING 2025-07-27 06:14:56,468 log 6468 9080 Not Found: /favicon.ico
WARNING 2025-07-27 06:14:56,470 runserver 6468 7868 [33mHTTP GET /favicon.ico 404 [0.03, 127.0.0.1:53027][0m
INFO 2025-07-27 06:15:14,424 runserver 6468 7868 [32mHTTP POST /admin/login/?next=/admin/ 302 [4.67, 127.0.0.1:53027][0m
INFO 2025-07-27 06:15:16,680 runserver 6468 7868 [mHTTP GET /admin/ 200 [2.24, 127.0.0.1:53027][0m
INFO 2025-07-27 06:15:16,803 runserver 6468 7868 [mHTTP GET /static/admin/css/dashboard.css 200 [0.06, 127.0.0.1:53027][0m
INFO 2025-07-27 06:15:16,810 runserver 6468 7868 [mHTTP GET /static/admin/img/icon-addlink.svg 200 [0.06, 127.0.0.1:53028][0m
INFO 2025-07-27 06:15:16,811 runserver 6468 7868 [mHTTP GET /static/admin/img/icon-changelink.svg 200 [0.06, 127.0.0.1:53029][0m
INFO 2025-07-27 06:15:50,960 autoreload 6468 6680 C:\Users\user\Documents\Project\stanum_web\account\admin.py changed, reloading.
INFO 2025-07-27 06:15:53,533 autoreload 7496 15220 Watching for file changes with StatReloader
INFO 2025-07-27 06:16:06,284 runserver 7496 676 [mHTTP GET /admin/ 200 [2.21, 127.0.0.1:53055][0m
INFO 2025-07-27 06:16:58,728 runserver 7496 676 [mHTTP POST /api/v1/account/auth/signup 201 [12.86, 127.0.0.1:53055][0m
INFO 2025-07-27 06:17:29,554 autoreload 7496 15220 C:\Users\user\Documents\Project\stanum_web\stanum_web\settings.py changed, reloading.
INFO 2025-07-27 06:17:31,708 autoreload 2388 2348 Watching for file changes with StatReloader
INFO 2025-07-27 06:18:09,230 runserver 2388 16324 [mHTTP POST /api/v1/account/auth/signup 201 [5.62, 127.0.0.1:53081][0m
INFO 2025-07-27 06:18:37,649 autoreload 2388 2348 C:\Users\user\Documents\Project\stanum_web\account\models.py changed, reloading.
INFO 2025-07-27 06:18:40,425 autoreload 9936 9124 Watching for file changes with StatReloader
INFO 2025-07-27 06:19:01,143 autoreload 9936 9124 C:\Users\user\Documents\Project\stanum_web\utils\otp.py changed, reloading.
INFO 2025-07-27 06:19:04,195 autoreload 14520 5308 Watching for file changes with StatReloader
INFO 2025-07-27 06:19:50,507 runserver 14520 15260 [mHTTP POST /api/v1/account/auth/signup 201 [6.07, 127.0.0.1:53117][0m
INFO 2025-07-27 06:20:24,189 runserver 14520 15260 [mHTTP GET /api/v1/account/auth/verify/2/960064 200 [6.47, 127.0.0.1:53117][0m
INFO 2025-07-27 06:21:02,179 runserver 14520 15260 [mHTTP POST /api/v1/account/auth/password/forget 200 [2.90, 127.0.0.1:53117][0m
INFO 2025-07-27 06:21:49,590 runserver 14520 15260 [mHTTP GET /api/v1/account/auth/password/reset/validate-otp/2/803066 200 [8.82, 127.0.0.1:53117][0m
ERROR 2025-07-27 06:22:18,355 log 14520 4148 Internal Server Error: /api/v1/account/auth/password/reset/2/ctl5od-f9432bfb0a3af91bbf46322c75f58590
Traceback (most recent call last):
  File "C:\Users\user\Documents\venv\Lib\site-packages\django\db\backends\base\base.py", line 289, in ensure_connection
    self.connect()
  File "C:\Users\user\Documents\venv\Lib\site-packages\django\utils\asyncio.py", line 26, in inner
    return func(*args, **kwargs)
           ^^^^^^^^^^^^^^^^^^^^^
  File "C:\Users\user\Documents\venv\Lib\site-packages\django\db\backends\base\base.py", line 270, in connect
    self.connection = self.get_new_connection(conn_params)
                      ^^^^^^^^^^^^^^^^^^^^^^^^^^^^^^^^^^^^
  File "C:\Users\user\Documents\venv\Lib\site-packages\django\utils\asyncio.py", line 26, in inner
    return func(*args, **kwargs)
           ^^^^^^^^^^^^^^^^^^^^^
  File "C:\Users\user\Documents\venv\Lib\site-packages\django\db\backends\postgresql\base.py", line 275, in get_new_connection
    connection = self.Database.connect(**conn_params)
                 ^^^^^^^^^^^^^^^^^^^^^^^^^^^^^^^^^^^^
  File "C:\Users\user\Documents\venv\Lib\site-packages\psycopg2\__init__.py", line 122, in connect
    conn = _connect(dsn, connection_factory=connection_factory, **kwasync)
           ^^^^^^^^^^^^^^^^^^^^^^^^^^^^^^^^^^^^^^^^^^^^^^^^^^^^^^^^^^^^^^^
psycopg2.OperationalError: could not translate host name "victor-ao-ayomideolusola5002-b13e.h.aivencloud.com" to address: No such host is known. 


The above exception was the direct cause of the following exception:

Traceback (most recent call last):
  File "C:\Users\user\Documents\venv\Lib\site-packages\asgiref\sync.py", line 518, in thread_handler
    raise exc_info[1]
  File "C:\Users\user\Documents\venv\Lib\site-packages\django\core\handlers\exception.py", line 42, in inner
    response = await get_response(request)
               ^^^^^^^^^^^^^^^^^^^^^^^^^^^
  File "C:\Users\user\Documents\venv\Lib\site-packages\asgiref\sync.py", line 518, in thread_handler
    raise exc_info[1]
  File "C:\Users\user\Documents\venv\Lib\site-packages\django\core\handlers\base.py", line 253, in _get_response_async
    response = await wrapped_callback(
               ^^^^^^^^^^^^^^^^^^^^^^^
  File "C:\Users\user\Documents\venv\Lib\site-packages\asgiref\sync.py", line 468, in __call__
    ret = await asyncio.shield(exec_coro)
          ^^^^^^^^^^^^^^^^^^^^^^^^^^^^^^^
  File "C:\Users\user\Documents\venv\Lib\site-packages\asgiref\current_thread_executor.py", line 40, in run
    result = self.fn(*self.args, **self.kwargs)
             ^^^^^^^^^^^^^^^^^^^^^^^^^^^^^^^^^^
  File "C:\Users\user\Documents\venv\Lib\site-packages\asgiref\sync.py", line 522, in thread_handler
    return func(*args, **kwargs)
           ^^^^^^^^^^^^^^^^^^^^^
  File "C:\Users\user\Documents\venv\Lib\site-packages\django\views\decorators\csrf.py", line 56, in wrapper_view
    return view_func(*args, **kwargs)
           ^^^^^^^^^^^^^^^^^^^^^^^^^^
  File "C:\Users\user\Documents\venv\Lib\site-packages\django\views\generic\base.py", line 104, in view
    return self.dispatch(request, *args, **kwargs)
           ^^^^^^^^^^^^^^^^^^^^^^^^^^^^^^^^^^^^^^^
  File "C:\Users\user\Documents\venv\Lib\site-packages\rest_framework\views.py", line 509, in dispatch
    response = self.handle_exception(exc)
               ^^^^^^^^^^^^^^^^^^^^^^^^^^
  File "C:\Users\user\Documents\venv\Lib\site-packages\rest_framework\views.py", line 469, in handle_exception
    self.raise_uncaught_exception(exc)
  File "C:\Users\user\Documents\venv\Lib\site-packages\rest_framework\views.py", line 480, in raise_uncaught_exception
    raise exc
  File "C:\Users\user\Documents\venv\Lib\site-packages\rest_framework\views.py", line 506, in dispatch
    response = handler(request, *args, **kwargs)
               ^^^^^^^^^^^^^^^^^^^^^^^^^^^^^^^^^
  File "C:\Users\user\Documents\Project\stanum_web\account\views.py", line 444, in post
    user = get_object_or_404(User, id=id, email_verified=True)
           ^^^^^^^^^^^^^^^^^^^^^^^^^^^^^^^^^^^^^^^^^^^^^^^^^^^
  File "C:\Users\user\Documents\venv\Lib\site-packages\django\shortcuts.py", line 85, in get_object_or_404
    return queryset.get(*args, **kwargs)
           ^^^^^^^^^^^^^^^^^^^^^^^^^^^^^
  File "C:\Users\user\Documents\venv\Lib\site-packages\django\db\models\query.py", line 633, in get
    num = len(clone)
          ^^^^^^^^^^
  File "C:\Users\user\Documents\venv\Lib\site-packages\django\db\models\query.py", line 380, in __len__
    self._fetch_all()
  File "C:\Users\user\Documents\venv\Lib\site-packages\django\db\models\query.py", line 1881, in _fetch_all
    self._result_cache = list(self._iterable_class(self))
                         ^^^^^^^^^^^^^^^^^^^^^^^^^^^^^^^^
  File "C:\Users\user\Documents\venv\Lib\site-packages\django\db\models\query.py", line 91, in __iter__
    results = compiler.execute_sql(
              ^^^^^^^^^^^^^^^^^^^^^
  File "C:\Users\user\Documents\venv\Lib\site-packages\django\db\models\sql\compiler.py", line 1560, in execute_sql
    cursor = self.connection.cursor()
             ^^^^^^^^^^^^^^^^^^^^^^^^
  File "C:\Users\user\Documents\venv\Lib\site-packages\django\utils\asyncio.py", line 26, in inner
    return func(*args, **kwargs)
           ^^^^^^^^^^^^^^^^^^^^^
  File "C:\Users\user\Documents\venv\Lib\site-packages\django\db\backends\base\base.py", line 330, in cursor
    return self._cursor()
           ^^^^^^^^^^^^^^
  File "C:\Users\user\Documents\venv\Lib\site-packages\django\db\backends\base\base.py", line 306, in _cursor
    self.ensure_connection()
  File "C:\Users\user\Documents\venv\Lib\site-packages\django\utils\asyncio.py", line 26, in inner
    return func(*args, **kwargs)
           ^^^^^^^^^^^^^^^^^^^^^
  File "C:\Users\user\Documents\venv\Lib\site-packages\django\db\backends\base\base.py", line 288, in ensure_connection
    with self.wrap_database_errors:
  File "C:\Users\user\Documents\venv\Lib\site-packages\django\db\utils.py", line 91, in __exit__
    raise dj_exc_value.with_traceback(traceback) from exc_value
  File "C:\Users\user\Documents\venv\Lib\site-packages\django\db\backends\base\base.py", line 289, in ensure_connection
    self.connect()
  File "C:\Users\user\Documents\venv\Lib\site-packages\django\utils\asyncio.py", line 26, in inner
    return func(*args, **kwargs)
           ^^^^^^^^^^^^^^^^^^^^^
  File "C:\Users\user\Documents\venv\Lib\site-packages\django\db\backends\base\base.py", line 270, in connect
    self.connection = self.get_new_connection(conn_params)
                      ^^^^^^^^^^^^^^^^^^^^^^^^^^^^^^^^^^^^
  File "C:\Users\user\Documents\venv\Lib\site-packages\django\utils\asyncio.py", line 26, in inner
    return func(*args, **kwargs)
           ^^^^^^^^^^^^^^^^^^^^^
  File "C:\Users\user\Documents\venv\Lib\site-packages\django\db\backends\postgresql\base.py", line 275, in get_new_connection
    connection = self.Database.connect(**conn_params)
                 ^^^^^^^^^^^^^^^^^^^^^^^^^^^^^^^^^^^^
  File "C:\Users\user\Documents\venv\Lib\site-packages\psycopg2\__init__.py", line 122, in connect
    conn = _connect(dsn, connection_factory=connection_factory, **kwasync)
           ^^^^^^^^^^^^^^^^^^^^^^^^^^^^^^^^^^^^^^^^^^^^^^^^^^^^^^^^^^^^^^^
django.db.utils.OperationalError: could not translate host name "victor-ao-ayomideolusola5002-b13e.h.aivencloud.com" to address: No such host is known. 

ERROR 2025-07-27 06:22:18,463 runserver 14520 15260 [35;1mHTTP POST /api/v1/account/auth/password/reset/2/ctl5od-f9432bfb0a3af91bbf46322c75f58590 500 [0.75, 127.0.0.1:53128][0m
ERROR 2025-07-27 06:22:27,490 log 14520 4148 Internal Server Error: /api/v1/account/auth/password/reset/2/ctl5od-f9432bfb0a3af91bbf46322c75f58590
Traceback (most recent call last):
  File "C:\Users\user\Documents\venv\Lib\site-packages\django\db\backends\base\base.py", line 289, in ensure_connection
    self.connect()
  File "C:\Users\user\Documents\venv\Lib\site-packages\django\utils\asyncio.py", line 26, in inner
    return func(*args, **kwargs)
           ^^^^^^^^^^^^^^^^^^^^^
  File "C:\Users\user\Documents\venv\Lib\site-packages\django\db\backends\base\base.py", line 270, in connect
    self.connection = self.get_new_connection(conn_params)
                      ^^^^^^^^^^^^^^^^^^^^^^^^^^^^^^^^^^^^
  File "C:\Users\user\Documents\venv\Lib\site-packages\django\utils\asyncio.py", line 26, in inner
    return func(*args, **kwargs)
           ^^^^^^^^^^^^^^^^^^^^^
  File "C:\Users\user\Documents\venv\Lib\site-packages\django\db\backends\postgresql\base.py", line 275, in get_new_connection
    connection = self.Database.connect(**conn_params)
                 ^^^^^^^^^^^^^^^^^^^^^^^^^^^^^^^^^^^^
  File "C:\Users\user\Documents\venv\Lib\site-packages\psycopg2\__init__.py", line 122, in connect
    conn = _connect(dsn, connection_factory=connection_factory, **kwasync)
           ^^^^^^^^^^^^^^^^^^^^^^^^^^^^^^^^^^^^^^^^^^^^^^^^^^^^^^^^^^^^^^^
psycopg2.OperationalError: could not translate host name "victor-ao-ayomideolusola5002-b13e.h.aivencloud.com" to address: No such host is known. 


The above exception was the direct cause of the following exception:

Traceback (most recent call last):
  File "C:\Users\user\Documents\venv\Lib\site-packages\asgiref\sync.py", line 518, in thread_handler
    raise exc_info[1]
  File "C:\Users\user\Documents\venv\Lib\site-packages\django\core\handlers\exception.py", line 42, in inner
    response = await get_response(request)
               ^^^^^^^^^^^^^^^^^^^^^^^^^^^
  File "C:\Users\user\Documents\venv\Lib\site-packages\asgiref\sync.py", line 518, in thread_handler
    raise exc_info[1]
  File "C:\Users\user\Documents\venv\Lib\site-packages\django\core\handlers\base.py", line 253, in _get_response_async
    response = await wrapped_callback(
               ^^^^^^^^^^^^^^^^^^^^^^^
  File "C:\Users\user\Documents\venv\Lib\site-packages\asgiref\sync.py", line 468, in __call__
    ret = await asyncio.shield(exec_coro)
          ^^^^^^^^^^^^^^^^^^^^^^^^^^^^^^^
  File "C:\Users\user\Documents\venv\Lib\site-packages\asgiref\current_thread_executor.py", line 40, in run
    result = self.fn(*self.args, **self.kwargs)
             ^^^^^^^^^^^^^^^^^^^^^^^^^^^^^^^^^^
  File "C:\Users\user\Documents\venv\Lib\site-packages\asgiref\sync.py", line 522, in thread_handler
    return func(*args, **kwargs)
           ^^^^^^^^^^^^^^^^^^^^^
  File "C:\Users\user\Documents\venv\Lib\site-packages\django\views\decorators\csrf.py", line 56, in wrapper_view
    return view_func(*args, **kwargs)
           ^^^^^^^^^^^^^^^^^^^^^^^^^^
  File "C:\Users\user\Documents\venv\Lib\site-packages\django\views\generic\base.py", line 104, in view
    return self.dispatch(request, *args, **kwargs)
           ^^^^^^^^^^^^^^^^^^^^^^^^^^^^^^^^^^^^^^^
  File "C:\Users\user\Documents\venv\Lib\site-packages\rest_framework\views.py", line 509, in dispatch
    response = self.handle_exception(exc)
               ^^^^^^^^^^^^^^^^^^^^^^^^^^
  File "C:\Users\user\Documents\venv\Lib\site-packages\rest_framework\views.py", line 469, in handle_exception
    self.raise_uncaught_exception(exc)
  File "C:\Users\user\Documents\venv\Lib\site-packages\rest_framework\views.py", line 480, in raise_uncaught_exception
    raise exc
  File "C:\Users\user\Documents\venv\Lib\site-packages\rest_framework\views.py", line 506, in dispatch
    response = handler(request, *args, **kwargs)
               ^^^^^^^^^^^^^^^^^^^^^^^^^^^^^^^^^
  File "C:\Users\user\Documents\Project\stanum_web\account\views.py", line 444, in post
    user = get_object_or_404(User, id=id, email_verified=True)
           ^^^^^^^^^^^^^^^^^^^^^^^^^^^^^^^^^^^^^^^^^^^^^^^^^^^
  File "C:\Users\user\Documents\venv\Lib\site-packages\django\shortcuts.py", line 85, in get_object_or_404
    return queryset.get(*args, **kwargs)
           ^^^^^^^^^^^^^^^^^^^^^^^^^^^^^
  File "C:\Users\user\Documents\venv\Lib\site-packages\django\db\models\query.py", line 633, in get
    num = len(clone)
          ^^^^^^^^^^
  File "C:\Users\user\Documents\venv\Lib\site-packages\django\db\models\query.py", line 380, in __len__
    self._fetch_all()
  File "C:\Users\user\Documents\venv\Lib\site-packages\django\db\models\query.py", line 1881, in _fetch_all
    self._result_cache = list(self._iterable_class(self))
                         ^^^^^^^^^^^^^^^^^^^^^^^^^^^^^^^^
  File "C:\Users\user\Documents\venv\Lib\site-packages\django\db\models\query.py", line 91, in __iter__
    results = compiler.execute_sql(
              ^^^^^^^^^^^^^^^^^^^^^
  File "C:\Users\user\Documents\venv\Lib\site-packages\django\db\models\sql\compiler.py", line 1560, in execute_sql
    cursor = self.connection.cursor()
             ^^^^^^^^^^^^^^^^^^^^^^^^
  File "C:\Users\user\Documents\venv\Lib\site-packages\django\utils\asyncio.py", line 26, in inner
    return func(*args, **kwargs)
           ^^^^^^^^^^^^^^^^^^^^^
  File "C:\Users\user\Documents\venv\Lib\site-packages\django\db\backends\base\base.py", line 330, in cursor
    return self._cursor()
           ^^^^^^^^^^^^^^
  File "C:\Users\user\Documents\venv\Lib\site-packages\django\db\backends\base\base.py", line 306, in _cursor
    self.ensure_connection()
  File "C:\Users\user\Documents\venv\Lib\site-packages\django\utils\asyncio.py", line 26, in inner
    return func(*args, **kwargs)
           ^^^^^^^^^^^^^^^^^^^^^
  File "C:\Users\user\Documents\venv\Lib\site-packages\django\db\backends\base\base.py", line 288, in ensure_connection
    with self.wrap_database_errors:
  File "C:\Users\user\Documents\venv\Lib\site-packages\django\db\utils.py", line 91, in __exit__
    raise dj_exc_value.with_traceback(traceback) from exc_value
  File "C:\Users\user\Documents\venv\Lib\site-packages\django\db\backends\base\base.py", line 289, in ensure_connection
    self.connect()
  File "C:\Users\user\Documents\venv\Lib\site-packages\django\utils\asyncio.py", line 26, in inner
    return func(*args, **kwargs)
           ^^^^^^^^^^^^^^^^^^^^^
  File "C:\Users\user\Documents\venv\Lib\site-packages\django\db\backends\base\base.py", line 270, in connect
    self.connection = self.get_new_connection(conn_params)
                      ^^^^^^^^^^^^^^^^^^^^^^^^^^^^^^^^^^^^
  File "C:\Users\user\Documents\venv\Lib\site-packages\django\utils\asyncio.py", line 26, in inner
    return func(*args, **kwargs)
           ^^^^^^^^^^^^^^^^^^^^^
  File "C:\Users\user\Documents\venv\Lib\site-packages\django\db\backends\postgresql\base.py", line 275, in get_new_connection
    connection = self.Database.connect(**conn_params)
                 ^^^^^^^^^^^^^^^^^^^^^^^^^^^^^^^^^^^^
  File "C:\Users\user\Documents\venv\Lib\site-packages\psycopg2\__init__.py", line 122, in connect
    conn = _connect(dsn, connection_factory=connection_factory, **kwasync)
           ^^^^^^^^^^^^^^^^^^^^^^^^^^^^^^^^^^^^^^^^^^^^^^^^^^^^^^^^^^^^^^^
django.db.utils.OperationalError: could not translate host name "victor-ao-ayomideolusola5002-b13e.h.aivencloud.com" to address: No such host is known. 

ERROR 2025-07-27 06:22:27,518 runserver 14520 15260 [35;1mHTTP POST /api/v1/account/auth/password/reset/2/ctl5od-f9432bfb0a3af91bbf46322c75f58590 500 [0.08, 127.0.0.1:53128][0m
INFO 2025-07-27 06:23:01,427 runserver 14520 15260 [mHTTP POST /api/v1/account/auth/password/reset/2/ctl5od-f9432bfb0a3af91bbf46322c75f58590 200 [2.58, 127.0.0.1:53141][0m
